Workbook

Sheet 요약
A1: [수입] | E1: (만원)
B2: ='수입&예산'!K3 -> 수입(계) | C2: ='수입&예산'!L3 -> Tiss | D2: ='수입&예산'!M3 -> JM | E2: ='수입&예산'!N3 -> 총합
B3: ='수입&예산'!K4 -> 월간 수입 | C3: ='수입&예산'!L4 -> 559.8199 | D3: ='수입&예산'!M4 -> 0 | E3: ='수입&예산'!N4 -> 559.8199
B4: ='수입&예산'!K5 -> 연간 수입 | C4: ='수입&예산'!L5 -> 2206 | D4: ='수입&예산'!M5 -> 0 | E4: ='수입&예산'!N5 -> 2206
B5: ='수입&예산'!K6 -> 연 총 수입 | C5: ='수입&예산'!L6 -> 8923.8388 | D5: ='수입&예산'!M6 -> 0 | E5: ='수입&예산'!N6 -> 8923.8388
A7: [예산] | F7: (만원)
B8: ='수입&예산'!K14 -> 예산(대분류별) | C8: ='수입&예산'!L14 -> 공동 | D8: ='수입&예산'!M14 -> Tiss | E8: ='수입&예산'!N14 -> JM | F8: ='수입&예산'!O14 -> 총합
B9: ='수입&예산'!K15 -> 고정비 | C9: ='수입&예산'!L15 -> 50.4 | D9: ='수입&예산'!M15 -> 64.1 | E9: ='수입&예산'!N15 -> 8 | F9: ='수입&예산'!O15 -> 122.5
B10: ='수입&예산'!K16 -> 주거 | C10: ='수입&예산'!L16 -> 0 | D10: ='수입&예산'!M16 -> 0 | E10: ='수입&예산'!N16 -> 0 | F10: ='수입&예산'!O16 -> 0
B11: ='수입&예산'!K17 -> 용돈 | C11: ='수입&예산'!L17 -> 0 | D11: ='수입&예산'!M17 -> 0 | E11: ='수입&예산'!N17 -> 0 | F11: ='수입&예산'!O17 -> 0
B12: ='수입&예산'!K18 -> 생활비 | C12: ='수입&예산'!L18 -> 35 | D12: ='수입&예산'!M18 -> 0 | E12: ='수입&예산'!N18 -> 0 | F12: ='수입&예산'!O18 -> 35
B13: ='수입&예산'!K19 -> 세금 | C13: ='수입&예산'!L19 -> 61.3 | D13: ='수입&예산'!M19 -> 0 | E13: ='수입&예산'!N19 -> 0 | F13: ='수입&예산'!O19 -> 61.3
B14: ='수입&예산'!K20 -> 기타 | C14: ='수입&예산'!L20 -> 35 | D14: ='수입&예산'!M20 -> 0 | E14: ='수입&예산'!N20 -> 0 | F14: ='수입&예산'!O20 -> 35
F16: (만원)
B17: ='수입&예산'!K26 -> 예산(대출/저축) | C17: ='수입&예산'!L26 -> 공동 | D17: ='수입&예산'!M26 -> Tiss | E17: ='수입&예산'!N26 -> JM | F17: ='수입&예산'!O26 -> 총합
B18: ='수입&예산'!K27 -> 대출상환 | C18: ='수입&예산'!L27 -> 90 | D18: ='수입&예산'!M27 -> 0 | E18: ='수입&예산'!N27 -> 0 | F18: ='수입&예산'!O27 -> 90
B19: ='수입&예산'!K28 -> 저축 | C19: ='수입&예산'!L28 -> 0 | D19: ='수입&예산'!M28 -> 0 | E19: ='수입&예산'!N28 -> 0 | F19: ='수입&예산'!O28 -> 0
F21: (만원)
B22: ='수입&예산'!K30 -> 예산(계) | C22: ='수입&예산'!L30 -> 공동 | D22: ='수입&예산'!M30 -> Tiss | E22: ='수입&예산'!N30 -> JM | F22: ='수입&예산'!O30 -> 총합
B23: ='수입&예산'!K31 -> 월간 예산(소비) | C23: ='수입&예산'!L31 -> 120.4 | D23: ='수입&예산'!M31 -> 64.1 | E23: ='수입&예산'!N31 -> 8 | F23: ='수입&예산'!O31 -> 192.5
B24: ='수입&예산'!K32 -> 월간 예산(전체) | C24: ='수입&예산'!L32 -> 210.4 | D24: ='수입&예산'!M32 -> 64.1 | E24: ='수입&예산'!N32 -> 8 | F24: ='수입&예산'!O32 -> 282.5
B25: ='수입&예산'!K33 -> 연간 예산(소비) | C25: ='수입&예산'!L33 -> 61.3 | D25: ='수입&예산'!M33 -> 0 | E25: ='수입&예산'!N33 -> 0 | F25: ='수입&예산'!O33 -> 61.3
B26: ='수입&예산'!K34 -> 연 총 예산(전체) | C26: ='수입&예산'!L34 -> 61.3 | D26: ='수입&예산'!M34 -> 0 | E26: ='수입&예산'!N34 -> 0 | F26: ='수입&예산'!O34 -> 61.3
B27: ='수입&예산'!K35 -> 총계(소비) | C27: ='수입&예산'!L35 -> 1506.1 | D27: ='수입&예산'!M35 -> 769.2 | E27: ='수입&예산'!N35 -> 96 | F27: ='수입&예산'!O35 -> 2371.3
B28: ='수입&예산'!K36 -> 총계(전체) | C28: ='수입&예산'!L36 -> 2586.1 | D28: ='수입&예산'!M36 -> 769.2 | E28: ='수입&예산'!N36 -> 96 | F28: ='수입&예산'!O36 -> 3451.3
A30: [저축] | C30: (만원)
B31: ='수입&예산'!K38 -> 저축(계) | C31: ='수입&예산'!L38 -> 금액 | E31: 기준 | F31: 월 | G31: 연
B32: ='수입&예산'!K39 -> 월 순수 저축액 | C32: ='수입&예산'!L39 -> 277.3199 | E32: 0.6 | F32: =$E$3*E32 -> 335.89194 | G32: =$E$5*E32 -> 5354.3033
B33: ='수입&예산'!K40 -> 월 대출상환+저축액 | C33: ='수입&예산'!L40 -> 367.3199 | E33: 0.65 | F33: =$E$3*E33 -> 363.88293 | G33: =$E$5*E33 -> 5800.4952
B34: ='수입&예산'!K41 -> 연 순수 저축액 | C34: ='수입&예산'!L41 -> 5472.5388 | E34: 0.7 | F34: =$E$3*E34 -> 391.87393 | G34: =$E$5*E34 -> 6246.6872
B35: ='수입&예산'!K42 -> 연 대출상환+저축액 | C35: ='수입&예산'!L42 -> 6552.5388 | E35: 0.75 | F35: =$E$3*E35 -> 419.86492 | G35: =$E$5*E35 -> 6692.8791

Sheet 수입&예산
A1: [수입]
A2: [2025] | I2: (만원) | N2: (만원)
A3: 수입 | B3: 비고 | C3: Tiss | D3: 주기 | E3: 대상월 | F3: JM | G3: 주기 | H3: 대상월 | I3: 총합 | K3: 수입(계) | L3: Tiss | M3: JM | N3: 총합
A4: 월급 | C4: 554.3 | D4: M | E4: N/A | G4: M | H4: N/A | I4: =IF(D4="M",C4*12,C4)+IF(G4="M",F4*12,F4) -> 6651.6 | K4: 월간 수입 | L4: =SUMIF(D$4:D$12,"M",C$4:C$12) -> 559.8199 | M4: =SUMIF(G$4:G$12,"M",F$4:F$12) -> 0 | N4: =SUM(L4:M4) -> 559.8199
A5: 기타 상여금 | B5: 통신지원금 | C5: 5.5199 | D5: M | E5: N/A | G5: N/A | H5: N/A | I5: =IF(D5="M",C5*12,C5)+IF(G5="M",F5*12,F5) -> 66.2388 | K5: 연간 수입 | L5: =SUMIF(D$4:D$12,"Y",C$4:C$12) -> 2206 | M5: =SUMIF(E$4:E$12,"Y",D$4:D$12) -> 0 | N5: =SUM(L5:M5) -> 2206
A6: 기타 상여금 | B6: 인센티브 | C6: =ROUNDDOWN(C4*12*0.29272,0) -> 1947 | D6: Y | E6: 202501 | I6: =IF(D6="M",C6*12,C6)+IF(G6="M",F6*12,F6) -> 1947 | K6: 연 총 수입 | L6: =L4*12+L5 -> 8923.8388 | M6: =M4*12+M5 -> 0 | N6: =SUM(L6:M6) -> 8923.8388
A7: 기타 상여금 | B7: 명절-설 | C7: =110*0.7 -> 77 | D7: Y | E7: 2025 | I7: =IF(D7="M",C7*12,C7)+IF(G7="M",F7*12,F7) -> 77
A8: 기타 상여금 | B8: 명절-추석 | C8: =110*0.7 -> 77 | D8: Y | E8: 202510 | I8: =IF(D8="M",C8*12,C8)+IF(G8="M",F8*12,F8) -> 77
A9: 기타 상여금 | B9: 하계휴가비 | C9: =50*0.7 -> 35 | D9: Y | E9: 202507 | I9: =IF(D9="M",C9*12,C9)+IF(G9="M",F9*12,F9) -> 35
A10: 복지포인트 | C10: =100*0.7 -> 70 | D10: Y | E10: 202501 | I10: =IF(D10="M",C10*12,C10)+IF(G10="M",F10*12,F10) -> 70
A11: 기타 | I11: =IF(D11="M",C11*12,C11)+IF(G11="M",F11*12,F11) -> 0
A13: 예산(소비)
A14: 대분류 | B14: 중분류 | C14: 공동 | D14: Tiss | E14: JM | F14: 주기 | G14: 합계 | H14: 납부월 | I14: 비고 | K14: 예산(대분류별) | L14: 공동 | M14: Tiss | N14: JM | O14: 총합
A15: 고정비 | B15: 휴대폰/인터넷 | D15: 4.4 | F15: M | G15: =SUM(C15:E15) -> 4.4 | I15: JM(2.8) | K15: 고정비 | L15: =SUMIF($A$15:$A$27,$K15,C$15:C$27) -> 50.4 | M15: =SUMIF($A$15:$A$27,$K15,D$15:D$27) -> 64.1 | N15: =SUMIF($A$15:$A$27,$K15,E$15:E$27) -> 8 | O15: =SUM(L15:N15) -> 122.5
A16: 고정비 | B16: 보험/연금 | D16: =23.1+1.5 -> 24.6 | F16: M | G16: =SUM(C16:E16) -> 24.6 | I16: 삼성생명+삼성화재 / 동양생명(8.6)+국민연금(10)+건강보험(?) | K16: 주거 | L16: =SUMIF($A$15:$A$27,$K16,C$15:C$27) -> 0 | M16: =SUMIF($A$15:$A$27,$K16,D$15:D$27) -> 0 | N16: =SUMIF($A$15:$A$27,$K16,E$15:E$27) -> 0 | O16: =SUM(L16:N16) -> 0
A17: 고정비 | B17: 부모님 | D17: =10+7.1 -> 17.1 | F17: M | G17: =SUM(C17:E17) -> 17.1 | I17: 공용+현대해상화재보험 | K17: 용돈 | L17: =SUMIF($A$15:$A$27,$K17,C$15:C$27) -> 0 | M17: =SUMIF($A$15:$A$27,$K17,D$15:D$27) -> 0 | N17: =SUMIF($A$15:$A$27,$K17,E$15:E$27) -> 0 | O17: =SUM(L17:N17) -> 0
A18: 고정비 | B18: 기흥모임 | C18: 13 | F18: M | G18: =SUM(C18:E18) -> 13 | K18: 생활비 | L18: =SUMIF($A$15:$A$27,$K18,C$15:C$27) -> 35 | M18: =SUMIF($A$15:$A$27,$K18,D$15:D$27) -> 0 | N18: =SUMIF($A$15:$A$27,$K18,E$15:E$27) -> 0 | O18: =SUM(L18:N18) -> 35
A19: 고정비 | B19: 교통비 | D19: 8 | E19: 8 | F19: M | G19: =SUM(C19:E19) -> 16 | K19: 세금 | L19: =SUMIF($A$15:$A$27,$K19,C$15:C$27) -> 61.3 | M19: =SUMIF($A$15:$A$27,$K19,D$15:D$27) -> 0 | N19: =SUMIF($A$15:$A$27,$K19,E$15:E$27) -> 0 | O19: =SUM(L19:N19) -> 61.3
A20: 고정비 | B20: 구독형서비스 | C20: =2.2+1.4+0.8 -> 4.4 | F20: M | G20: =SUM(C20:E20) -> 4.4 | I20: 인터넷+정수기+쿠팡 | K20: 기타 | L20: =SUMIF($A$15:$A$27,$K20,C$15:C$27) -> 35 | M20: =SUMIF($A$15:$A$27,$K20,D$15:D$27) -> 0 | N20: =SUMIF($A$15:$A$27,$K20,E$15:E$27) -> 0 | O20: =SUM(L20:N20) -> 35
A21: 고정비 | B21: 용돈 | D21: 10 | F21: M | G21: =SUM(C21:E21) -> 10 | I21: JM(8.5)
A22: 고정비 | B22: 아파트관리비 | C22: 33 | F22: M | G22: =SUM(C22:E22) -> 33
A23: 생활비 | C23: 35 | F23: M | G23: =SUM(C23:E23) -> 35
A24: 세금 | B24: 재산세(주택) | C24: 30 | F24: Y | G24: =SUM(C24:E24) -> 30 | H24: 202207
A25: 세금 | B25: 재산세(주택) | C25: 30 | F25: Y | G25: =SUM(C25:E25) -> 30 | H25: 202209
A26: 세금 | B26: 주민세 | C26: 1.3 | F26: Y | G26: =SUM(C26:E26) -> 1.3 | H26: 202208 | K26: 예산(대출/저축) | L26: 공동 | M26: Tiss | N26: JM | O26: 총합
A27: 기타 | C27: 35 | F27: M | G27: =SUM(C27:E27) -> 35 | K27: 대출상환 | L27: =SUMIF($A$31:$A$32,$K27,C$31:C$32) -> 90 | M27: =SUMIF($A$15:$A$27,$K27,D$15:D$27) -> 0 | N27: =SUMIF($A$15:$A$27,$K27,E$15:E$27) -> 0 | O27: =SUM(L27:N27) -> 90
K28: 저축 | L28: =SUMIF($A$31:$A$32,$K28,C$31:C$32) -> 0 | M28: =SUMIF($A$15:$A$27,$K28,D$15:D$27) -> 0 | N28: =SUMIF($A$15:$A$27,$K28,E$15:E$27) -> 0 | O28: =SUM(L28:N28) -> 0
A29: 예산(대출/저축)
A30: 대분류 | B30: 중분류 | C30: 공동 | D30: Tiss | E30: JM | F30: 주기 | K30: 예산(계) | L30: 공동 | M30: Tiss | N30: JM | O30: 총합
A31: 대출상환 | B31: 디딤돌 | C31: 90 | F31: M | K31: 월간 예산(소비) | L31: =SUMIF($F$15:$F$27,"M",C$15:C$27) -> 120.4 | M31: =SUMIF($F$15:$F$27,"M",D$15:D$27) -> 64.1 | N31: =SUMIF($F$15:$F$27,"M",E$15:E$27) -> 8 | O31: =SUM(L31:N31) -> 192.5
A32: 저축 | B32: 저축 | F32: M | K32: 월간 예산(전체) | L32: =SUMIF($F$15:$F$32,"M",C$15:C$32) -> 210.4 | M32: =SUMIF($F$15:$F$33,"M",D$15:D$33) -> 64.1 | N32: =SUMIF($F$15:$F$33,"M",E$15:E$33) -> 8 | O32: =SUM(L32:N32) -> 282.5
K33: 연간 예산(소비) | L33: =SUMIF($F$15:$F$27,"Y",C$15:C$27) -> 61.3 | M33: =SUMIF($F$15:$F$27,"Y",D$15:D$27) -> 0 | N33: =SUMIF($F$15:$F$27,"Y",E$15:E$27) -> 0 | O33: =SUM(L33:N33) -> 61.3
K34: 연 총 예산(전체) | L34: =SUMIF($F$15:$F$32,"Y",C$15:C$32) -> 61.3 | M34: =SUMIF($F$15:$F$32,"Y",D$15:D$32) -> 0 | N34: =SUMIF($F$15:$F$32,"Y",E$15:E$32) -> 0 | O34: =SUM(L34:N34) -> 61.3
K35: 총계(소비) | L35: =L31*12+L33 -> 1506.1 | M35: =M31*12+M33 -> 769.2 | N35: =N31*12+N33 -> 96 | O35: =O31*12+O33 -> 2371.3
K36: 총계(전체) | L36: =L32*12+L34 -> 2586.1 | M36: =M32*12+M34 -> 769.2 | N36: =N32*12+N34 -> 96 | O36: =SUM(L36:N36) -> 3451.3
K38: 저축(계) | L38: 금액
K39: 월 순수 저축액 | L39: =N4-O32 -> 277.3199
K40: 월 대출상환+저축액 | L40: =N4-O31 -> 367.3199
K41: 연 순수 저축액 | L41: =N6-O36 -> 5472.5388
K42: 연 대출상환+저축액 | L42: ='수입&예산'!N6-O35 -> 6552.5388

Sheet 대출
A2: No. | B2: 상환예정일자 | D2: 상환예정금액 | E2: 상환예정금액 | F2: 상환예정금액 | G2: 상환예정금액 | H2: 구간별 이자계산일자 | I2: 구간별 이자계산일자
A3: No. | B3: 상환월 | C3: 영업일자 | D3: 원리금 | E3: 원금 | F3: 이자 | G3: 상환 후 잔액 | H3: 시작일자 | I3: 종료일자
A4: 1 | B4: 201808 | C4: 2018-08-27 | D4: 1282130 | E4: 555555 | F4: 726575 | G4: 199444445 | H4: 2018-07-04 | I4: 2018-08-24
A5: 2 | B5: 201809 | C5: 2018-09-27 | D5: 987502 | E5: 555555 | F5: 431947 | G5: 198888890 | H5: 2018-08-25 | I5: 2018-09-24
A6: 3 | B6: 201810 | C6: 2018-10-25 | D6: 972404 | E6: 555555 | F6: 416849 | G6: 198333335 | H6: 2018-09-25 | I6: 2018-10-24
A7: 4 | B7: 201811 | C7: 2018-11-26 | D7: 985096 | E7: 555555 | F7: 429541 | G7: 197777780 | H7: 2018-10-25 | I7: 2018-11-24
A8: 5 | B8: 201812 | C8: 2018-12-26 | D8: 970075 | E8: 555555 | F8: 414520 | G8: 197222225 | H8: 2018-11-25 | I8: 2018-12-24
A9: 6 | B9: 201901 | C9: 2019-01-25 | D9: 982689 | E9: 555555 | F9: 427134 | G9: 196666670 | H9: 2018-12-25 | I9: 2019-01-24
A10: 7 | B10: 201902 | C10: 2019-02-25 | D10: 981486 | E10: 555555 | F10: 425931 | G10: 196111115 | H10: 2019-01-25 | I10: 2019-02-24
A11: 8 | B11: 201903 | C11: 2019-03-25 | D11: 939180 | E11: 555555 | F11: 383625 | G11: 195555560 | H11: 2019-02-25 | I11: 2019-03-24
A12: 9 | B12: 201904 | C12: 2019-04-25 | D12: 979080 | E12: 555555 | F12: 423525 | G12: 195000005 | H12: 2019-03-25 | I12: 2019-04-24
A13: 10 | B13: 201905 | C13: 2019-05-27 | D13: 964253 | E13: 555555 | F13: 408698 | G13: 194444450 | H13: 2019-04-25 | I13: 2019-05-24
A14: 11 | B14: 201906 | C14: 2019-06-25 | D14: 976673 | E14: 555555 | F14: 421118 | G14: 193888895 | H14: 2019-05-25 | I14: 2019-06-24
A15: 12 | B15: 201907 | C15: 2019-07-25 | D15: 961924 | E15: 555555 | F15: 406369 | G15: 193333340 | H15: 2019-06-25 | I15: 2019-07-24
... A363: 360 | B363: 204807 | C363: 2048-07-06 | D363: 556180 | E363: 555755 | F363: 425 | G363: 0 | H363: 2048-06-25 | I363: 2048-07-05

Sheet 자금전체
C2: Min | D2: Max
A3: 자산 | B3: 부동산 | C3: 900000000 | D3: 950000000
B4: 계좌 | C4: =26000000+6000000+1960000 -> 33960000 | D4: =26000000+6000000+1960000 -> 33960000
B5: 현금 | C5: 22000000 | D5: 22000000 | E5: +@
B6: 주식 | C6: 76000000 | D6: 77000000
B7: 주식계좌 | C7: 45000000 | D7: 45000000
B8: 코인 | C8: 4500000 | D8: 4800000
B9: 연차+성과급 | C9: =6000000+21000000 -> 27000000 | D9: =7000000+23000000 -> 30000000
B10: 퇴직금 | C10: 0 | D10: =90000000*0.69 -> 62100000
C11: =SUM(C3:C10) -> 1108460000 | D11: =SUM(D3:D10) -> 1224860000
A13: 마이너스 | B13: 대출금 | C13: -151111160 | D13: -150000000
B14: 압정 | C14: -2896000 | D14: -3000000
C15: =SUM(C13:C14) -> -154007160 | D15: =SUM(D13:D14) -> -153000000
C17: =SUM(C15,C11) -> 954452840 | D17: =SUM(D15,D11) -> 1071860000
B19: 이사갈집 | C19: 1300000000 | D19: 1450000000
A21: 필요금액 | B21: 복비(팔때) | C21: =(C3*0.005)*-1.1 -> -4950000 | D21: =(D3*0.005)*-1.1 -> -5225000
B22: 복비(살때) | C22: =(C19*0.006)*-1.1 -> -8580000 | D22: =(D19*0.006)*-1.1 -> -9570000
B23: 취득세 | C23: =-(C19*0.03+C19*0.003) -> -42900000 | D23: =-(D19*0.03+D19*0.003) -> -47850000
B24: 이사비용 | C24: -2000000 | D24: -2500000
B25: +가전
B26: +인테리어
C27: =SUM(C21:C26) -> -58430000 | D27: =SUM(D21:D26) -> -65145000
A29: 대출필요 | C29: =SUM(C17-C19+C27) -> -403977160 | D29: =SUM(D17-D19+D27) -> -443285000
A30: 원리금균등 | C30: =ROUNDUP(C29,-7) -> -410000000 | D30: =ROUNDUP(D29,-7) -> -450000000
B31: 3.9 | C31: 2122507 | D31: 2311174
B32: 4.5 | C32: 2280084 | D32: 2482758
B38: 퇴직급계산 | C38: 지급일수*일평균급여 | E38: 41277 | F38: 46053
B39: 지급일수 | C39: 근속일수*30/365 | E39: =F38-E38 -> 4776 | F39: =E39*30/365 -> 392.54795
B40: 일평균급여 | C40: 퇴직발생전 3개월간 받음 임금의 총액 / 그 기간의 총일수
C41: =(7125000*2+7125000*1.1)/92 -> 240081.52
C42: =C41*F39 -> 94243508
C43: =C42*0.69 -> 65028021

Sheet 이사
A1: [팔집] | B1: min | D1: [살집] | E1: min | G1: -> 보관 X | K1: me
A2: 매도 | B2: =SUM(B3:B13) -> 929857500 | D2: 매수 | E2: =SUM(E3:E13) -> -1452642000 | G2: 이사 | H2: =SUM(H3:H15) -> -4450000 | J2: 자본 | K2: =SUM(K3:K15) -> 573591460 | M2: =SUM(K2,H2,E2,B2) -> 46356960
A3: 금액 | B3: 935000000 | D3: 금액 | E3: -1395000000 | G3: 이사비용 | H3: =-4000000 -> -4000000 | J3: 대출(신) | K3: 470000000
A4: 중계수수료 | B4: =(B3*0.005)*-1.1 -> -5142500 | D4: 중계수수료 | E4: =(E3*0.006)*1.1 -> -9207000 | G4: 엘리베이터 사용료 | H4: =-100000-100000 -> -200000 | J4: 대출(구) | K4: -150000000
A5: 식세기 복구비 | B5: 0 | D5: 취득세 | E5: =(E3*0.033) -> -46035000 | G5: 보관비 | H5: 0 | J5: 계좌(KB) | K5: =8300000-1450000 -> 6850000
A6: 인덕션 복구비 | B6: 0 | D6: 입주청소 | E6: -400000 | G6: 식세기 이전 | H6: 0 | J6: 계좌(토스) | K6: 28150000
D7: 도배 | E7: -2000000 | G7: 인덕션 이전 | H7: -200000 | J7: 계좌(삼증) | K7: 46790000
A8: 에어컨 판매 | B8: 0 | D8: 신규가전 | E8: 0 | G8: 정수기 이전 | H8: -50000 | J8: 주식 | K8: 81930000
A9: 인덕션 판매 | B9: 0 | G9: 에어컨 이전 | H9: 0 | J9: 코인 | K9: 3640000
A10: 식세기 판매 | B10: 0 | G10: 중문 | J10: 상여금 | K10: 22000000
J11: 퇴직금 | K11: 62000000 | L11: ~6500
J12: 휴가비 | K12: =24500*1.1*8*0.69*L12 -> 2231460 | L12: 15
G16: 이사 | H16: =SUM(H17:H29) -> -5980000
G17: 이사비용 | H17: =-2500000*2 -> -5000000
G18: 엘리베이터 사용료 | H18: =-100000-200000 -> -300000
G19: 보관비 | H19: =-100000*2 -> -200000
G20: 식세기 설치 | H20: =-130000-100000 -> -230000 | I20: ?
G21: 인덕션 설치 | H21: -200000 | I21: ?
G22: 정수기 설치 | H22: -50000 | I22: ?
G23: 에어컨 이전 | H23: (이사비용 포함)

Sheet 자금흐름
B1: 46026 | E1: 시작 | G1: 46027 | J1: 해외 예수금 | L1: 46030 | O1: 주식정리 | Q1: 46036 | T1: 중간계산 | V1: 46045 | Y1: 계약일 | AA1: 46046 | AD1: 중간계산 | AF1: 46050 | AI1: 중간계산 | AK1: 46081 | AN1: 중간계산
B2: 잔고 | C2: 지출 | D2: 총계 | E2: 비고 | G2: 잔고 | H2: 지출 | I2: 총계 | J2: 비고 | L2: 잔고 | M2: 지출 | N2: 총계 | O2: 비고 | Q2: 잔고 | R2: 지출/예정 | S2: 총계 | T2: 비고 | V2: 잔고 | W2: 지출 | X2: 총계 | Y2: 비고 | AA2: 잔고 | AB2: 예정 | AC2: 총계 | AD2: 비고 | AF2: 잔고 | AG2: 예정 | AH2: 총계 | AI2: 비고 | AK2: 잔고 | AL2: 예정 | AM2: 총계 | AN2: 비고
A3: [자본] | B3: =SUM(B4:B12) -> 242261557 | D3: =SUM(D4:D12) -> 242261557 | G3: =SUM(G4:G12) -> 141261557 | I3: =SUM(I4:I12) -> 141261557 | L3: =SUM(L4:L12) -> 141261557 | N3: =SUM(N4:N12) -> 141261557 | Q3: =SUM(Q4:Q12) -> 134340000 | R3: =SUM(R4:R38) -> -399672000 | S3: =SUM(Q3:R3) -> -265332000 | V3: =SUM(V4:V12) -> 130186580 | X3: =SUM(X4:X12) -> 11479580 | AA3: =SUM(AA4:AA51) -> 148130000 | AB3: =SUM(AB4:AB51) -> -152706999 | AC3: =SUM(AA3:AB3) -> -4576999 | AF3: =SUM(AF4:AF51) -> 18140000 | AG3: =SUM(AG4:AG51) -> -22888049 | AH3: =SUM(AF3:AG3) -> -4748049 | AK3: =SUM(AK4:AK51) -> 203980000 | AL3: =SUM(AL4:AL51) -> -192838050 | AM3: =SUM(AK3:AL3) -> 11141950
A4: 계좌(KB) | B4: 44509445 | D4: =SUM(B4:C4) -> 44509445 | G4: 44509445 | H4: =H6*-1 -> 10677135 | I4: =SUM(G4:H4) -> 55186580 | J4: 해외 예수금 이체 | L4: =44509445+10677135 -> 55186580 | M4: =M7*-1 -> 75000000 | N4: =SUM(L4:M4) -> 130186580 | O4: 주식 정리(완) | Q4: 117340000 | S4: =SUM(Q4:R4) -> 117340000 | T4: 계약금+중계수수료 | V4: =N4 -> 130186580 | W4: =SUM(W24,W25) -> -118707000 | X4: =SUM(V4:W4) -> 11479580 | Y4: 계약금+중계수수료 | AA4: 148130000 | AB4: 0 | AC4: =SUM(AA4:AB4) -> 148130000 | AF4: 18140000 | AG4: -4000000 | AH4: =SUM(AF4:AG4) -> 14140000 | AK4: 33980000 | AL4: -4000000 | AM4: =SUM(AK4:AL4) -> 29980000
A5: 계좌(토스) | B5: 0 | D5: =SUM(B5:C5) -> 0 | G5: 0 | I5: =SUM(G5:H5) -> 0 | L5: 0 | N5: =SUM(L5:M5) -> 0 | Q5: 0 | S5: =SUM(Q5:R5) -> 0 | V5: 0 | X5: =SUM(V5:W5) -> 0 | AA5: 0 | AB5: 0 | AC5: =SUM(AA5:AB5) -> 0 | AF5: 0 | AG5: 0 | AH5: =SUM(AF5:AG5) -> 0 | AK5: 170000000 | AL5: 0 | AM5: =SUM(AK5:AL5) -> 170000000
A6: 계좌(삼증) | B6: =10581150+95985 -> 10677135 | D6: =SUM(B6:C6) -> 10677135 | E6: 해외 달러 | G6: =10581150+95985 -> 10677135 | H6: =G6*-1 -> -10677135 | I6: =SUM(G6:H6) -> 0 | L6: 0 | N6: =SUM(L6:M6) -> 0 | Q6: 0 | S6: =SUM(Q6:R6) -> 0 | V6: 0 | X6: =SUM(V6:W6) -> 0 | AA6: 0 | AB6: 0 | AC6: =SUM(AA6:AB6) -> 0 | AF6: 0 | AG6: 0 | AH6: =SUM(AF6:AG6) -> 0 | AK6: 0 | AL6: 0 | AM6: =SUM(AK6:AL6) -> 0
A7: 주식 | B7: 82310744 | D7: =SUM(B7:C7) -> 82310744 | G7: 82310744 | I7: =SUM(G7:H7) -> 82310744 | L7: 82310744 | M7: -75000000 | N7: =SUM(L7:M7) -> 7310744 | Q7: 0 | S7: =SUM(Q7:R7) -> 0 | V7: 0 | X7: =SUM(V7:W7) -> 0 | AA7: 0 | AB7: 0 | AC7: =SUM(AA7:AB7) -> 0 | AF7: 0 | AG7: 0 | AH7: =SUM(AF7:AG7) -> 0 | AK7: 0 | AL7: 0 | AM7: =SUM(AK7:AL7) -> 0
A8: 코인 | B8: 3764233 | D8: =SUM(B8:C8) -> 3764233 | G8: 3764233 | I8: =SUM(G8:H8) -> 3764233 | L8: 3764233 | N8: =SUM(L8:M8) -> 3764233 | Q8: 0 | S8: =SUM(Q8:R8) -> 0 | V8: 0 | X8: =SUM(V8:W8) -> 0 | AA8: 0 | AB8: 0 | AC8: =SUM(AA8:AB8) -> 0 | AF8: 0 | AG8: 0 | AH8: =SUM(AF8:AG8) -> 0 | AK8: 0 | AL8: 0 | AM8: =SUM(AK8:AL8) -> 0
A9: 상여금 | B9: 22000000 | D9: =SUM(B9:C9) -> 22000000 | G9: 0 | I9: =SUM(G9:H9) -> 0 | L9: 0 | N9: =SUM(L9:M9) -> 0 | Q9: 0 | R9: 20000000 | S9: =SUM(Q9:R9) -> 20000000 | V9: 0 | X9: =SUM(V9:W9) -> 0 | AA9: 0 | AB9: 0 | AC9: =SUM(AA9:AB9) -> 0 | AF9: 0 | AG9: 0 | AH9: =SUM(AF9:AG9) -> 0 | AK9: 0 | AL9: 0 | AM9: =SUM(AK9:AL9) -> 0
A10: 퇴직금 | B10: 62000000 | D10: =SUM(B10:C10) -> 62000000 | G10: 0 | I10: =SUM(G10:H10) -> 0 | L10: 0 | N10: =SUM(L10:M10) -> 0 | Q10: 0 | R10: 65000000 | S10: =SUM(Q10:R10) -> 65000000 | V10: 0 | X10: =SUM(V10:W10) -> 0 | AA10: 0 | AB10: 1 | AC10: =SUM(AA10:AB10) -> 1 | AD10: 안부족하면 IRP에 그대로 둘 예정 | AF10: 0 | AG10: 1 | AH10: =SUM(AF10:AG10) -> 1 | AI10: 안부족하면 IRP에 그대로 둘 예정 | AK10: 0 | AL10: 0 | AM10: =SUM(AK10:AL10) -> 0 | AN10: 안부족하면 IRP에 그대로 둘 예정
A11: 현금(Tiss) | B11: =10000000-3000000 -> 7000000 | D11: =SUM(B11:C11) -> 7000000 | G11: 0 | I11: =SUM(G11:H11) -> 0 | L11: 0 | N11: =SUM(L11:M11) -> 0 | Q11: 7000000 | S11: =SUM(Q11:R11) -> 7000000 | V11: 0 | X11: =SUM(V11:W11) -> 0 | AA11: 0 | AB11: -4000000 | AC11: =SUM(AA11:AB11) -> -4000000 | AD11: 경매(임시) | AF11: 0 | AG11: -170000 | AH11: =SUM(AF11:AG11) -> -170000 | AI11: 가스레인지 구입 | AK11: 0 | AL11: -170000 | AM11: =SUM(AK11:AL11) -> -170000 | AN11: 가스레인지 구입
A12: 현금(JM) | B12: 10000000 | D12: =SUM(B12:C12) -> 10000000 | G12: 0 | I12: =SUM(G12:H12) -> 0 | L12: 0 | N12: =SUM(L12:M12) -> 0 | Q12: 10000000 | S12: =SUM(Q12:R12) -> 10000000 | V12: 0 | X12: =SUM(V12:W12) -> 0 | AA12: 0 | AB12: 0 | AC12: =SUM(AA12:AB12) -> 0 | AF12: 0 | AG12: 0 | AH12: =SUM(AF12:AG12) -> 0 | AK12: 0 | AL12: 0 | AM12: =SUM(AK12:AL12) -> 0
A13: [대출]
A14: 대출(신) | B14: 0 | C14: 0 | D14: =SUM(B14:C14) -> 0 | G14: 0 | H14: 0 | I14: =SUM(G14:H14) -> 0 | L14: 0 | M14: 0 | N14: =SUM(L14:M14) -> 0 | Q14: 0 | R14: 0 | S14: =SUM(Q14:R14) -> 0 | V14: 0 | W14: 0 | X14: =SUM(V14:W14) -> 0 | AA14: 0 | AB14: 480000000 | AC14: =SUM(AA14:AB14) -> 480000000 | AF14: 0 | AG14: 480000000 | AH14: =SUM(AF14:AG14) -> 480000000 | AK14: 0 | AL14: 480000000 | AM14: =SUM(AK14:AL14) -> 480000000
A15: 대출(구) | B15: =-150555605 -> -150555605 | C15: 0 | D15: =SUM(B15:C15) -> -150555605 | G15: =-150555605 -> -150555605 | H15: 0 | I15: =SUM(G15:H15) -> -150555605 | L15: =-150555605 -> -150555605 | M15: 0 | N15: =SUM(L15:M15) -> -150555605 | Q15: =-150555605 -> -150555605 | R15: 0 | S15: =SUM(Q15:R15) -> -150555605 | V15: =-150555605 -> -150555605 | W15: 0 | X15: =SUM(V15:W15) -> -150555605 | AA15: 0 | AB15: -150000000 | AC15: =SUM(AA15:AB15) -> -150000000 | AF15: 0 | AG15: -20000050 | AH15: =SUM(AF15:AG15) -> -20000050 | AK15: 0 | AL15: -20000050 | AM15: =SUM(AK15:AL15) -> -20000050
A16: [기센푸]
A17: 계약금 | B17: 0 | C17: 0 | D17: =SUM(B17:C17) -> 0 | G17: 0 | H17: 0 | I17: =SUM(G17:H17) -> 0 | L17: 0 | M17: 0 | N17: =SUM(L17:M17) -> 0 | Q17: 0 | R17: 93000000 | S17: =SUM(Q17:R17) -> 93000000 | V17: 0 | W17: 0 | X17: =SUM(V17:W17) -> 0 | AA17: 0 | AB17: 0 | AC17: =SUM(AA17:AB17) -> 0 | AF17: 0 | AG17: 0 | AH17: =SUM(AF17:AG17) -> 0 | AK17: 0 | AL17: 0 | AM17: =SUM(AK17:AL17) -> 0
A18: 중계수수료 | Q18: 0 | R18: -5115000 | S18: =SUM(Q18:R18) -> -5115000 | AA18: 0 | AB18: -5115000 | AC18: =SUM(AA18:AB18) -> -5115000 | AF18: 0 | AG18: -5142500 | AH18: =SUM(AF18:AG18) -> -5142500 | AK18: 0 | AL18: -5142500 | AM18: =SUM(AK18:AL18) -> -5142500
A19: 중도금 | B19: 0 | C19: 0 | D19: =SUM(B19:C19) -> 0 | G19: 0 | H19: 0 | I19: =SUM(G19:H19) -> 0 | L19: 0 | M19: 0 | N19: =SUM(L19:M19) -> 0 | Q19: 0 | R19: 120000000 | S19: =SUM(Q19:R19) -> 120000000 | V19: 0 | W19: 0 | X19: =SUM(V19:W19) -> 0 | AA19: 0 | AB19: 170000000 | AC19: =SUM(AA19:AB19) -> 170000000 | AF19: 0 | AG19: 170000000 | AH19: =SUM(AF19:AG19) -> 170000000 | AK19: 0 | AL19: 0 | AM19: =SUM(AK19:AL19) -> 0
A20: 잔금 | B20: 0 | C20: 0 | D20: =SUM(B20:C20) -> 0 | G20: 0 | H20: 0 | I20: =SUM(G20:H20) -> 0 | L20: 0 | M20: 0 | N20: =SUM(L20:M20) -> 0 | Q20: 0 | R20: =930000000-R19-R17 -> 717000000 | S20: =SUM(Q20:R20) -> 717000000 | V20: 0 | W20: 0 | X20: =SUM(V20:W20) -> 0 | AA20: 0 | AB20: 671500000 | AC20: =SUM(AA20:AB20) -> 671500000 | AF20: 0 | AG20: 671500000 | AH20: =SUM(AF20:AG20) -> 671500000 | AK20: 0 | AL20: 671500000 | AM20: =SUM(AK20:AL20) -> 671500000
A21: [철클]
A22: 매매약정금 | B22: 0 | C22: -30000000 | D22: =SUM(B22:C22) -> -30000000 | G22: 0 | H22: -30000000 | I22: =SUM(G22:H22) -> -30000000 | L22: 0 | M22: -30000000 | N22: =SUM(L22:M22) -> -30000000 | Q22: 0 | R22: -30000000 | S22: =SUM(Q22:R22) -> -30000000 | V22: 0 | W22: -30000000 | X22: =SUM(V22:W22) -> -30000000 | AA22: 0 | AB22: 0 | AC22: =SUM(AA22:AB22) -> 0 | AF22: 0 | AG22: 0 | AH22: =SUM(AF22:AG22) -> 0 | AK22: 0 | AL22: 0 | AM22: =SUM(AK22:AL22) -> 0
A23: 토허제(법무사) | B23: 0 | C23: -100000 | D23: =SUM(B23:C23) -> -100000 | E23: 계약일 | G23: 0 | H23: -100000 | I23: =SUM(G23:H23) -> -100000 | L23: 0 | M23: -100000 | N23: =SUM(L23:M23) -> -100000 | Q23: 0 | R23: 0 | S23: =SUM(Q23:R23) -> 0 | V23: 0 | W23: -100000 | X23: =SUM(V23:W23) -> -100000 | AA23: 0 | AB23: 0 | AC23: =SUM(AA23:AB23) -> 0 | AF23: 0 | AG23: 0 | AH23: =SUM(AF23:AG23) -> 0 | AK23: 0 | AL23: 0 | AM23: =SUM(AK23:AL23) -> 0
A24: 계약금 | B24: 0 | C24: -109500000 | D24: =SUM(B24:C24) -> -109500000 | E24: 계약일 | G24: 0 | H24: 0 | I24: =SUM(G24:H24) -> 0 | L24: 0 | M24: 0 | N24: =SUM(L24:M24) -> 0 | Q24: 0 | R24: -109500000 | S24: =SUM(Q24:R24) -> -109500000 | V24: 0 | W24: -109500000 | X24: =SUM(V24:W24) -> -109500000 | AA24: 0 | AB24: 0 | AC24: =SUM(AA24:AB24) -> 0 | AF24: 0 | AG24: 0 | AH24: =SUM(AF24:AG24) -> 0 | AK24: 0 | AL24: 0 | AM24: =SUM(AK24:AL24) -> 0
A25: 중계수수료 | B25: 0 | C25: -9207000 | D25: =SUM(B25:C25) -> -9207000 | E25: 계약일 | G25: 0 | H25: 0 | I25: =SUM(G25:H25) -> 0 | L25: 0 | M25: 0 | N25: =SUM(L25:M25) -> 0 | Q25: 0 | R25: -9207000 | S25: =SUM(Q25:R25) -> -9207000 | V25: 0 | W25: -9207000 | X25: =SUM(V25:W25) -> -9207000 | AA25: 0 | AB25: -9207000 | AC25: =SUM(AA25:AB25) -> -9207000 | AF25: 0 | AG25: -9207000 | AH25: =SUM(AF25:AG25) -> -9207000 | AK25: 0 | AL25: -9207000 | AM25: =SUM(AK25:AL25) -> -9207000
A26: 중도금 | B26: 0 | C26: -160500000 | D26: =SUM(B26:C26) -> -160500000 | E26: ~3/4(수) | G26: 0 | H26: 0 | I26: =SUM(G26:H26) -> 0 | L26: 0 | M26: 0 | N26: =SUM(L26:M26) -> 0 | Q26: 0 | R26: =-300000000-R24-R22 -> -160500000 | S26: =SUM(Q26:R26) -> -160500000 | V26: 0 | W26: 0 | X26: =SUM(V26:W26) -> 0 | AA26: 0 | AB26: -160500000 | AC26: =SUM(AA26:AB26) -> -160500000 | AF26: 0 | AG26: -160500000 | AH26: =SUM(AF26:AG26) -> -160500000 | AK26: 0 | AL26: -160500000 | AM26: =SUM(AK26:AL26) -> -160500000
A27: 잔금 | B27: 0 | C27: =-1395000000-SUM(C26,C24) -> -1125000000 | D27: =SUM(B27:C27) -> -1125000000 | E27: ~4/17(금) | G27: 0 | H27: 0 | I27: =SUM(G27:H27) -> 0 | L27: 0 | M27: 0 | N27: =SUM(L27:M27) -> 0 | Q27: 0 | R27: =-1395000000-R26-R24-R22 -> -1095000000 | S27: =SUM(Q27:R27) -> -1095000000 | V27: 0 | W27: 0 | X27: =SUM(V27:W27) -> 0 | AA27: 0 | AB27: -1095000000 | AC27: =SUM(AA27:AB27) -> -1095000000 | AF27: 0 | AG27: -1095000000 | AH27: =SUM(AF27:AG27) -> -1095000000 | AK27: 0 | AL27: -1095000000 | AM27: =SUM(AK27:AL27) -> -1095000000
A28: 등기(법무사) | B28: 0 | C28: -9999 | D28: =SUM(B28:C28) -> -9999 | G28: 0 | H28: 0 | I28: =SUM(G28:H28) -> 0 | L28: 0 | M28: 0 | N28: =SUM(L28:M28) -> 0 | Q28: 0 | R28: 0 | S28: =SUM(Q28:R28) -> 0 | V28: 0 | W28: 0 | X28: =SUM(V28:W28) -> 0 | AA28: 0 | AB28: -1300000 | AC28: =SUM(AA28:AB28) -> -1300000 | AF28: 0 | AG28: -1300000 | AH28: =SUM(AF28:AG28) -> -1300000 | AK28: 0 | AL28: -1300000 | AM28: =SUM(AK28:AL28) -> -1300000
A29: 취등록세 | B29: 0 | C29: -46035000 | D29: =SUM(B29:C29) -> -46035000 | G29: 0 | H29: 0 | I29: =SUM(G29:H29) -> 0 | AA29: 0 | AB29: -46035000 | AC29: =SUM(AA29:AB29) -> -46035000 | AF29: 0 | AG29: -46035000 | AH29: =SUM(AF29:AG29) -> -46035000 | AK29: 0 | AL29: -46035000 | AM29: =SUM(AK29:AL29) -> -46035000
A30: [이사]
A31: 이사비용 | C31: -4000000 | D31: =SUM(B31:C31) -> -4000000 | G31: 0 | H31: 0 | I31: =SUM(G31:H31) -> 0 | L31: 0 | M31: 0 | N31: =SUM(L31:M31) -> 0 | Q31: 0 | R31: -4500000 | S31: =SUM(Q31:R31) -> -4500000 | V31: 0 | W31: 0 | X31: =SUM(V31:W31) -> 0 | AA31: 0 | AB31: -2550000 | AC31: =SUM(AA31:AB31) -> -2550000 | AD31: 280-25 | AF31: 0 | AG31: -2550000 | AH31: =SUM(AF31:AG31) -> -2550000 | AI31: 280-25 | AK31: 0 | AL31: -2550000 | AM31: =SUM(AK31:AL31) -> -2550000 | AN31: 280-25
A32: 입주청소 | C32: -9999 | D32: =SUM(B32:C32) -> -9999 | G32: 0 | H32: 0 | I32: =SUM(G32:H32) -> 0 | L32: 0 | M32: 0 | N32: =SUM(L32:M32) -> 0 | Q32: 0 | R32: -400000 | S32: =SUM(Q32:R32) -> -400000 | V32: 0 | W32: 0 | X32: =SUM(V32:W32) -> 0 | AA32: 0 | AB32: 0 | AC32: =SUM(AA32:AB32) -> 0 | AF32: 0 | AG32: 0 | AH32: =SUM(AF32:AG32) -> 0 | AK32: 0 | AL32: 0 | AM32: =SUM(AK32:AL32) -> 0
A33: 엘베 사용료 | C33: -200000 | D33: =SUM(B33:C33) -> -200000 | G33: 0 | H33: 0 | I33: =SUM(G33:H33) -> 0 | L33: 0 | M33: 0 | N33: =SUM(L33:M33) -> 0 | Q33: 0 | R33: -200000 | S33: =SUM(Q33:R33) -> -200000 | V33: 0 | W33: 0 | X33: =SUM(V33:W33) -> 0 | AA33: 0 | AB33: -200000 | AC33: =SUM(AA33:AB33) -> -200000 | AF33: 0 | AG33: -200000 | AH33: =SUM(AF33:AG33) -> -200000 | AK33: 0 | AL33: -100000 | AM33: =SUM(AK33:AL33) -> -100000 | AN33: 2/19 센푸 엘베 사용료 입금 완료
A34: 인덕션 이전 | C34: -200000 | D34: =SUM(B34:C34) -> -200000 | G34: 0 | H34: 0 | I34: =SUM(G34:H34) -> 0 | L34: 0 | M34: 0 | N34: =SUM(L34:M34) -> 0 | Q34: 0 | R34: -200000 | S34: =SUM(Q34:R34) -> -200000 | V34: 0 | W34: 0 | X34: =SUM(V34:W34) -> 0 | AA34: 0 | AB34: -200000 | AC34: =SUM(AA34:AB34) -> -200000 | AF34: 0 | AG34: -200000 | AH34: =SUM(AF34:AG34) -> -200000 | AK34: 0 | AL34: -200000 | AM34: =SUM(AK34:AL34) -> -200000
A35: 정수기 이전 | C35: -50000 | D35: =SUM(B35:C35) -> -50000 | G35: 0 | H35: 0 | I35: =SUM(G35:H35) -> 0 | L35: 0 | M35: 0 | N35: =SUM(L35:M35) -> 0 | Q35: 0 | R35: -50000 | S35: =SUM(Q35:R35) -> -50000 | V35: 0 | W35: 0 | X35: =SUM(V35:W35) -> 0 | AA35: 0 | AB35: -50000 | AC35: =SUM(AA35:AB35) -> -50000 | AF35: 0 | AG35: -60000 | AH35: =SUM(AF35:AG35) -> -60000 | AK35: 0 | AL35: -60000 | AM35: =SUM(AK35:AL35) -> -60000
A36: 인터넷 이전 | C36: -9999 | D36: =SUM(B36:C36) -> -9999 | G36: 0 | H36: 0 | I36: =SUM(G36:H36) -> 0 | L36: 0 | M36: 0 | N36: =SUM(L36:M36) -> 0 | Q36: 0 | R36: 0 | S36: =SUM(Q36:R36) -> 0 | V36: 0 | W36: 0 | X36: =SUM(V36:W36) -> 0 | AA36: 0 | AB36: -50000 | AC36: =SUM(AA36:AB36) -> -50000 | AF36: 0 | AG36: -23500 | AH36: =SUM(AF36:AG36) -> -23500 | AK36: 0 | AL36: -23500 | AM36: =SUM(AK36:AL36) -> -23500
A37: 도시가스 신청 | AL37: -50000 | AM37: =SUM(AK37:AL37) -> -50000
A38: 가구 배출 | C38: -9999 | D38: =SUM(B38:C38) -> -9999 | G38: 0 | H38: 0 | I38: =SUM(G38:H38) -> 0 | L38: 0 | M38: 0 | N38: =SUM(L38:M38) -> 0 | Q38: 0 | R38: 0 | S38: =SUM(Q38:R38) -> 0 | V38: 0 | W38: 0 | X38: =SUM(V38:W38) -> 0 | AA38: 0 | AB38: 0 | AC38: =SUM(AA38:AB38) -> 0 | AF38: 0 | AG38: 0 | AH38: =SUM(AF38:AG38) -> 0 | AK38: 0 | AL38: 0 | AM38: =SUM(AK38:AL38) -> 0
A39: [구입]
A40: 식탁 | AA40: 0 | AB40: 0 | AC40: =SUM(AA40:AB40) -> 0 | AF40: 0 | AG40: 0 | AH40: =SUM(AF40:AG40) -> 0 | AK40: 0 | AL40: 0 | AM40: =SUM(AK40:AL40) -> 0
...

Sheet 확인리스트(삭제용)
B2: 이사 비용 및 예약
B3: 입주 청소 및 예약
B4: 등기 비용
B5: 특약 추가 할 내용 | C5: O
B6: 법무사 | C6: O
B7: 대출 헬퍼 수수료 및 내용

Sheet 202412
A1: [지출] | I1: 전월 | J1: 202412 | K1: 당월 | L1: 202501 | N1: [소비 총계] | O1: =SUMIF(P3:P233,"지출",T3:T233) -> 0
A2: 대상월 | B2: SN | C2: 대분류 | D2: 중분류 | E2: 예산(기본) | F2: 예산(추가) | G2: 예산(합계) | H2: 전월 소비 | I2: 전월 차액 | J2: 소비 | K2: 예산-소비 | L2: 사용율 | N2: 날짜 | O2: 시간 | P2: 타입 | Q2: 대분류 | R2: 중분류 | S2: 내용 | T2: 금액 | U2: 화폐 | V2: 결제수단 | W2: 메모 | X2: 대상 | Y2: 과소비
A3: =$L$1 -> 202501 | B3: =ROW()-2 -> 1 | C3: 대출상환 | D3: 디딤돌 | E3: =SUMIFS('수입&예산'!$C$15:$C$34,'수입&예산'!$A$15:$A$34,C3,'수입&예산'!$B$15:$B$34,D3)*10000 -> 900000 | F3: 0 | G3: =SUM(E3:F3) -> 900000 | H3: =INDIRECT($J$1&"!J"&ROW()) -> -895849 | I3: =J3-H3 -> 0 | J3: =VLOOKUP(A3,대출!$B$4:$G$363,3,FALSE)*-1 -> -895849 | K3: =G3+J3 -> 4151 | L3: =IF(G3=0,0,-J3/G3) -> 0.99538778
A4: =$L$1 -> 202501 | B4: =ROW()-2 -> 2 | C4: 고정비 | D4: 용돈 | E4: =SUMIFS('수입&예산'!$G$15:$G$27,'수입&예산'!$A$15:$A$27,C4,'수입&예산'!$B$15:$B$27,D4)*10000 -> 100000 | F4: 0 | G4: =SUM(E4:F4) -> 100000 | H4: =INDIRECT($J$1&"!J"&ROW()) -> 0 | I4: =J4-H4 -> 0 | J4: =SUMIFS($T$3:$T$233,$P$3:$P$233,"지출",$Q$3:$Q$233,C4,$R$3:$R$233,D4) -> 0 | K4: =G4+J4 -> 100000 | L4: =IF(G4=0,0,-J4/G4) -> 0
A5: =$L$1 -> 202501 | B5: =ROW()-2 -> 3 | C5: 고정비 | D5: 휴대폰/인터넷 | E5: =SUMIFS('수입&예산'!$G$15:$G$27,'수입&예산'!$A$15:$A$27,C5,'수입&예산'!$B$15:$B$27,D5)*10000 -> 44000 | F5: 0 | G5: =SUM(E5:F5) -> 44000 | H5: =INDIRECT($J$1&"!J"&ROW()) -> 0 | I5: =J5-H5 -> 0 | J5: =SUMIFS($T$3:$T$233,$P$3:$P$233,"지출",$Q$3:$Q$233,C5,$R$3:$R$233,D5) -> 0 | K5: =G5+J5 -> 44000 | L5: =IF(G5=0,0,-J5/G5) -> 0
A6: =$L$1 -> 202501 | B6: =ROW()-2 -> 4 | C6: 고정비 | D6: 아파트관리비 | E6: =SUMIFS('수입&예산'!$G$15:$G$27,'수입&예산'!$A$15:$A$27,C6,'수입&예산'!$B$15:$B$27,D6)*10000 -> 330000 | F6: 0 | G6: =SUM(E6:F6) -> 330000 | H6: =INDIRECT($J$1&"!J"&ROW()) -> 0 | I6: =J6-H6 -> 0 | J6: =SUMIFS($T$3:$T$233,$P$3:$P$233,"지출",$Q$3:$Q$233,C6,$R$3:$R$233,D6) -> 0 | K6: =G6+J6 -> 330000 | L6: =IF(G6=0,0,-J6/G6) -> 0
A7: =$L$1 -> 202501 | B7: =ROW()-2 -> 5 | C7: 고정비 | D7: 기흥모임 | E7: =SUMIFS('수입&예산'!$G$15:$G$27,'수입&예산'!$A$15:$A$27,C7,'수입&예산'!$B$15:$B$27,D7)*10000 -> 130000 | F7: 0 | G7: =SUM(E7:F7) -> 130000 | H7: =INDIRECT($J$1&"!J"&ROW()) -> 0 | I7: =J7-H7 -> 0 | J7: =SUMIFS($T$3:$T$233,$P$3:$P$233,"지출",$Q$3:$Q$233,C7,$R$3:$R$233,D7) -> 0 | K7: =G7+J7 -> 130000 | L7: =IF(G7=0,0,-J7/G7) -> 0
A8: =$L$1 -> 202501 | B8: =ROW()-2 -> 6 | C8: 고정비 | D8: 부모님 | E8: =SUMIFS('수입&예산'!$G$15:$G$27,'수입&예산'!$A$15:$A$27,C8,'수입&예산'!$B$15:$B$27,D8)*10000 -> 171000 | F8: 0 | G8: =SUM(E8:F8) -> 171000 | H8: =INDIRECT($J$1&"!J"&ROW()) -> 0 | I8: =J8-H8 -> 0 | J8: =SUMIFS($T$3:$T$233,$P$3:$P$233,"지출",$Q$3:$Q$233,C8,$R$3:$R$233,D8) -> 0 | K8: =G8+J8 -> 171000 | L8: =IF(G8=0,0,-J8/G8) -> 0
A9: =$L$1 -> 202501 | B9: =ROW()-2 -> 7 | C9: 고정비 | D9: 보험/연금 | E9: =SUMIFS('수입&예산'!$G$15:$G$27,'수입&예산'!$A$15:$A$27,C9,'수입&예산'!$B$15:$B$27,D9)*10000 -> 246000 | F9: 0 | G9: =SUM(E9:F9) -> 246000 | H9: =INDIRECT($J$1&"!J"&ROW()) -> 0 | I9: =J9-H9 -> 0 | J9: =SUMIFS($T$3:$T$233,$P$3:$P$233,"지출",$Q$3:$Q$233,C9,$R$3:$R$233,D9) -> 0 | K9: =G9+J9 -> 246000 | L9: =IF(G9=0,0,-J9/G9) -> 0
A10: =$L$1 -> 202501 | B10: =ROW()-2 -> 8 | C10: 고정비 | D10: 교통비 | E10: =SUMIFS('수입&예산'!$G$15:$G$27,'수입&예산'!$A$15:$A$27,C10,'수입&예산'!$B$15:$B$27,D10)*10000 -> 160000 | F10: 0 | G10: =SUM(E10:F10) -> 160000 | H10: =INDIRECT($J$1&"!J"&ROW()) -> 0 | I10: =J10-H10 -> 0 | J10: =SUMIFS($T$3:$T$233,$P$3:$P$233,"지출",$Q$3:$Q$233,C10,$R$3:$R$233,D10) -> 0 | K10: =G10+J10 -> 160000 | L10: =IF(G10=0,0,-J10/G10) -> 0
A11: =$L$1 -> 202501 | B11: =ROW()-2 -> 9 | C11: 고정비 | D11: 구독형서비스 | E11: =SUMIFS('수입&예산'!$G$15:$G$27,'수입&예산'!$A$15:$A$27,C11,'수입&예산'!$B$15:$B$27,D11)*10000 -> 44000 | F11: 0 | G11: =SUM(E11:F11) -> 44000 | H11: =INDIRECT($J$1&"!J"&ROW()) -> 0 | I11: =J11-H11 -> 0 | J11: =SUMIFS($T$3:$T$233,$P$3:$P$233,"지출",$Q$3:$Q$233,C11,$R$3:$R$233,D11) -> 0 | K11: =G11+J11 -> 44000 | L11: =IF(G11=0,0,-J11/G11) -> 0
A12: =$L$1 -> 202501 | B12: =ROW()-2 -> 10 | C12: 생활비 | E12: =SUMIFS('수입&예산'!$G$15:$G$27,'수입&예산'!$A$15:$A$27,C12)*10000 -> 350000 | F12: 0 | G12: =SUM(E12:F12) -> 350000 | H12: =INDIRECT($J$1&"!J"&ROW()) -> 0 | I12: =J12-H12 -> 0 | J12: =SUMIFS($T$3:$T$233,$P$3:$P$233,"지출",$Q$3:$Q$233,C12) -> 0 | K12: =G12+J12 -> 350000 | L12: =IF(G12=0,0,-J12/G12) -> 0
A13: =$L$1 -> 202501 | B13: =ROW()-2 -> 11 | C13: 의료/건강 | E13: =SUMIFS('수입&예산'!$G$15:$G$27,'수입&예산'!$A$15:$A$27,C13)*10000 -> 0 | F13: =-J13 -> 0 | G13: =SUM(E13:F13) -> 0 | H13: =INDIRECT($J$1&"!J"&ROW()) -> 0 | I13: =J13-H13 -> 0 | J13: =SUMIFS($T$3:$T$233,$P$3:$P$233,"지출",$Q$3:$Q$233,C13) -> 0 | K13: =G13+J13 -> 0 | L13: =IF(G13=0,0,-J13/G13) -> 0
A14: =$L$1 -> 202501 | B14: =ROW()-2 -> 12 | C14: 모임 | E14: =SUMIFS('수입&예산'!$G$15:$G$27,'수입&예산'!$A$15:$A$27,C14)*10000 -> 0 | F14: =-J14 -> 0 | G14: =SUM(E14:F14) -> 0 | H14: =INDIRECT($J$1&"!J"&ROW()) -> 0 | I14: =J14-H14 -> 0 | J14: =SUMIFS($T$3:$T$233,$P$3:$P$233,"지출",$Q$3:$Q$233,C14) -> 0 | K14: =G14+J14 -> 0 | L14: =IF(G14=0,0,-J14/G14) -> 0
A15: =$L$1 -> 202501 | B15: =ROW()-2 -> 13 | C15: Tiss | E15: =SUMIFS('수입&예산'!$G$15:$G$27,'수입&예산'!A15:A27,C15,'수입&예산'!$H$15:$H$27,L1)*10000 -> 0 | F15: 0 | G15: =SUM(E15:F15) -> 0 | H15: =INDIRECT($J$1&"!J"&ROW()) -> 0 | I15: =J15-H15 -> 0 | J15: =SUMIFS($T$3:$T$233,$P$3:$P$233,"지출",$Q$3:$Q$233,C15) -> 0 | K15: =G15+J15 -> 0 | L15: =IF(G15=0,0,-J15/G15) -> 0
A16: =$L$1 -> 202501 | B16: =ROW()-2 -> 14 | C16: JM | E16: =SUMIFS('수입&예산'!$G$15:$G$27,'수입&예산'!A16:A28,C16,'수입&예산'!$H$15:$H$27,L2)*10000 -> 0 | F16: 0 | G16: =SUM(E16:F16) -> 0 | H16: =INDIRECT($J$1&"!J"&ROW()) -> 0 | I16: =J16-H16 -> 0 | J16: =SUMIFS($T$3:$T$233,$P$3:$P$233,"지출",$Q$3:$Q$233,C16) -> 0 | K16: =G16+J16 -> 0 | L16: =IF(G16=0,0,-J16/G16) -> 0
A17: =$L$1 -> 202501 | B17: =ROW()-2 -> 15 | C17: 세금 | E17: =SUMIFS('수입&예산'!$G$15:$G$27,'수입&예산'!A16:A28,C17,'수입&예산'!$H$15:$H$27,L2)*10000 -> 0 | F17: 0 | G17: =SUM(E17:F17) -> 0 | H17: =INDIRECT($J$1&"!J"&ROW()) -> 0 | I17: =J17-H17 -> 0 | J17: =SUMIFS($T$3:$T$233,$P$3:$P$233,"지출",$Q$3:$Q$233,C17) -> 0 | K17: =G17+J17 -> 0 | L17: =IF(G17=0,0,-J17/G17) -> 0
A18: =$L$1 -> 202501 | B18: =ROW()-2 -> 16 | C18: 기타 | E18: =SUMIFS('수입&예산'!$G$15:$G$27,'수입&예산'!$A$15:$A$27,C18)*10000 -> 350000 | F18: =-J18 -> 0 | G18: =SUM(E18:F18) -> 350000 | H18: =INDIRECT($J$1&"!J"&ROW()) -> 0 | I18: =J18-H18 -> 0 | J18: =SUMIFS($T$3:$T$233,$P$3:$P$233,"지출",$Q$3:$Q$233,C18) -> 0 | K18: =G18+J18 -> 350000 | L18: =IF(G18=0,0,-J18/G18) -> 0
A19: 합계 | E19: =SUM(E3:E17) -> 2475000 | F19: =SUM(F3:F17) -> 0 | G19: =SUM(G3:G17) -> 2475000 | H19: =SUM(H3:H17) -> -895849 | I19: =SUM(I3:I17) -> 0 | J19: =SUM(J3:J17) -> -895849 | K19: =SUM(K3:K17) -> 1579151 | L19: =IF(G19=0,0,-J19/G19) -> 0.36195919
I20: 예산(기본) 기준 | K20: =E19+J19 -> 1579151 | L20: =IF(E19=0,0,-J19/E19) -> 0.36195919
A22: (상세) | C22: 대분류 | D22: 중분류 | E22: 소비금액
C23: 생활비 | D23: 식비 | E23: =SUMIFS($T$3:$T$233,$P$3:$P$233,"지출",$Q$3:$Q$233,C23,$R$3:$R$233,D23) -> 0
C24: 생활비 | D24: 외식 | E24: =SUMIFS($T$3:$T$233,$P$3:$P$233,"지출",$Q$3:$Q$233,C24,$R$3:$R$233,D24) -> 0
C25: 생활비 | D25: 생활용품 | E25: =SUMIFS($T$3:$T$233,$P$3:$P$233,"지출",$Q$3:$Q$233,C25,$R$3:$R$233,D25) -> 0
C26: 생활비 | D26: 기타 | E26: =SUMIFS($T$3:$T$233,$P$3:$P$233,"지출",$Q$3:$Q$233,C26,$R$3:$R$233,D26) -> 0
C27: 생활비 합계 | E27: =SUM(E22:E26) -> 0
C28: 모임 | D28: 데이트 | E28: =SUMIFS($T$3:$T$233,$P$3:$P$233,"지출",$Q$3:$Q$233,C28,$R$3:$R$233,D28) -> 0
C29: 모임 | D29: 가족 | E29: =SUMIFS($T$3:$T$233,$P$3:$P$233,"지출",$Q$3:$Q$233,C29,$R$3:$R$233,D29) -> 0
C30: 모임 | D30: 기타 | E30: =SUMIFS($T$3:$T$233,$P$3:$P$233,"지출",$Q$3:$Q$233,C30,$R$3:$R$233,D30) -> 0
C31: 모임 합계 | E31: =SUM(E28:E30) -> 0
C32: 기타 | D32: 경조사 | E32: =SUMIFS($T$3:$T$233,$P$3:$P$233,"지출",$Q$3:$Q$233,C32,$R$3:$R$233,D32) -> 0
C33: 기타 | D33: 미용 | E33: =SUMIFS($T$3:$T$233,$P$3:$P$233,"지출",$Q$3:$Q$233,C33,$R$3:$R$233,D33) -> 0
C34: 기타 | D34: 의복 | E34: =SUMIFS($T$3:$T$233,$P$3:$P$233,"지출",$Q$3:$Q$233,C34,$R$3:$R$233,D34) -> 0
C35: 기타 | D35: 선물 | E35: =SUMIFS($T$3:$T$233,$P$3:$P$233,"지출",$Q$3:$Q$233,C35,$R$3:$R$233,D35) -> 0
C36: 기타 | D36: 교육 | E36: =SUMIFS($T$3:$T$233,$P$3:$P$233,"지출",$Q$3:$Q$233,C36,$R$3:$R$233,D36) -> 0
C37: 기타 | D37: 기타 | E37: =SUMIFS($T$3:$T$233,$P$3:$P$233,"지출",$Q$3:$Q$233,C37,$R$3:$R$233,D37) -> 0
C38: 기타 | D38: 취미/운동 | E38: =SUMIFS($T$3:$T$233,$P$3:$P$233,"지출",$Q$3:$Q$233,C38,$R$3:$R$233,D38) -> 0
C39: 기타 | D39: 가전제품 | E39: =SUMIFS($T$3:$T$233,$P$3:$P$233,"지출",$Q$3:$Q$233,C39,$R$3:$R$233,D39) -> 0
C40: 기타 합계 | E40: =SUM(E32:E35) -> 0
C41: Tiss | D41: 택시 | E41: =SUMIFS($T$3:$T$233,$P$3:$P$233,"지출",$Q$3:$Q$233,C41,$R$3:$R$233,D41) -> 0
...

Sheet 202501
A1: [지출] | I1: 전월 | J1: 202412 | K1: 당월 | L1: 202501 | N1: [소비 총계] | O1: =SUMIF(P3:P233,"지출",T3:T233) -> -3567122
A2: 대상월 | B2: SN | C2: 대분류 | D2: 중분류 | E2: 예산(기본) | F2: 예산(추가) | G2: 예산(합계) | H2: 전월 소비 | I2: 전월 차액 | J2: 소비 | K2: 예산-소비 | L2: 사용율 | N2: 날짜 | O2: 시간 | P2: 타입 | Q2: 대분류 | R2: 중분류 | S2: 내용 | T2: 금액 | U2: 화폐 | V2: 결제수단 | W2: 메모 | X2: 대상 | Y2: 과소비
A3: =$L$1 -> 202501 | B3: =ROW()-2 -> 1 | C3: 대출상환 | D3: 디딤돌 | E3: =SUMIFS('수입&예산'!$C$15:$C$34,'수입&예산'!$A$15:$A$34,C3,'수입&예산'!$B$15:$B$34,D3)*10000 -> 900000 | F3: 0 | G3: =SUM(E3:F3) -> 900000 | H3: =INDIRECT($J$1&"!J"&ROW()) -> -895849 | I3: =J3-H3 -> 0 | J3: =VLOOKUP(A3,대출!$B$4:$G$363,3,FALSE)*-1 -> -895849 | K3: =G3+J3 -> 4151 | L3: =IF(G3=0,0,-J3/G3) -> 0.99538778 | N3: 45659 | O3: 0.82672454 | P3: 지출 | Q3: Tiss | R3: 모임 | S3: 뽕나무쟁이족발 | T3: -63000 | U3: KRW | V3: 대한항공카드 030 | X3: Tiss | Y3: O
A4: =$L$1 -> 202501 | B4: =ROW()-2 -> 2 | C4: 고정비 | D4: 용돈 | E4: =SUMIFS('수입&예산'!$G$15:$G$27,'수입&예산'!$A$15:$A$27,C4,'수입&예산'!$B$15:$B$27,D4)*10000 -> 100000 | F4: 0 | G4: =SUM(E4:F4) -> 100000 | H4: =INDIRECT($J$1&"!J"&ROW()) -> 0 | I4: =J4-H4 -> -100000 | J4: =SUMIFS($T$3:$T$233,$P$3:$P$233,"지출",$Q$3:$Q$233,C4,$R$3:$R$233,D4) -> -100000 | K4: =G4+J4 -> 0 | L4: =IF(G4=0,0,-J4/G4) -> 1 | N4: 45660 | O4: 0.40185185 | P4: 지출 | Q4: 고정비 | R4: 구독형서비스 | S4: 쿠팡_와우멤버십 | T4: -7890 | U4: KRW | V4: 대한항공카드 030
A5: =$L$1 -> 202501 | B5: =ROW()-2 -> 3 | C5: 고정비 | D5: 휴대폰/인터넷 | E5: =SUMIFS('수입&예산'!$G$15:$G$27,'수입&예산'!$A$15:$A$27,C5,'수입&예산'!$B$15:$B$27,D5)*10000 -> 44000 | F5: 0 | G5: =SUM(E5:F5) -> 44000 | H5: =INDIRECT($J$1&"!J"&ROW()) -> 0 | I5: =J5-H5 -> -65890 | J5: =SUMIFS($T$3:$T$233,$P$3:$P$233,"지출",$Q$3:$Q$233,C5,$R$3:$R$233,D5) -> -65890 | K5: =G5+J5 -> -21890 | L5: =IF(G5=0,0,-J5/G5) -> 1.4975 | N5: 45660 | O5: 0.66283565 | P5: 지출 | Q5: 생활비 | R5: 식비 | S5: 쿠팡_쿠페이 | T5: -25540 | U5: KRW | V5: 대한항공카드 030
A6: =$L$1 -> 202501 | B6: =ROW()-2 -> 4 | C6: 고정비 | D6: 아파트관리비 | E6: =SUMIFS('수입&예산'!$G$15:$G$27,'수입&예산'!$A$15:$A$27,C6,'수입&예산'!$B$15:$B$27,D6)*10000 -> 330000 | F6: 0 | G6: =SUM(E6:F6) -> 330000 | H6: =INDIRECT($J$1&"!J"&ROW()) -> 0 | I6: =J6-H6 -> -367410 | J6: =SUMIFS($T$3:$T$233,$P$3:$P$233,"지출",$Q$3:$Q$233,C6,$R$3:$R$233,D6) -> -367410 | K6: =G6+J6 -> -37410 | L6: =IF(G6=0,0,-J6/G6) -> 1.1133636 | N6: 45660 | O6: 0.72605324 | P6: 지출 | Q6: 생활비 | R6: 식비 | S6: 쿠팡_쿠페이 | T6: -6230 | U6: KRW | V6: 대한항공카드 030
A7: =$L$1 -> 202501 | B7: =ROW()-2 -> 5 | C7: 고정비 | D7: 기흥모임 | E7: =SUMIFS('수입&예산'!$G$15:$G$27,'수입&예산'!$A$15:$A$27,C7,'수입&예산'!$B$15:$B$27,D7)*10000 -> 130000 | F7: 0 | G7: =SUM(E7:F7) -> 130000 | H7: =INDIRECT($J$1&"!J"&ROW()) -> 0 | I7: =J7-H7 -> -130000 | J7: =SUMIFS($T$3:$T$233,$P$3:$P$233,"지출",$Q$3:$Q$233,C7,$R$3:$R$233,D7) -> -130000 | K7: =G7+J7 -> 0 | L7: =IF(G7=0,0,-J7/G7) -> 1 | N7: 45661 | O7: 0.70269676 | P7: 지출 | Q7: 모임 | R7: 데이트 | S7: 코끼리만두 | T7: -17500 | U7: KRW | V7: 대한항공카드 030 | W7: 수원 데이트(1/4,토) - 저녁 | Y7: O
A8: =$L$1 -> 202501 | B8: =ROW()-2 -> 6 | C8: 고정비 | D8: 부모님 | E8: =SUMIFS('수입&예산'!$G$15:$G$27,'수입&예산'!$A$15:$A$27,C8,'수입&예산'!$B$15:$B$27,D8)*10000 -> 171000 | F8: 0 | G8: =SUM(E8:F8) -> 171000 | H8: =INDIRECT($J$1&"!J"&ROW()) -> 0 | I8: =J8-H8 -> -162690 | J8: =SUMIFS($T$3:$T$233,$P$3:$P$233,"지출",$Q$3:$Q$233,C8,$R$3:$R$233,D8) -> -162690 | K8: =G8+J8 -> 8310 | L8: =IF(G8=0,0,-J8/G8) -> 0.95140351 | N8: 45661 | O8: 0.71642361 | P8: 지출 | Q8: 모임 | R8: 데이트 | S8: 토스 김미진 | T8: -2000 | U8: KRW | V8: 월급/생활비 | W8: 수원 데이트(1/4,토) - 간식 | Y8: O
A9: =$L$1 -> 202501 | B9: =ROW()-2 -> 7 | C9: 고정비 | D9: 보험/연금 | E9: =SUMIFS('수입&예산'!$G$15:$G$27,'수입&예산'!$A$15:$A$27,C9,'수입&예산'!$B$15:$B$27,D9)*10000 -> 246000 | F9: 0 | G9: =SUM(E9:F9) -> 246000 | H9: =INDIRECT($J$1&"!J"&ROW()) -> 0 | I9: =J9-H9 -> -218959 | J9: =SUMIFS($T$3:$T$233,$P$3:$P$233,"지출",$Q$3:$Q$233,C9,$R$3:$R$233,D9) -> -218959 | K9: =G9+J9 -> 27041 | L9: =IF(G9=0,0,-J9/G9) -> 0.89007724 | N9: 45661 | O9: 0.72434028 | P9: 지출 | Q9: 모임 | R9: 데이트 | S9: 안다미로 | T9: -17000 | U9: KRW | V9: 대한항공카드 030 | W9: 수원 데이트(1/4,토) - 카페 | Y9: O
A10: =$L$1 -> 202501 | B10: =ROW()-2 -> 8 | C10: 고정비 | D10: 교통비 | E10: =SUMIFS('수입&예산'!$G$15:$G$27,'수입&예산'!$A$15:$A$27,C10,'수입&예산'!$B$15:$B$27,D10)*10000 -> 160000 | F10: 0 | G10: =SUM(E10:F10) -> 160000 | H10: =INDIRECT($J$1&"!J"&ROW()) -> 0 | I10: =J10-H10 -> -5800 | J10: =SUMIFS($T$3:$T$233,$P$3:$P$233,"지출",$Q$3:$Q$233,C10,$R$3:$R$233,D10) -> -5800 | K10: =G10+J10 -> 154200 | L10: =IF(G10=0,0,-J10/G10) -> 0.03625 | N10: 45661 | O10: 0.77408565 | P10: 지출 | Q10: 생활비 | R10: 식비 | S10: 명동만두 | T10: -16000 | U10: KRW | V10: 대한항공카드 030 | W10: 수원 데이트(1/4,토) - 만두(식비) | Y10: O
A11: =$L$1 -> 202501 | B11: =ROW()-2 -> 9 | C11: 고정비 | D11: 구독형서비스 | E11: =SUMIFS('수입&예산'!$G$15:$G$27,'수입&예산'!$A$15:$A$27,C11,'수입&예산'!$B$15:$B$27,D11)*10000 -> 44000 | F11: 0 | G11: =SUM(E11:F11) -> 44000 | H11: =INDIRECT($J$1&"!J"&ROW()) -> 0 | I11: =J11-H11 -> -35690 | J11: =SUMIFS($T$3:$T$233,$P$3:$P$233,"지출",$Q$3:$Q$233,C11,$R$3:$R$233,D11) -> -35690 | K11: =G11+J11 -> 8310 | L11: =IF(G11=0,0,-J11/G11) -> 0.81113636 | N11: 45661 | O11: 0.80642361 | P11: 지출 | Q11: 의료/건강 | R11: 약국 | S11: 3층온누리약국 | T11: -2000 | U11: KRW | V11: 대한항공카드 030
A12: =$L$1 -> 202501 | B12: =ROW()-2 -> 10 | C12: 생활비 | E12: =SUMIFS('수입&예산'!$G$15:$G$27,'수입&예산'!$A$15:$A$27,C12)*10000 -> 350000 | F12: 0 | G12: =SUM(E12:F12) -> 350000 | H12: =INDIRECT($J$1&"!J"&ROW()) -> 0 | I12: =J12-H12 -> -889769 | J12: =SUMIFS($T$3:$T$233,$P$3:$P$233,"지출",$Q$3:$Q$233,C12) -> -889769 | K12: =G12+J12 -> -539769 | L12: =IF(G12=0,0,-J12/G12) -> 2.5421971 | N12: 45661 | O12: 0.81508102 | P12: 지출 | Q12: 생활비 | R12: 생활용품 | S12: 다이소아성산업 | T12: -10000 | U12: KRW | V12: 대한항공카드 030
A13: =$L$1 -> 202501 | B13: =ROW()-2 -> 11 | C13: 의료/건강 | E13: =SUMIFS('수입&예산'!$G$15:$G$27,'수입&예산'!$A$15:$A$27,C13)*10000 -> 0 | F13: =-J13 -> 2000 | G13: =SUM(E13:F13) -> 2000 | H13: =INDIRECT($J$1&"!J"&ROW()) -> 0 | I13: =J13-H13 -> -2000 | J13: =SUMIFS($T$3:$T$233,$P$3:$P$233,"지출",$Q$3:$Q$233,C13) -> -2000 | K13: =G13+J13 -> 0 | L13: =IF(G13=0,0,-J13/G13) -> 1 | N13: 45662 | O13: 0.8446412 | P13: 지출 | Q13: 생활비 | R13: 생활용품 | S13: 쿠팡_쿠페이 | T13: -26240 | U13: KRW | V13: 대한항공카드 030
A14: =$L$1 -> 202501 | B14: =ROW()-2 -> 12 | C14: 모임 | E14: =SUMIFS('수입&예산'!$G$15:$G$27,'수입&예산'!$A$15:$A$27,C14)*10000 -> 0 | F14: =-J14 -> 36500 | G14: =SUM(E14:F14) -> 36500 | H14: =INDIRECT($J$1&"!J"&ROW()) -> 0 | I14: =J14-H14 -> -36500 | J14: =SUMIFS($T$3:$T$233,$P$3:$P$233,"지출",$Q$3:$Q$233,C14) -> -36500 | K14: =G14+J14 -> 0 | L14: =IF(G14=0,0,-J14/G14) -> 1 | N14: 45663 | O14: 0.71940972 | P14: 지출 | Q14: 기타 | R14: 선물 | S14: 카카오선물하기_카카오페이 | T14: -25900 | U14: KRW | V14: 대한항공카드 030 | W14: 이미형 과장 생선
A15: =$L$1 -> 202501 | B15: =ROW()-2 -> 13 | C15: Tiss | E15: =SUMIFS('수입&예산'!$G$15:$G$27,'수입&예산'!A15:A27,C15,'수입&예산'!$H$15:$H$27,L1)*10000 -> 0 | F15: 0 | G15: =SUM(E15:F15) -> 0 | H15: =INDIRECT($J$1&"!J"&ROW()) -> 0 | I15: =J15-H15 -> -63000 | J15: =SUMIFS($T$3:$T$233,$P$3:$P$233,"지출",$Q$3:$Q$233,C15) -> -63000 | K15: =G15+J15 -> -63000 | L15: =IF(G15=0,0,-J15/G15) -> 0 | N15: 45663 | O15: 0.92756944 | P15: 지출 | Q15: 생활비 | R15: 기타 | S15: 토스 박미선 | T15: -317000 | U15: KRW | V15: 월급/생활비 | W15: 코스트코
A16: =$L$1 -> 202501 | B16: =ROW()-2 -> 14 | C16: JM | E16: =SUMIFS('수입&예산'!$G$15:$G$27,'수입&예산'!A16:A28,C16,'수입&예산'!$H$15:$H$27,L2)*10000 -> 0 | F16: 0 | G16: =SUM(E16:F16) -> 0 | H16: =INDIRECT($J$1&"!J"&ROW()) -> 0 | I16: =J16-H16 -> 0 | J16: =SUMIFS($T$3:$T$233,$P$3:$P$233,"지출",$Q$3:$Q$233,C16) -> 0 | K16: =G16+J16 -> 0 | L16: =IF(G16=0,0,-J16/G16) -> 0 | N16: 45666 | O16: 0.44849537 | P16: 이체 | Q16: 복지포인트 | R16: 미분류 | S16: 차액 | T16: 1000000 | U16: KRW | V16: 복지포인트
A17: =$L$1 -> 202501 | B17: =ROW()-2 -> 15 | C17: 세금 | E17: =SUMIFS('수입&예산'!$G$15:$G$27,'수입&예산'!A16:A28,C17,'수입&예산'!$H$15:$H$27,L2)*10000 -> 0 | F17: 0 | G17: =SUM(E17:F17) -> 0 | H17: =INDIRECT($J$1&"!J"&ROW()) -> 0 | I17: =J17-H17 -> 0 | J17: =SUMIFS($T$3:$T$233,$P$3:$P$233,"지출",$Q$3:$Q$233,C17) -> 0 | K17: =G17+J17 -> 0 | L17: =IF(G17=0,0,-J17/G17) -> 0 | N17: 45666 | O17: 0.83646991 | P17: 지출 | Q17: 생활비 | R17: 식비 | S17: 마켓9단 | T17: -10000 | U17: KRW | V17: 복지포인트 | W17: 강남역-마늘빵 | Y17: O
A18: =$L$1 -> 202501 | B18: =ROW()-2 -> 16 | C18: 기타 | E18: =SUMIFS('수입&예산'!$G$15:$G$27,'수입&예산'!$A$15:$A$27,C18)*10000 -> 350000 | F18: =-J18 -> 593565 | G18: =SUM(E18:F18) -> 943565 | H18: =INDIRECT($J$1&"!J"&ROW()) -> 0 | I18: =J18-H18 -> -593565 | J18: =SUMIFS($T$3:$T$233,$P$3:$P$233,"지출",$Q$3:$Q$233,C18) -> -593565 | K18: =G18+J18 -> 350000 | L18: =IF(G18=0,0,-J18/G18) -> 0.62906636 | N18: 45667 | O18: 0.35170139 | P18: 지출 | Q18: 생활비 | R18: 생활용품 | S18: 쿠팡_쿠페이 | T18: -17080 | U18: KRW | V18: 대한항공카드 030
A19: 합계 | E19: =SUM(E3:E18) -> 2825000 | F19: =SUM(F3:F18) -> 632065 | G19: =SUM(G3:G18) -> 3457065 | H19: =SUM(H3:H18) -> -895849 | I19: =SUM(I3:I18) -> -2671273 | J19: =SUM(J3:J18) -> -3567122 | K19: =SUM(K3:K18) -> -110057 | L19: =IF(G19=0,0,-J19/G19) -> 1.0318354 | N19: 45668 | O19: 0.67336806 | P19: 지출 | Q19: 생활비 | R19: 생활용품 | S19: aliexpress | T19: -13484 | U19: KRW | V19: 대한항공카드 030 | W19: 충전기/케이블 | Y19: O
I20: 예산(기본) 기준 | K20: =E19+J19 -> -742122 | L20: =IF(E19=0,0,-J19/E19) -> 1.2626981 | N20: 45668 | O20: 0.84925926 | P20: 지출 | Q20: 생활비 | R20: 생활용품 | S20: 쿠팡_쿠페이 | T20: -7900 | U20: KRW | V20: 대한항공카드 030 | W20: 와인쇼핑백
N21: 45668 | O21: 0.8630787 | P21: 지출 | Q21: 생활비 | R21: 생활용품 | S21: 다이소아성산업 | T21: -10000 | U21: KRW | V21: 대한항공카드 030 | W21: 리들샷(2팩), 지퍼백, 제습제
A22: (상세) | C22: 대분류 | D22: 중분류 | E22: 소비금액 | N22: 45669 | O22: 0.83332176 | P22: 지출 | Q22: 생활비 | R22: 생활용품 | S22: 쿠팡_쿠페이 | T22: -29900 | U22: KRW | V22: 대한항공카드 030 | W22: 유기농사과식초, 키친타올걸이
C23: 생활비 | D23: 식비 | E23: =SUMIFS($T$3:$T$233,$P$3:$P$233,"지출",$Q$3:$Q$233,C23,$R$3:$R$233,D23) -> -199810 | N23: 45670 | O23: 0.79099537 | P23: 지출 | Q23: 기타 | R23: 미용 | S23: *161원캐쉬백다이소 | T23: -32039 | U23: KRW | V23: 월급/생활비 | W23: 리들샷(10팩), 제습제
C24: 생활비 | D24: 외식 | E24: =SUMIFS($T$3:$T$233,$P$3:$P$233,"지출",$Q$3:$Q$233,C24,$R$3:$R$233,D24) -> -89760 | N24: 45670 | O24: 0.80646991 | P24: 이체 | Q24: 카드대금 | R24: 미분류 | S24: 현대카드대금 | T24: -903017 | U24: KRW | V24: 월급/생활비
C25: 생활비 | D25: 생활용품 | E25: =SUMIFS($T$3:$T$233,$P$3:$P$233,"지출",$Q$3:$Q$233,C25,$R$3:$R$233,D25) -> -280199 | N25: 45671 | O25: 0.77190972 | P25: 이체 | Q25: 카드대금 | R25: 미분류 | S25: KB카드출금 | T25: -451140 | U25: KRW | V25: 월급/생활비
C26: 생활비 | D26: 기타 | E26: =SUMIFS($T$3:$T$233,$P$3:$P$233,"지출",$Q$3:$Q$233,C26,$R$3:$R$233,D26) -> -320000 | N26: 45671 | O26: 0.91105324 | P26: 지출 | Q26: 생활비 | R26: 식비 | S26: GS25기흥센트럴점 | T26: -3500 | U26: KRW | V26: 대한항공카드 030
C27: 생활비 합계 | E27: =SUM(E21:E26) -> -889769 | N27: 45674 | O27: 0.37206019 | P27: 지출 | Q27: 생활비 | R27: 식비 | S27: 쿠팡_쿠페이 | T27: -20530 | U27: KRW | V27: 대한항공카드 030 | W27: 어묵, 치즈스틱
C28: 모임 | D28: 데이트 | E28: =SUMIFS($T$3:$T$233,$P$3:$P$233,"지출",$Q$3:$Q$233,C28,$R$3:$R$233,D28) -> -36500 | N28: 45674 | O28: 0.38928241 | P28: 지출 | Q28: 생활비 | R28: 외식 | S28: 쿠팡이츠 | T28: -29260 | U28: KRW | V28: 대한항공카드 030 | W28: 배달-프랭크버거 | Y28: O
C29: 모임 | D29: 가족 | E29: =SUMIFS($T$3:$T$233,$P$3:$P$233,"지출",$Q$3:$Q$233,C29,$R$3:$R$233,D29) -> 0 | N29: 45674 | O29: 0.58393519 | P29: 수입 | Q29: 기타 상여금 | R29: 미분류 | S29: 오토에버경비 | T29: 55199 | U29: KRW | V29: 월급/생활비 | W29: 통신비 지원
C30: 모임 | D30: 기타 | E30: =SUMIFS($T$3:$T$233,$P$3:$P$233,"지출",$Q$3:$Q$233,C30,$R$3:$R$233,D30) -> 0 | N30: 45674 | O30: 0.60329861 | P30: 지출 | Q30: 기타 | R30: 경조사 | S30: 송금 내역 | T30: -50000 | U30: KRW | V30: 카카오페이 머니 | W30: 노찬형 책임 자식 결혼
C31: 모임 합계 | E31: =SUM(E28:E30) -> -36500 | N31: 45675 | O31: 0.72738426 | P31: 지출 | Q31: 생활비 | R31: 식비 | S31: 쿠팡_쿠페이 | T31: -9140 | U31: KRW | V31: 대한항공카드 030 | W31: 몽쉘통통(딸기) | Y31: O
C32: 기타 | D32: 경조사 | E32: =SUMIFS($T$3:$T$233,$P$3:$P$233,"지출",$Q$3:$Q$233,C32,$R$3:$R$233,D32) -> -50000 | N32: 45676 | O32: 0.36712963 | P32: 이체 | Q32: 저축 | R32: 미분류 | S32: 계좌개설용4528 | T32: 1 | U32: KRW | V32: 월급/생활비
C33: 기타 | D33: 미용 | E33: =SUMIFS($T$3:$T$233,$P$3:$P$233,"지출",$Q$3:$Q$233,C33,$R$3:$R$233,D33) -> -32039 | N33: 45676 | O33: 0.36752315 | P33: 이체 | Q33: 이체 | R33: 미분류 | S33: 비대면신규 | T33: 0 | U33: KRW | V33: E-RUN 파킹통장(예스뱅킹)
C34: 기타 | D34: 의복 | E34: =SUMIFS($T$3:$T$233,$P$3:$P$233,"지출",$Q$3:$Q$233,C34,$R$3:$R$233,D34) -> 0 | N34: 45676 | O34: 0.77175926 | P34: 지출 | Q34: 기타 | R34: 가전제품 | S34: 쿠팡_쿠페이 | T34: -36170 | U34: KRW | V34: 대한항공카드 030 | W34: 쿠팡-다리미판
C35: 기타 | D35: 선물 | E35: =SUMIFS($T$3:$T$233,$P$3:$P$233,"지출",$Q$3:$Q$233,C35,$R$3:$R$233,D35) -> -340950 | N35: 45676 | O35: 0.78306713 | P35: 지출 | Q35: 생활비 | R35: 기타 | S35: 공공온라인_4 | T35: -3000 | U35: KRW | V35: 대한항공카드 030 | W35: 다리미판 처리(빼기)
C36: 기타 | D36: 교육 | E36: =SUMIFS($T$3:$T$233,$P$3:$P$233,"지출",$Q$3:$Q$233,C36,$R$3:$R$233,D36) -> 0 | N36: 45676 | O36: 0.79788194 | P36: 지출 | Q36: 생활비 | R36: 생활용품 | S36: 쿠팡_쿠페이 | T36: -9500 | U36: KRW | V36: 대한항공카드 030 | W36: 쿠팡-비닐봉투(80L 100장)
C37: 기타 | D37: 기타 | E37: =SUMIFS($T$3:$T$233,$P$3:$P$233,"지출",$Q$3:$Q$233,C37,$R$3:$R$233,D37) -> 0 | N37: 45676 | O37: 0.82934028 | P37: 이체 | Q37: 이체 | R37: 미분류 | S37: 카카오페이 | T37: -1000000 | U37: KRW | V37: 월급/생활비
C38: 기타 | D38: 취미/운동 | E38: =SUMIFS($T$3:$T$233,$P$3:$P$233,"지출",$Q$3:$Q$233,C38,$R$3:$R$233,D38) -> 0 | N38: 45676 | O38: 0.82934028 | P38: 이체 | Q38: 이체 | R38: 미분류 | S38: 박*현 | T38: 1000000 | U38: KRW | V38: 카카오페이 머니
C39: 기타 | D39: 가전제품 | E39: =SUMIFS($T$3:$T$233,$P$3:$P$233,"지출",$Q$3:$Q$233,C39,$R$3:$R$233,D39) -> -170576 | N39: 45677 | O39: 0.40868056 | P39: 지출 | Q39: 고정비 | R39: 휴대폰/인터넷 | S39: KT인터넷제휴납부 | T39: -22000 | U39: KRW | V39: 대한항공카드 030
C40: 기타 합계 | E40: =SUM(E32:E39) -> -593565 | N40: 45677 | O40: 0.40868056 | P40: 지출 | Q40: 고정비 | R40: 휴대폰/인터넷 | S40: KT통신요금자동납부 | T40: -43890 | U40: KRW | V40: 대한항공카드 030
...

Sheet 202502
A1: [지출] | I1: 전월 | J1: 202501 | K1: 당월 | L1: 202502 | N1: [소비 총계] | O1: =SUMIF(P3:P233,"지출",T3:T233) -> -6131264
A2: 대상월 | B2: SN | C2: 대분류 | D2: 중분류 | E2: 예산(기본) | F2: 예산(추가) | G2: 예산(합계) | H2: 전월 소비 | I2: 전월 차액 | J2: 소비 | K2: 예산-소비 | L2: 사용율 | N2: 날짜 | O2: 시간 | P2: 타입 | Q2: 대분류 | R2: 중분류 | S2: 내용 | T2: 금액 | U2: 화폐 | V2: 결제수단 | W2: 메모 | X2: 대상 | Y2: 과소비
A3: =$L$1 -> 202502 | B3: =ROW()-2 -> 1 | C3: 대출상환 | D3: 디딤돌 | E3: =SUMIFS('수입&예산'!$C$15:$C$34,'수입&예산'!$A$15:$A$34,C3,'수입&예산'!$B$15:$B$34,D3)*10000 -> 900000 | F3: 0 | G3: =SUM(E3:F3) -> 900000 | H3: =INDIRECT($J$1&"!J"&ROW()) -> -895849 | I3: =J3-H3 -> 993 | J3: =VLOOKUP(A3,대출!$B$4:$G$363,3,FALSE)*-1 -> -894856 | K3: =G3+J3 -> 5144 | L3: =IF(G3=0,0,-J3/G3) -> 0.99428444 | N3: 45689 | O3: 0.36212963 | P3: 이체 | Q3: 이체 | R3: 미분류 | S3: 차액 | T3: -5395 | U3: KRW | V3: 경기화폐(Tiss)
A4: =$L$1 -> 202502 | B4: =ROW()-2 -> 2 | C4: 고정비 | D4: 용돈 | E4: =SUMIFS('수입&예산'!$G$15:$G$27,'수입&예산'!$A$15:$A$27,C4,'수입&예산'!$B$15:$B$27,D4)*10000 -> 100000 | F4: 0 | G4: =SUM(E4:F4) -> 100000 | H4: =INDIRECT($J$1&"!J"&ROW()) -> -100000 | I4: =J4-H4 -> 0 | J4: =SUMIFS($T$3:$T$233,$P$3:$P$233,"지출",$Q$3:$Q$233,C4,$R$3:$R$233,D4) -> -100000 | K4: =G4+J4 -> 0 | L4: =IF(G4=0,0,-J4/G4) -> 1 | N4: 45689 | O4: 0.36394676 | P4: 이체 | Q4: 이체 | R4: 미분류 | S4: 자산 추가 | T4: 782000 | U4: KRW | V4: 온누리상품권
A5: =$L$1 -> 202502 | B5: =ROW()-2 -> 3 | C5: 고정비 | D5: 휴대폰/인터넷 | E5: =SUMIFS('수입&예산'!$G$15:$G$27,'수입&예산'!$A$15:$A$27,C5,'수입&예산'!$B$15:$B$27,D5)*10000 -> 44000 | F5: 0 | G5: =SUM(E5:F5) -> 44000 | H5: =INDIRECT($J$1&"!J"&ROW()) -> -65890 | I5: =J5-H5 -> -6400 | J5: =SUMIFS($T$3:$T$233,$P$3:$P$233,"지출",$Q$3:$Q$233,C5,$R$3:$R$233,D5) -> -72290 | K5: =G5+J5 -> -28290 | L5: =IF(G5=0,0,-J5/G5) -> 1.6429545 | N5: 45689 | O5: 0.39429398 | P5: 이체 | Q5: 이체 | R5: 미분류 | S5: 티머니569 | T5: 1 | U5: KRW | V5: 월급/생활비
A6: =$L$1 -> 202502 | B6: =ROW()-2 -> 4 | C6: 고정비 | D6: 아파트관리비 | E6: =SUMIFS('수입&예산'!$G$15:$G$27,'수입&예산'!$A$15:$A$27,C6,'수입&예산'!$B$15:$B$27,D6)*10000 -> 330000 | F6: 0 | G6: =SUM(E6:F6) -> 330000 | H6: =INDIRECT($J$1&"!J"&ROW()) -> -367410 | I6: =J6-H6 -> 156160 | J6: =SUMIFS($T$3:$T$233,$P$3:$P$233,"지출",$Q$3:$Q$233,C6,$R$3:$R$233,D6) -> -211250 | K6: =G6+J6 -> 118750 | L6: =IF(G6=0,0,-J6/G6) -> 0.64015152 | N6: 45689 | O6: 0.40708333 | P6: 지출 | Q6: 고정비 | R6: 교통비 | S6: 티머니 | T6: -80000 | U6: KRW | V6: 월급/생활비 | W6: JM 교통비 충전
A7: =$L$1 -> 202502 | B7: =ROW()-2 -> 5 | C7: 고정비 | D7: 기흥모임 | E7: =SUMIFS('수입&예산'!$G$15:$G$27,'수입&예산'!$A$15:$A$27,C7,'수입&예산'!$B$15:$B$27,D7)*10000 -> 130000 | F7: 0 | G7: =SUM(E7:F7) -> 130000 | H7: =INDIRECT($J$1&"!J"&ROW()) -> -130000 | I7: =J7-H7 -> 0 | J7: =SUMIFS($T$3:$T$233,$P$3:$P$233,"지출",$Q$3:$Q$233,C7,$R$3:$R$233,D7) -> -130000 | K7: =G7+J7 -> 0 | L7: =IF(G7=0,0,-J7/G7) -> 1 | N7: 45689 | O7: 0.48016204 | P7: 지출 | Q7: 기타 | R7: 미용 | S7: CJ올리브영_국내 | T7: -23500 | U7: KRW | V7: 대한항공카드 030 | W7: 리들샷
A8: =$L$1 -> 202502 | B8: =ROW()-2 -> 6 | C8: 고정비 | D8: 부모님 | E8: =SUMIFS('수입&예산'!$G$15:$G$27,'수입&예산'!$A$15:$A$27,C8,'수입&예산'!$B$15:$B$27,D8)*10000 -> 171000 | F8: 0 | G8: =SUM(E8:F8) -> 171000 | H8: =INDIRECT($J$1&"!J"&ROW()) -> -162690 | I8: =J8-H8 -> 62690 | J8: =SUMIFS($T$3:$T$233,$P$3:$P$233,"지출",$Q$3:$Q$233,C8,$R$3:$R$233,D8) -> -100000 | K8: =G8+J8 -> 71000 | L8: =IF(G8=0,0,-J8/G8) -> 0.58479532 | N8: 45689 | O8: 0.52059028 | P8: 지출 | Q8: 의료/건강 | R8: 미분류 | S8: 분당내마음정신건강의학과 | T8: -23100 | U8: KRW | V8: 대한항공카드 030
A9: =$L$1 -> 202502 | B9: =ROW()-2 -> 7 | C9: 고정비 | D9: 보험/연금 | E9: =SUMIFS('수입&예산'!$G$15:$G$27,'수입&예산'!$A$15:$A$27,C9,'수입&예산'!$B$15:$B$27,D9)*10000 -> 246000 | F9: 0 | G9: =SUM(E9:F9) -> 246000 | H9: =INDIRECT($J$1&"!J"&ROW()) -> -218959 | I9: =J9-H9 -> -62690 | J9: =SUMIFS($T$3:$T$233,$P$3:$P$233,"지출",$Q$3:$Q$233,C9,$R$3:$R$233,D9) -> -281649 | K9: =G9+J9 -> -35649 | L9: =IF(G9=0,0,-J9/G9) -> 1.1449146 | N9: 45689 | O9: 0.52315972 | P9: 지출 | Q9: 의료/건강 | R9: 약국 | S9: 정자프라자약국 | T9: -5800 | U9: KRW | V9: 대한항공카드 030
A10: =$L$1 -> 202502 | B10: =ROW()-2 -> 8 | C10: 고정비 | D10: 교통비 | E10: =SUMIFS('수입&예산'!$G$15:$G$27,'수입&예산'!$A$15:$A$27,C10,'수입&예산'!$B$15:$B$27,D10)*10000 -> 160000 | F10: 0 | G10: =SUM(E10:F10) -> 160000 | H10: =INDIRECT($J$1&"!J"&ROW()) -> -5800 | I10: =J10-H10 -> -74200 | J10: =SUMIFS($T$3:$T$233,$P$3:$P$233,"지출",$Q$3:$Q$233,C10,$R$3:$R$233,D10) -> -80000 | K10: =G10+J10 -> 80000 | L10: =IF(G10=0,0,-J10/G10) -> 0.5 | N10: 45689 | O10: 0.54458333 | P10: 지출 | Q10: 생활비 | R10: 생활용품 | S10: 다이소아성산업 | T10: -39000 | U10: KRW | V10: 대한항공카드 030 | W10: 리들샷
A11: =$L$1 -> 202502 | B11: =ROW()-2 -> 9 | C11: 고정비 | D11: 구독형서비스 | E11: =SUMIFS('수입&예산'!$G$15:$G$27,'수입&예산'!$A$15:$A$27,C11,'수입&예산'!$B$15:$B$27,D11)*10000 -> 44000 | F11: 0 | G11: =SUM(E11:F11) -> 44000 | H11: =INDIRECT($J$1&"!J"&ROW()) -> -35690 | I11: =J11-H11 -> 27800 | J11: =SUMIFS($T$3:$T$233,$P$3:$P$233,"지출",$Q$3:$Q$233,C11,$R$3:$R$233,D11) -> -7890 | K11: =G11+J11 -> 36110 | L11: =IF(G11=0,0,-J11/G11) -> 0.17931818 | N11: 45689 | O11: 0.55493056 | P11: 지출 | Q11: 생활비 | R11: 기타 | S11: 롯데프리미엄푸드마켓기흥점 | T11: -28900 | U11: KRW | V11: 대한항공카드 030 | W11: 술
A12: =$L$1 -> 202502 | B12: =ROW()-2 -> 10 | C12: 생활비 | E12: =SUMIFS('수입&예산'!$G$15:$G$27,'수입&예산'!$A$15:$A$27,C12)*10000 -> 350000 | F12: 0 | G12: =SUM(E12:F12) -> 350000 | H12: =INDIRECT($J$1&"!J"&ROW()) -> -889769 | I12: =J12-H12 -> 372053 | J12: =SUMIFS($T$3:$T$233,$P$3:$P$233,"지출",$Q$3:$Q$233,C12) -> -517716 | K12: =G12+J12 -> -167716 | L12: =IF(G12=0,0,-J12/G12) -> 1.4791886 | N12: 45689 | O12: 0.55972222 | P12: 지출 | Q12: 생활비 | R12: 식비 | S12: 르봉베이커리 | T12: -4800 | U12: KRW | V12: 경기화폐(JM)
A13: =$L$1 -> 202502 | B13: =ROW()-2 -> 11 | C13: 의료/건강 | E13: =SUMIFS('수입&예산'!$G$15:$G$27,'수입&예산'!$A$15:$A$27,C13)*10000 -> 0 | F13: =-J13 -> 367900 | G13: =SUM(E13:F13) -> 367900 | H13: =INDIRECT($J$1&"!J"&ROW()) -> -2000 | I13: =J13-H13 -> -365900 | J13: =SUMIFS($T$3:$T$233,$P$3:$P$233,"지출",$Q$3:$Q$233,C13) -> -367900 | K13: =G13+J13 -> 0 | L13: =IF(G13=0,0,-J13/G13) -> 1 | N13: 45689 | O13: 0.59813657 | P13: 지출 | Q13: 생활비 | R13: 생활용품 | S13: 쿠팡_쿠페이 | T13: -6490 | U13: KRW | V13: 대한항공카드 030 | W13: 쿠팡-멀티포트 충전기
A14: =$L$1 -> 202502 | B14: =ROW()-2 -> 12 | C14: 모임 | E14: =SUMIFS('수입&예산'!$G$15:$G$27,'수입&예산'!$A$15:$A$27,C14)*10000 -> 0 | F14: =-J14 -> 243950 | G14: =SUM(E14:F14) -> 243950 | H14: =INDIRECT($J$1&"!J"&ROW()) -> -36500 | I14: =J14-H14 -> -207450 | J14: =SUMIFS($T$3:$T$233,$P$3:$P$233,"지출",$Q$3:$Q$233,C14) -> -243950 | K14: =G14+J14 -> 0 | L14: =IF(G14=0,0,-J14/G14) -> 1 | N14: 45690 | O14: 0.4822338 | P14: 지출 | Q14: 기타 | R14: 의복 | S14: 스케쳐스수원영통점 | T14: -98200 | U14: KRW | V14: 대한항공카드 030 | W14: JM 운동화
A15: =$L$1 -> 202502 | B15: =ROW()-2 -> 13 | C15: Tiss | E15: =SUMIFS('수입&예산'!$G$15:$G$27,'수입&예산'!A15:A27,C15,'수입&예산'!$H$15:$H$27,L1)*10000 -> 0 | F15: 0 | G15: =SUM(E15:F15) -> 0 | H15: =INDIRECT($J$1&"!J"&ROW()) -> -63000 | I15: =J15-H15 -> 63000 | J15: =SUMIFS($T$3:$T$233,$P$3:$P$233,"지출",$Q$3:$Q$233,C15) -> 0 | K15: =G15+J15 -> 0 | L15: =IF(G15=0,0,-J15/G15) -> 0 | N15: 45690 | O15: 0.52224537 | P15: 지출 | Q15: 생활비 | R15: 외식 | S15: 진짜순대 | T15: -30000 | U15: KRW | V15: 대한항공카드 030
A16: =$L$1 -> 202502 | B16: =ROW()-2 -> 14 | C16: JM | E16: =SUMIFS('수입&예산'!$G$15:$G$27,'수입&예산'!A16:A28,C16,'수입&예산'!$H$15:$H$27,L2)*10000 -> 0 | F16: 0 | G16: =SUM(E16:F16) -> 0 | H16: =INDIRECT($J$1&"!J"&ROW()) -> 0 | I16: =J16-H16 -> -20690 | J16: =SUMIFS($T$3:$T$233,$P$3:$P$233,"지출",$Q$3:$Q$233,C16) -> -20690 | K16: =G16+J16 -> -20690 | L16: =IF(G16=0,0,-J16/G16) -> 0 | N16: 45690 | O16: 0.55136574 | P16: 지출 | Q16: 기타 | R16: 의복 | S16: 애경자산관리AK기흥 | T16: -44910 | U16: KRW | V16: 대한항공카드 030 | W16: JM 후드티
A17: =$L$1 -> 202502 | B17: =ROW()-2 -> 15 | C17: 세금 | E17: =SUMIFS('수입&예산'!$G$15:$G$27,'수입&예산'!A16:A28,C17,'수입&예산'!$H$15:$H$27,L2)*10000 -> 0 | F17: 0 | G17: =SUM(E17:F17) -> 0 | H17: =INDIRECT($J$1&"!J"&ROW()) -> 0 | I17: =J17-H17 -> 0 | J17: =SUMIFS($T$3:$T$233,$P$3:$P$233,"지출",$Q$3:$Q$233,C17) -> 0 | K17: =G17+J17 -> 0 | L17: =IF(G17=0,0,-J17/G17) -> 0 | N17: 45691 | O17: 0.27662037 | P17: 지출 | Q17: 생활비 | R17: 생활용품 | S17: 쿠팡_쿠페이 | T17: -11650 | U17: KRW | V17: 대한항공카드 030 | W17: 쿠팡-드라이 시트
A18: =$L$1 -> 202502 | B18: =ROW()-2 -> 16 | C18: 기타 | E18: =SUMIFS('수입&예산'!$G$15:$G$27,'수입&예산'!$A$15:$A$27,C18)*10000 -> 350000 | F18: =-J18 -> 3103048 | G18: =SUM(E18:F18) -> 3453048 | H18: =INDIRECT($J$1&"!J"&ROW()) -> -593565 | I18: =J18-H18 -> -2509483 | J18: =SUMIFS($T$3:$T$233,$P$3:$P$233,"지출",$Q$3:$Q$233,C18) -> -3103048 | K18: =G18+J18 -> 350000 | L18: =IF(G18=0,0,-J18/G18) -> 0.89864027 | N18: 45691 | O18: 0.2796412 | P18: 지출 | Q18: JM | R18: 기타 | S18: 쿠팡_쿠페이 | T18: -20690 | U18: KRW | V18: 대한항공카드 030 | W18: JM 스니커즈
A19: 합계 | E19: =SUM(E3:E18) -> 2825000 | F19: =SUM(F3:F18) -> 3714898 | G19: =SUM(G3:G18) -> 6539898 | H19: =SUM(H3:H18) -> -3567122 | I19: =SUM(I3:I18) -> -2564117 | J19: =SUM(J3:J18) -> -6131239 | K19: =SUM(K3:K18) -> 408659 | L19: =IF(G19=0,0,-J19/G19) -> 0.93751294 | N19: 45691 | O19: 0.40172454 | P19: 지출 | Q19: 고정비 | R19: 구독형서비스 | S19: 쿠팡_와우멤버십 | T19: -7890 | U19: KRW | V19: 대한항공카드 030
I20: 예산(기본) 기준 | K20: =E19+J19 -> -3306239 | L20: =IF(E19=0,0,-J19/E19) -> 2.1703501 | N20: 45691 | O20: 0.52462963 | P20: 지출 | Q20: 기타 | R20: 선물 | S20: 카카오선물하기_카카오페이 | T20: -37000 | U20: KRW | V20: 복지포인트 | W20: 최준연책임 생선
N21: 45691 | O21: 0.53658565 | P21: 지출 | Q21: 기타 | R21: 선물 | S21: 카카오_상품권_다날 | T21: -30000 | U21: KRW | V21: 복지포인트 | W21: 김종갑 차장 생선
A22: (상세) | C22: 대분류 | D22: 중분류 | E22: 소비금액 | N22: 45691 | O22: 0.53857639 | P22: 지출 | Q22: 기타 | R22: 선물 | S22: 카카오_다날 | T22: -33000 | U22: KRW | V22: 복지포인트 | W22: 정남용 부장 생선
