Workbook

Sheet 설정
B2: 기본 설정
B3: 연도 | C3: 2026 | D3: 이 셀만 바꾸면 전체 시트 자동 업데이트
B4: 담당자1 | C4: Tiss
B5: 담당자2 | C5: JM
B6: 버전 | C6: v0.06 | D6: 마이너 +0.01 / 메이저 +1.00
B8: 뱅샐 카테고리 매핑
B9: 뱅샐 대분류 | C9: 뱅샐 소분류 | D9: 가계부 대분류
B10: 고정비 | C10: 교통비 | D10: 고정비
B11: 고정비 | C11: 휴대폰 | D11: 고정비
B12: 고정비 | C12: 인터넷 | D12: 고정비
B13: 고정비 | C13: 보험 | D13: 고정비
B14: 고정비 | C14: 구독 | D14: 고정비
B15: 고정비 | C15: (전체) | D15: 고정비
B16: 생활비 | C16: 외식 | D16: 생활비
B17: 생활비 | C17: 식료품 | D17: 생활비
B18: 생활비 | C18: 생활용품 | D18: 생활비
B19: 생활비 | C19: (전체) | D19: 생활비
B20: 의료/건강 | C20: (전체) | D20: 의료/건강
... B28: 기타 | C28: (전체) | D28: 기타
B30: ※ 매핑되지 않은 항목은 자동으로 '기타'로 분류됩니다.

Sheet 수입&예산
B2: [ 수입 ] 2026년 (단위: 만원)
B3: 항목 | C3: 비고 | D3: Tiss 금액 | E3: 주기 | F3: 대상월 | G3: JM 금액 | H3: 주기 | I3: 대상월 | K3: 월수입(Tiss) | L3: 월수입(JM) | M3: 월수입(합계) | N3: 연수입(합계)
B4: 월급 | D4: 554.3 | E4: M | K4: =IF(E4="M",D4,0) | L4: =IF(H4="M",G4,0) | M4: =K4+L4 | N4: =IF(E4="M",D4*12,D4)+IF(H4="M",G4*12,G4)
B5: 기타상여금 | C5: 통신지원금 | D5: 5.52 | E5: M | K5: =IF(E5="M",D5,0) | L5: =IF(H5="M",G5,0) | M5: =K5+L5 | N5: =IF(E5="M",D5*12,D5)+IF(H5="M",G5*12,G5)
B6: 기타상여금 | C6: 인센티브 | E6: Y | I6: 연초 확정 후 입력 | K6: =IF(E6="M",D6,0) | L6: =IF(H6="M",G6,0) | M6: =K6+L6 | N6: =IF(E6="M",D6*12,D6)+IF(H6="M",G6*12,G6)
B7: 기타상여금 | C7: 명절-설 | E7: Y | F7: 01 | K7: =IF(E7="M",D7,0) | L7: =IF(H7="M",G7,0) | M7: =K7+L7 | N7: =IF(E7="M",D7*12,D7)+IF(H7="M",G7*12,G7)
B8: 기타상여금 | C8: 명절-추석 | E8: Y | F8: 09 | K8: =IF(E8="M",D8,0) | L8: =IF(H8="M",G8,0) | M8: =K8+L8 | N8: =IF(E8="M",D8*12,D8)+IF(H8="M",G8*12,G8)
B9: 기타상여금 | C9: 하계휴가비 | E9: Y | F9: 07 | K9: =IF(E9="M",D9,0) | L9: =IF(H9="M",G9,0) | M9: =K9+L9 | N9: =IF(E9="M",D9*12,D9)+IF(H9="M",G9*12,G9)
B10: 복지포인트 | E10: Y | K10: =IF(E10="M",D10,0) | L10: =IF(H10="M",G10,0) | M10: =K10+L10 | N10: =IF(E10="M",D10*12,D10)+IF(H10="M",G10*12,G10)
B11: 금융수입 | E11: M | I11: 이자/배당 등 | K11: =IF(E11="M",D11,0) | L11: =IF(H11="M",G11,0) | M11: =K11+L11 | N11: =IF(E11="M",D11*12,D11)+IF(H11="M",G11*12,G11)
B12: 월수입 합계 | D12: =SUM(D4:D11) | G12: =SUM(G4:G11) | K12: =SUM(K4:K11) | L12: =SUM(L4:L11) | M12: =SUM(M4:M11) | N12: =SUM(N4:N11)
B14: [ 예산(소비) ] 2026년 (단위: 만원)
B15: 대분류 | C15: 중분류 | D15: 공동 | E15: Tiss | F15: JM | G15: 주기 | H15: 합계(월) | I15: 납부월 | J15: 비고
B16: 고정비 | C16: 교통비 | E16: 8 | F16: 8 | G16: M | H16: =IF(G16="M",D16+E16+F16,(D16+E16+F16)/12)
B17: 고정비 | C17: 휴대폰/인터넷 | E17: 2.2 | F17: 2.2 | G17: M | H17: =IF(G17="M",D17+E17+F17,(D17+E17+F17)/12)
B18: 고정비 | C18: 보험/연금 | E18: 23.1 | G18: M | H18: =IF(G18="M",D18+E18+F18,(D18+E18+F18)/12) | J18: 동양생명 등
B19: 고정비 | C19: 부모님 | G19: M | H19: =IF(G19="M",D19+E19+F19,(D19+E19+F19)/12)
B20: 고정비 | C20: 기흥모임 | D20: 13 | G20: M | H20: =IF(G20="M",D20+E20+F20,(D20+E20+F20)/12)
B21: 고정비 | C21: 구독형서비스 | G21: M | H21: =IF(G21="M",D21+E21+F21,(D21+E21+F21)/12) | J21: 넷플릭스 등
B22: 고정비 | C22: 용돈 | E22: 10 | F22: 8.5 | G22: M | H22: =IF(G22="M",D22+E22+F22,(D22+E22+F22)/12)
B23: 고정비 | C23: 아파트관리비 | D23: 33 | G23: M | H23: =IF(G23="M",D23+E23+F23,(D23+E23+F23)/12)
B24: 생활비 | C24: 생활비 | D24: 35 | G24: M | H24: =IF(G24="M",D24+E24+F24,(D24+E24+F24)/12)
B25: 의료/건강 | C25: 의료/건강 | G25: M | H25: =IF(G25="M",D25+E25+F25,(D25+E25+F25)/12)
B26: 모임 | C26: 모임 | G26: M | H26: =IF(G26="M",D26+E26+F26,(D26+E26+F26)/12)
B27: Tiss | C27: 개인 | G27: M | H27: =IF(G27="M",D27+E27+F27,(D27+E27+F27)/12)
B28: JM | C28: 개인 | G28: M | H28: =IF(G28="M",D28+E28+F28,(D28+E28+F28)/12)
B29: 세금 | C29: 재산세(주택) | D29: 30 | G29: Y | H29: =IF(G29="M",D29+E29+F29,(D29+E29+F29)/12) | I29: 07
B30: 세금 | C30: 종합소득세 | G30: Y | H30: =IF(G30="M",D30+E30+F30,(D30+E30+F30)/12) | I30: 05
B31: 대출상환 | C31: 디딤돌대출 | G31: M | H31: =IF(G31="M",D31+E31+F31,(D31+E31+F31)/12) | J31: 자동이체
B32: 부동산 | C32: 부동산 | G32: Y | H32: =IF(G32="M",D32+E32+F32,(D32+E32+F32)/12)
B33: 기타 | C33: 기타 | G33: M | H33: =IF(G33="M",D33+E33+F33,(D33+E33+F33)/12)
B34: 월지출 예산 합계 | D34: =SUM(D16:D33) | E34: =SUM(E16:E33) | F34: =SUM(F16:F33) | H34: =SUM(H16:H33)
B36: 월 순수입 (수입-지출) | H36: =K12-H34
B39: [ 저축 목표 ] 2026년 (단위: 만원)
B40: 항목 | C40: 금액(만원) | D40: 비고
B41: 청약저축 | C41: 20
B42: 정기적금 | C42: 0
B43: 비상금 적립 | C43: 0
B44: 기타저축 | C44: 0
B45: 월 저축 합계 | D45: =SUM(C41:C44)
...

Sheet 뱅샐입력
A1: ▶ 뱅크샐러드 앱 → 내보내기 → '가계부 내역' 시트를 복사하여 3행부터 붙여넣기 하세요.
A2: ※ 헤더(1행)는 그대로 두고, 데이터만 붙여넣기. '이체' 타입은 집계에서 자동 제외됩니다.
A3: 날짜 | B3: 시간 | C3: 타입 | D3: 대분류 | E3: 소분류 | F3: 내용 | G3: 금액 | H3: 화폐 | I3: 결제수단 | J3: 메모

Sheet 대시보드
B1: =TEXT(TODAY(),"YYYY년 MM월")&" 가계부 현황"
B2: ="기준: "& TODAY() &" · "& DAYS(EOMONTH(TODAY(),0),TODAY()) &"일 남음"
B4: 이번달 수입 | C4: 이번달 지출 | D4: 잔액 | E4: 예산합계 | F4: 달성율 | G4: 하루 평균 지출
B5: =IFERROR(INDIRECT("'"&TEXT(MONTH(TODAY()),"00")&"월!B2"),0) | C5: =IFERROR(INDIRECT("'"&TEXT(MONTH(TODAY()),"00")&"월!D2"),0) | D5: =IFERROR(INDIRECT("'"&TEXT(MONTH(TODAY()),"00")&"월!F2"),0) | E5: =IFERROR(INDIRECT("'"&TEXT(MONTH(TODAY()),"00")&"월!E23"),0) | F5: =IFERROR(INDIRECT("'"&TEXT(MONTH(TODAY()),"00")&"월!D2")/INDIRECT("'"&TEXT(MONTH(TODAY()),"00")&"월!E23"),0) | G5: =IFERROR(INDIRECT("'"&TEXT(MONTH(TODAY()),"00")&"월!D2")/(DAY(TODAY())),0)
B7: 카테고리 | C7: 세부항목 | D7: 예산 | E7: 실제지출 | F7: 차액 | G7: 달성율
B8: 고정비 | C8: 교통비 | D8: =IFERROR(INDIRECT("'"&TEXT(MONTH(TODAY()),"00")&"월!E5"),0) | E8: =IFERROR(INDIRECT("'"&TEXT(MONTH(TODAY()),"00")&"월!F5"),0) | F8: =D8-E8 | G8: =IFERROR(E8/D8,0)
B9: 고정비 | C9: 휴대폰/인터넷 | D9: =IFERROR(INDIRECT("'"&TEXT(MONTH(TODAY()),"00")&"월!E6"),0) | E9: =IFERROR(INDIRECT("'"&TEXT(MONTH(TODAY()),"00")&"월!F6"),0) | F9: =D9-E9 | G9: =IFERROR(E9/D9,0)
B10: 고정비 | C10: 보험/연금 | D10: =IFERROR(INDIRECT("'"&TEXT(MONTH(TODAY()),"00")&"월!E7"),0) | E10: =IFERROR(INDIRECT("'"&TEXT(MONTH(TODAY()),"00")&"월!F7"),0) | F10: =D10-E10 | G10: =IFERROR(E10/D10,0)
B11: 고정비 | C11: 부모님 | D11: =IFERROR(INDIRECT("'"&TEXT(MONTH(TODAY()),"00")&"월!E8"),0) | E11: =IFERROR(INDIRECT("'"&TEXT(MONTH(TODAY()),"00")&"월!F8"),0) | F11: =D11-E11 | G11: =IFERROR(E11/D11,0)
B12: 고정비 | C12: 기흥모임 | D12: =IFERROR(INDIRECT("'"&TEXT(MONTH(TODAY()),"00")&"월!E9"),0) | E12: =IFERROR(INDIRECT("'"&TEXT(MONTH(TODAY()),"00")&"월!F9"),0) | F12: =D12-E12 | G12: =IFERROR(E12/D12,0)
B13: 고정비 | C13: 구독형서비스 | D13: =IFERROR(INDIRECT("'"&TEXT(MONTH(TODAY()),"00")&"월!E10"),0) | E13: =IFERROR(INDIRECT("'"&TEXT(MONTH(TODAY()),"00")&"월!F10"),0) | F13: =D13-E13 | G13: =IFERROR(E13/D13,0)
B14: 고정비 | C14: 용돈 | D14: =IFERROR(INDIRECT("'"&TEXT(MONTH(TODAY()),"00")&"월!E11"),0) | E14: =IFERROR(INDIRECT("'"&TEXT(MONTH(TODAY()),"00")&"월!F11"),0) | F14: =D14-E14 | G14: =IFERROR(E14/D14,0)
B15: 고정비 | C15: 아파트관리비 | D15: =IFERROR(INDIRECT("'"&TEXT(MONTH(TODAY()),"00")&"월!E12"),0) | E15: =IFERROR(INDIRECT("'"&TEXT(MONTH(TODAY()),"00")&"월!F12"),0) | F15: =D15-E15 | G15: =IFERROR(E15/D15,0)
B16: 생활비 | C16: 생활비 | D16: =IFERROR(INDIRECT("'"&TEXT(MONTH(TODAY()),"00")&"월!E13"),0) | E16: =IFERROR(INDIRECT("'"&TEXT(MONTH(TODAY()),"00")&"월!F13"),0) | F16: =D16-E16 | G16: =IFERROR(E16/D16,0)
B17: 의료/건강 | C17: 의료/건강 | D17: =IFERROR(INDIRECT("'"&TEXT(MONTH(TODAY()),"00")&"월!E14"),0) | E17: =IFERROR(INDIRECT("'"&TEXT(MONTH(TODAY()),"00")&"월!F14"),0) | F17: =D17-E17 | G17: =IFERROR(E17/D17,0)
B18: 모임 | C18: 모임 | D18: =IFERROR(INDIRECT("'"&TEXT(MONTH(TODAY()),"00")&"월!E15"),0) | E18: =IFERROR(INDIRECT("'"&TEXT(MONTH(TODAY()),"00")&"월!F15"),0) | F18: =D18-E18 | G18: =IFERROR(E18/D18,0)
B19: Tiss | C19: 개인 | D19: =IFERROR(INDIRECT("'"&TEXT(MONTH(TODAY()),"00")&"월!E16"),0) | E19: =IFERROR(INDIRECT("'"&TEXT(MONTH(TODAY()),"00")&"월!F16"),0) | F19: =D19-E19 | G19: =IFERROR(E19/D19,0)
B20: JM | C20: 개인 | D20: =IFERROR(INDIRECT("'"&TEXT(MONTH(TODAY()),"00")&"월!E17"),0) | E20: =IFERROR(INDIRECT("'"&TEXT(MONTH(TODAY()),"00")&"월!F17"),0) | F20: =D20-E20 | G20: =IFERROR(E20/D20,0)
B21: 세금 | C21: 재산세(주택) | D21: =IFERROR(INDIRECT("'"&TEXT(MONTH(TODAY()),"00")&"월!E18"),0) | E21: =IFERROR(INDIRECT("'"&TEXT(MONTH(TODAY()),"00")&"월!F18"),0) | F21: =D21-E21 | G21: =IFERROR(E21/D21,0)
B22: 세금 | C22: 종합소득세 | D22: =IFERROR(INDIRECT("'"&TEXT(MONTH(TODAY()),"00")&"월!E19"),0) | E22: =IFERROR(INDIRECT("'"&TEXT(MONTH(TODAY()),"00")&"월!F19"),0) | F22: =D22-E22 | G22: =IFERROR(E22/D22,0)
B23: 대출상환 | C23: 디딤돌대출 | D23: =IFERROR(INDIRECT("'"&TEXT(MONTH(TODAY()),"00")&"월!E20"),0) | E23: =IFERROR(INDIRECT("'"&TEXT(MONTH(TODAY()),"00")&"월!F20"),0) | F23: =D23-E23 | G23: =IFERROR(E23/D23,0)
B24: 부동산 | C24: 부동산 | D24: =IFERROR(INDIRECT("'"&TEXT(MONTH(TODAY()),"00")&"월!E21"),0) | E24: =IFERROR(INDIRECT("'"&TEXT(MONTH(TODAY()),"00")&"월!F21"),0) | F24: =D24-E24 | G24: =IFERROR(E24/D24,0)
B25: 기타 | C25: 기타 | D25: =IFERROR(INDIRECT("'"&TEXT(MONTH(TODAY()),"00")&"월!E22"),0) | E25: =IFERROR(INDIRECT("'"&TEXT(MONTH(TODAY()),"00")&"월!F22"),0) | F25: =D25-E25 | G25: =IFERROR(E25/D25,0)
B26: 합계 | D26: =SUM(D8:D25) | E26: =SUM(E8:E25) | F26: =SUM(F8:F25) | G26: =IFERROR(E26/D26,0)

Sheet 요약
B1: =설정!C3&"년 가계부 요약"
B3: 월별 수입 / 지출 / 잔액
B4: 월 | C4: 수입 | D4: 지출 | E4: 잔액 | F4: 예산 | G4: 예산대비 | H4: 수입편차 | I4: 지출편차 | J4: 비고 (이달 특이사항)
J5: ← 수입·지출이 평균 대비 20% 초과 시 강조. 사유를 입력하세요.
B6: 1월 | C6: ='01월'!B2 | D6: ='01월'!D2 | E6: ='01월'!F2 | F6: =IFERROR('01월'!E23,0) | G6: =IFERROR(D6/F6,0) | H6: =IFERROR((C6-AVERAGEIF(C$6:C$17,">0"))/ABS(AVERAGEIF(C$6:C$17,">0")),0) | I6: =IFERROR((D6-AVERAGEIF(D$6:D$17,">0"))/ABS(AVERAGEIF(D$6:D$17,">0")),0) | K6: =IFERROR(AVERAGEIF(C$6:C$17,">0"),0) | L6: =IFERROR(AVERAGEIF(D$6:D$17,">0"),0)
B7: 2월 | C7: ='02월'!B2 | D7: ='02월'!D2 | E7: ='02월'!F2 | F7: =IFERROR('02월'!E23,0) | G7: =IFERROR(D7/F7,0) | H7: =IFERROR((C7-AVERAGEIF(C$6:C$17,">0"))/ABS(AVERAGEIF(C$6:C$17,">0")),0) | I7: =IFERROR((D7-AVERAGEIF(D$6:D$17,">0"))/ABS(AVERAGEIF(D$6:D$17,">0")),0) | K7: =IFERROR(AVERAGEIF(C$6:C$17,">0"),0) | L7: =IFERROR(AVERAGEIF(D$6:D$17,">0"),0)
B8: 3월 | C8: ='03월'!B2 | D8: ='03월'!D2 | E8: ='03월'!F2 | F8: =IFERROR('03월'!E23,0) | G8: =IFERROR(D8/F8,0) | H8: =IFERROR((C8-AVERAGEIF(C$6:C$17,">0"))/ABS(AVERAGEIF(C$6:C$17,">0")),0) | I8: =IFERROR((D8-AVERAGEIF(D$6:D$17,">0"))/ABS(AVERAGEIF(D$6:D$17,">0")),0) | K8: =IFERROR(AVERAGEIF(C$6:C$17,">0"),0) | L8: =IFERROR(AVERAGEIF(D$6:D$17,">0"),0)
B9: 4월 | C9: ='04월'!B2 | D9: ='04월'!D2 | E9: ='04월'!F2 | F9: =IFERROR('04월'!E23,0) | G9: =IFERROR(D9/F9,0) | H9: =IFERROR((C9-AVERAGEIF(C$6:C$17,">0"))/ABS(AVERAGEIF(C$6:C$17,">0")),0) | I9: =IFERROR((D9-AVERAGEIF(D$6:D$17,">0"))/ABS(AVERAGEIF(D$6:D$17,">0")),0) | K9: =IFERROR(AVERAGEIF(C$6:C$17,">0"),0) | L9: =IFERROR(AVERAGEIF(D$6:D$17,">0"),0)
B10: 5월 | C10: ='05월'!B2 | D10: ='05월'!D2 | E10: ='05월'!F2 | F10: =IFERROR('05월'!E23,0) | G10: =IFERROR(D10/F10,0) | H10: =IFERROR((C10-AVERAGEIF(C$6:C$17,">0"))/ABS(AVERAGEIF(C$6:C$17,">0")),0) | I10: =IFERROR((D10-AVERAGEIF(D$6:D$17,">0"))/ABS(AVERAGEIF(D$6:D$17,">0")),0) | K10: =IFERROR(AVERAGEIF(C$6:C$17,">0"),0) | L10: =IFERROR(AVERAGEIF(D$6:D$17,">0"),0)
B11: 6월 | C11: ='06월'!B2 | D11: ='06월'!D2 | E11: ='06월'!F2 | F11: =IFERROR('06월'!E23,0) | G11: =IFERROR(D11/F11,0) | H11: =IFERROR((C11-AVERAGEIF(C$6:C$17,">0"))/ABS(AVERAGEIF(C$6:C$17,">0")),0) | I11: =IFERROR((D11-AVERAGEIF(D$6:D$17,">0"))/ABS(AVERAGEIF(D$6:D$17,">0")),0) | K11: =IFERROR(AVERAGEIF(C$6:C$17,">0"),0) | L11: =IFERROR(AVERAGEIF(D$6:D$17,">0"),0)
B12: 7월 | C12: ='07월'!B2 | D12: ='07월'!D2 | E12: ='07월'!F2 | F12: =IFERROR('07월'!E23,0) | G12: =IFERROR(D12/F12,0) | H12: =IFERROR((C12-AVERAGEIF(C$6:C$17,">0"))/ABS(AVERAGEIF(C$6:C$17,">0")),0) | I12: =IFERROR((D12-AVERAGEIF(D$6:D$17,">0"))/ABS(AVERAGEIF(D$6:D$17,">0")),0) | K12: =IFERROR(AVERAGEIF(C$6:C$17,">0"),0) | L12: =IFERROR(AVERAGEIF(D$6:D$17,">0"),0)
B13: 8월 | C13: ='08월'!B2 | D13: ='08월'!D2 | E13: ='08월'!F2 | F13: =IFERROR('08월'!E23,0) | G13: =IFERROR(D13/F13,0) | H13: =IFERROR((C13-AVERAGEIF(C$6:C$17,">0"))/ABS(AVERAGEIF(C$6:C$17,">0")),0) | I13: =IFERROR((D13-AVERAGEIF(D$6:D$17,">0"))/ABS(AVERAGEIF(D$6:D$17,">0")),0) | K13: =IFERROR(AVERAGEIF(C$6:C$17,">0"),0) | L13: =IFERROR(AVERAGEIF(D$6:D$17,">0"),0)
B14: 9월 | C14: ='09월'!B2 | D14: ='09월'!D2 | E14: ='09월'!F2 | F14: =IFERROR('09월'!E23,0) | G14: =IFERROR(D14/F14,0) | H14: =IFERROR((C14-AVERAGEIF(C$6:C$17,">0"))/ABS(AVERAGEIF(C$6:C$17,">0")),0) | I14: =IFERROR((D14-AVERAGEIF(D$6:D$17,">0"))/ABS(AVERAGEIF(D$6:D$17,">0")),0) | K14: =IFERROR(AVERAGEIF(C$6:C$17,">0"),0) | L14: =IFERROR(AVERAGEIF(D$6:D$17,">0"),0)
B15: 10월 | C15: ='10월'!B2 | D15: ='10월'!D2 | E15: ='10월'!F2 | F15: =IFERROR('10월'!E23,0) | G15: =IFERROR(D15/F15,0) | H15: =IFERROR((C15-AVERAGEIF(C$6:C$17,">0"))/ABS(AVERAGEIF(C$6:C$17,">0")),0) | I15: =IFERROR((D15-AVERAGEIF(D$6:D$17,">0"))/ABS(AVERAGEIF(D$6:D$17,">0")),0) | K15: =IFERROR(AVERAGEIF(C$6:C$17,">0"),0) | L15: =IFERROR(AVERAGEIF(D$6:D$17,">0"),0)
B16: 11월 | C16: ='11월'!B2 | D16: ='11월'!D2 | E16: ='11월'!F2 | F16: =IFERROR('11월'!E23,0) | G16: =IFERROR(D16/F16,0) | H16: =IFERROR((C16-AVERAGEIF(C$6:C$17,">0"))/ABS(AVERAGEIF(C$6:C$17,">0")),0) | I16: =IFERROR((D16-AVERAGEIF(D$6:D$17,">0"))/ABS(AVERAGEIF(D$6:D$17,">0")),0) | K16: =IFERROR(AVERAGEIF(C$6:C$17,">0"),0) | L16: =IFERROR(AVERAGEIF(D$6:D$17,">0"),0)
B17: 12월 | C17: ='12월'!B2 | D17: ='12월'!D2 | E17: ='12월'!F2 | F17: =IFERROR('12월'!E23,0) | G17: =IFERROR(D17/F17,0) | H17: =IFERROR((C17-AVERAGEIF(C$6:C$17,">0"))/ABS(AVERAGEIF(C$6:C$17,">0")),0) | I17: =IFERROR((D17-AVERAGEIF(D$6:D$17,">0"))/ABS(AVERAGEIF(D$6:D$17,">0")),0) | K17: =IFERROR(AVERAGEIF(C$6:C$17,">0"),0) | L17: =IFERROR(AVERAGEIF(D$6:D$17,">0"),0)
B18: 연간 합계 | C18: =SUM(C6:C17) | D18: =SUM(D6:D17) | E18: =SUM(E6:E17)
B43: 특이사항 목록 (비고 입력 시 자동 표시)
B44: 월 | C44: 수입편차 | D44: 지출편차 | E44: 비고
B45: =IFERROR(FILTER(CHOOSE({1,2,3,4},B$6:B$17,H$6:H$17,I$6:I$17,J$6:J$17),J$6:J$17<>""),"아직 입력된 특이사항이 없습니다.")
B61: ⑤ 미분류 거래 감지 (예산 카테고리 미매핑 지출 자동 표시)
B62: ※ 뱅샐 대분류가 예산 항목(JM, Tiss, 고정비, 기타, 대출상환, 모임, 부동산, 생활비, 세금, 의료/건강)에 없는 지출 거래를 표시합니다. 해당 거래가 없으면 '미분류 거래 없음'이 표시됩니다.
B63: 날짜 | C63: 대분류 | D63: 소분류 | E63: 내용 | F63: 금액
B64: =IFERROR(FILTER(CHOOSE({1,2,3,4,5},뱅샐입력!A$4:A$3003,뱅샐입력!D$4:D$3003,뱅샐입력!E$4:E$3003,뱅샐입력!F$4:F$3003,뱅샐입력!G$4:G$3003),(뱅샐입력!C$4:C$3003="지출")*(YEAR(뱅샐입력!A$4:A$3003)=설정!C3)*(뱅샐입력!D$4:D$3003<>"")*ISERROR(MATCH(뱅샐입력!D$4:D$3003,{"JM","Tiss","고정비","기타","대출상환","모임","부동산","생활비","세금","의료/건강"},0))),"미분류 거래 없음")

Sheet 01월
A1: =TEXT(DATE(설정!C3,1,1),"YYYY년 MM월 가계부")
A2: 이번달 수입 | B2: =SUMPRODUCT((MONTH(뱅샐입력!A$4:A$3003)=1)*(YEAR(뱅샐입력!A$4:A$3003)=설정!C3)*(뱅샐입력!C$4:C$3003="수입")*뱅샐입력!G$4:G$3003) | C2: 이번달 지출 | D2: =SUMPRODUCT((MONTH(뱅샐입력!A$4:A$3003)=1)*(YEAR(뱅샐입력!A$4:A$3003)=설정!C3)*(뱅샐입력!C$4:C$3003="지출")*ABS(뱅샐입력!G$4:G$3003)) | E2: 잔액 | F2: =B2-D2
A4: 대분류 | B4: 중분류 | C4: 예산기본 | D4: 예산추가 | E4: 예산합계 | F4: 실제지출 | G4: 차액 | H4: 달성율 | I4: 전월지출 | J4: 전월대비
A5: 고정비 | B5: 교통비 | C5: =IFERROR(SUMIFS(수입&예산!H$15:H$50,수입&예산!B$15:B$50,A5,수입&예산!C$15:C$50,B5)*10000,0) | D5: 0 | E5: =C5+D5 | F5: =SUMPRODUCT((MONTH(뱅샐입력!A$4:A$3003)=1)*(YEAR(뱅샐입력!A$4:A$3003)=설정!C3)*(뱅샐입력!C$4:C$3003="지출")*(뱅샐입력!D$4:D$3003=A5)*ABS(뱅샐입력!G$4:G$3003)) | G5: =E5-F5 | H5: =IFERROR(F5/E5,0) | I5: =IFERROR('12월'!F5,0) | J5: =F5-I5
A6: 고정비 | B6: 휴대폰/인터넷 | C6: =IFERROR(SUMIFS(수입&예산!H$15:H$50,수입&예산!B$15:B$50,A6,수입&예산!C$15:C$50,B6)*10000,0) | D6: 0 | E6: =C6+D6 | F6: =SUMPRODUCT((MONTH(뱅샐입력!A$4:A$3003)=1)*(YEAR(뱅샐입력!A$4:A$3003)=설정!C3)*(뱅샐입력!C$4:C$3003="지출")*(뱅샐입력!D$4:D$3003=A6)*ABS(뱅샐입력!G$4:G$3003)) | G6: =E6-F6 | H6: =IFERROR(F6/E6,0) | I6: =IFERROR('12월'!F6,0) | J6: =F6-I6
A7: 고정비 | B7: 보험/연금 | C7: =IFERROR(SUMIFS(수입&예산!H$15:H$50,수입&예산!B$15:B$50,A7,수입&예산!C$15:C$50,B7)*10000,0) | D7: 0 | E7: =C7+D7 | F7: =SUMPRODUCT((MONTH(뱅샐입력!A$4:A$3003)=1)*(YEAR(뱅샐입력!A$4:A$3003)=설정!C3)*(뱅샐입력!C$4:C$3003="지출")*(뱅샐입력!D$4:D$3003=A7)*ABS(뱅샐입력!G$4:G$3003)) | G7: =E7-F7 | H7: =IFERROR(F7/E7,0) | I7: =IFERROR('12월'!F7,0) | J7: =F7-I7
A8: 고정비 | B8: 부모님 | C8: =IFERROR(SUMIFS(수입&예산!H$15:H$50,수입&예산!B$15:B$50,A8,수입&예산!C$15:C$50,B8)*10000,0) | D8: 0 | E8: =C8+D8 | F8: =SUMPRODUCT((MONTH(뱅샐입력!A$4:A$3003)=1)*(YEAR(뱅샐입력!A$4:A$3003)=설정!C3)*(뱅샐입력!C$4:C$3003="지출")*(뱅샐입력!D$4:D$3003=A8)*ABS(뱅샐입력!G$4:G$3003)) | G8: =E8-F8 | H8: =IFERROR(F8/E8,0) | I8: =IFERROR('12월'!F8,0) | J8: =F8-I8
A9: 고정비 | B9: 기흥모임 | C9: =IFERROR(SUMIFS(수입&예산!H$15:H$50,수입&예산!B$15:B$50,A9,수입&예산!C$15:C$50,B9)*10000,0) | D9: 0 | E9: =C9+D9 | F9: =SUMPRODUCT((MONTH(뱅샐입력!A$4:A$3003)=1)*(YEAR(뱅샐입력!A$4:A$3003)=설정!C3)*(뱅샐입력!C$4:C$3003="지출")*(뱅샐입력!D$4:D$3003=A9)*ABS(뱅샐입력!G$4:G$3003)) | G9: =E9-F9 | H9: =IFERROR(F9/E9,0) | I9: =IFERROR('12월'!F9,0) | J9: =F9-I9
A10: 고정비 | B10: 구독형서비스 | C10: =IFERROR(SUMIFS(수입&예산!H$15:H$50,수입&예산!B$15:B$50,A10,수입&예산!C$15:C$50,B10)*10000,0) | D10: 0 | E10: =C10+D10 | F10: =SUMPRODUCT((MONTH(뱅샐입력!A$4:A$3003)=1)*(YEAR(뱅샐입력!A$4:A$3003)=설정!C3)*(뱅샐입력!C$4:C$3003="지출")*(뱅샐입력!D$4:D$3003=A10)*ABS(뱅샐입력!G$4:G$3003)) | G10: =E10-F10 | H10: =IFERROR(F10/E10,0) | I10: =IFERROR('12월'!F10,0) | J10: =F10-I10
A11: 고정비 | B11: 용돈 | C11: =IFERROR(SUMIFS(수입&예산!H$15:H$50,수입&예산!B$15:B$50,A11,수입&예산!C$15:C$50,B11)*10000,0) | D11: 0 | E11: =C11+D11 | F11: =SUMPRODUCT((MONTH(뱅샐입력!A$4:A$3003)=1)*(YEAR(뱅샐입력!A$4:A$3003)=설정!C3)*(뱅샐입력!C$4:C$3003="지출")*(뱅샐입력!D$4:D$3003=A11)*ABS(뱅샐입력!G$4:G$3003)) | G11: =E11-F11 | H11: =IFERROR(F11/E11,0) | I11: =IFERROR('12월'!F11,0) | J11: =F11-I11
A12: 고정비 | B12: 아파트관리비 | C12: =IFERROR(SUMIFS(수입&예산!H$15:H$50,수입&예산!B$15:B$50,A12,수입&예산!C$15:C$50,B12)*10000,0) | D12: 0 | E12: =C12+D12 | F12: =SUMPRODUCT((MONTH(뱅샐입력!A$4:A$3003)=1)*(YEAR(뱅샐입력!A$4:A$3003)=설정!C3)*(뱅샐입력!C$4:C$3003="지출")*(뱅샐입력!D$4:D$3003=A12)*ABS(뱅샐입력!G$4:G$3003)) | G12: =E12-F12 | H12: =IFERROR(F12/E12,0) | I12: =IFERROR('12월'!F12,0) | J12: =F12-I12
A13: 생활비 | B13: 생활비 | C13: =IFERROR(SUMIFS(수입&예산!H$15:H$50,수입&예산!B$15:B$50,A13,수입&예산!C$15:C$50,B13)*10000,0) | D13: 0 | E13: =C13+D13 | F13: =SUMPRODUCT((MONTH(뱅샐입력!A$4:A$3003)=1)*(YEAR(뱅샐입력!A$4:A$3003)=설정!C3)*(뱅샐입력!C$4:C$3003="지출")*(뱅샐입력!D$4:D$3003=A13)*ABS(뱅샐입력!G$4:G$3003)) | G13: =E13-F13 | H13: =IFERROR(F13/E13,0) | I13: =IFERROR('12월'!F13,0) | J13: =F13-I13
A14: 의료/건강 | B14: 의료/건강 | C14: =IFERROR(SUMIFS(수입&예산!H$15:H$50,수입&예산!B$15:B$50,A14,수입&예산!C$15:C$50,B14)*10000,0) | D14: 0 | E14: =C14+D14 | F14: =SUMPRODUCT((MONTH(뱅샐입력!A$4:A$3003)=1)*(YEAR(뱅샐입력!A$4:A$3003)=설정!C3)*(뱅샐입력!C$4:C$3003="지출")*(뱅샐입력!D$4:D$3003=A14)*ABS(뱅샐입력!G$4:G$3003)) | G14: =E14-F14 | H14: =IFERROR(F14/E14,0) | I14: =IFERROR('12월'!F14,0) | J14: =F14-I14
A15: 모임 | B15: 모임 | C15: =IFERROR(SUMIFS(수입&예산!H$15:H$50,수입&예산!B$15:B$50,A15,수입&예산!C$15:C$50,B15)*10000,0) | D15: 0 | E15: =C15+D15 | F15: =SUMPRODUCT((MONTH(뱅샐입력!A$4:A$3003)=1)*(YEAR(뱅샐입력!A$4:A$3003)=설정!C3)*(뱅샐입력!C$4:C$3003="지출")*(뱅샐입력!D$4:D$3003=A15)*ABS(뱅샐입력!G$4:G$3003)) | G15: =E15-F15 | H15: =IFERROR(F15/E15,0) | I15: =IFERROR('12월'!F15,0) | J15: =F15-I15
A16: Tiss | B16: 개인 | C16: =IFERROR(SUMIFS(수입&예산!H$15:H$50,수입&예산!B$15:B$50,A16,수입&예산!C$15:C$50,B16)*10000,0) | D16: 0 | E16: =C16+D16 | F16: =SUMPRODUCT((MONTH(뱅샐입력!A$4:A$3003)=1)*(YEAR(뱅샐입력!A$4:A$3003)=설정!C3)*(뱅샐입력!C$4:C$3003="지출")*(뱅샐입력!D$4:D$3003=A16)*ABS(뱅샐입력!G$4:G$3003)) | G16: =E16-F16 | H16: =IFERROR(F16/E16,0) | I16: =IFERROR('12월'!F16,0) | J16: =F16-I16
A17: JM | B17: 개인 | C17: =IFERROR(SUMIFS(수입&예산!H$15:H$50,수입&예산!B$15:B$50,A17,수입&예산!C$15:C$50,B17)*10000,0) | D17: 0 | E17: =C17+D17 | F17: =SUMPRODUCT((MONTH(뱅샐입력!A$4:A$3003)=1)*(YEAR(뱅샐입력!A$4:A$3003)=설정!C3)*(뱅샐입력!C$4:C$3003="지출")*(뱅샐입력!D$4:D$3003=A17)*ABS(뱅샐입력!G$4:G$3003)) | G17: =E17-F17 | H17: =IFERROR(F17/E17,0) | I17: =IFERROR('12월'!F17,0) | J17: =F17-I17
A18: 세금 | B18: 재산세(주택) | C18: =IFERROR(SUMIFS(수입&예산!H$15:H$50,수입&예산!B$15:B$50,A18,수입&예산!C$15:C$50,B18)*10000,0) | D18: 0 | E18: =C18+D18 | F18: =SUMPRODUCT((MONTH(뱅샐입력!A$4:A$3003)=1)*(YEAR(뱅샐입력!A$4:A$3003)=설정!C3)*(뱅샐입력!C$4:C$3003="지출")*(뱅샐입력!D$4:D$3003=A18)*ABS(뱅샐입력!G$4:G$3003)) | G18: =E18-F18 | H18: =IFERROR(F18/E18,0) | I18: =IFERROR('12월'!F18,0) | J18: =F18-I18
A19: 세금 | B19: 종합소득세 | C19: =IFERROR(SUMIFS(수입&예산!H$15:H$50,수입&예산!B$15:B$50,A19,수입&예산!C$15:C$50,B19)*10000,0) | D19: 0 | E19: =C19+D19 | F19: =SUMPRODUCT((MONTH(뱅샐입력!A$4:A$3003)=1)*(YEAR(뱅샐입력!A$4:A$3003)=설정!C3)*(뱅샐입력!C$4:C$3003="지출")*(뱅샐입력!D$4:D$3003=A19)*ABS(뱅샐입력!G$4:G$3003)) | G19: =E19-F19 | H19: =IFERROR(F19/E19,0) | I19: =IFERROR('12월'!F19,0) | J19: =F19-I19
A20: 대출상환 | B20: 디딤돌대출 | C20: =IFERROR(SUMIFS(수입&예산!H$15:H$50,수입&예산!B$15:B$50,A20,수입&예산!C$15:C$50,B20)*10000,0) | D20: 0 | E20: =C20+D20 | F20: =SUMPRODUCT((MONTH(뱅샐입력!A$4:A$3003)=1)*(YEAR(뱅샐입력!A$4:A$3003)=설정!C3)*(뱅샐입력!C$4:C$3003="지출")*(뱅샐입력!D$4:D$3003=A20)*ABS(뱅샐입력!G$4:G$3003)) | G20: =E20-F20 | H20: =IFERROR(F20/E20,0) | I20: =IFERROR('12월'!F20,0) | J20: =F20-I20
A21: 부동산 | B21: 부동산 | C21: =IFERROR(SUMIFS(수입&예산!H$15:H$50,수입&예산!B$15:B$50,A21,수입&예산!C$15:C$50,B21)*10000,0) | D21: 0 | E21: =C21+D21 | F21: =SUMPRODUCT((MONTH(뱅샐입력!A$4:A$3003)=1)*(YEAR(뱅샐입력!A$4:A$3003)=설정!C3)*(뱅샐입력!C$4:C$3003="지출")*(뱅샐입력!D$4:D$3003=A21)*ABS(뱅샐입력!G$4:G$3003)) | G21: =E21-F21 | H21: =IFERROR(F21/E21,0) | I21: =IFERROR('12월'!F21,0) | J21: =F21-I21
A22: 기타 | B22: 기타 | C22: =IFERROR(SUMIFS(수입&예산!H$15:H$50,수입&예산!B$15:B$50,A22,수입&예산!C$15:C$50,B22)*10000,0) | D22: 0 | E22: =C22+D22 | F22: =SUMPRODUCT((MONTH(뱅샐입력!A$4:A$3003)=1)*(YEAR(뱅샐입력!A$4:A$3003)=설정!C3)*(뱅샐입력!C$4:C$3003="지출")*(뱅샐입력!D$4:D$3003=A22)*ABS(뱅샐입력!G$4:G$3003)) | G22: =E22-F22 | H22: =IFERROR(F22/E22,0) | I22: =IFERROR('12월'!F22,0) | J22: =F22-I22
A23: 합계 | C23: =SUM(C5:C22) | D23: =SUM(D5:D22) | E23: =SUM(E5:E22) | F23: =SUM(F5:F22) | G23: =SUM(G5:G22) | H23: =IFERROR(F23/E23,0) | I23: =SUM(I5:I22) | J23: =F23-I23
A25: 날짜 | B25: 타입 | C25: 대분류 | D25: 소분류 | E25: 내용 | F25: 금액 | G25: 결제수단 | H25: 메모
A26: =IFERROR(FILTER(CHOOSE({1,2,3,4,5,6,7,8},뱅샐입력!A$4:A$3003,뱅샐입력!C$4:C$3003,뱅샐입력!D$4:D$3003,뱅샐입력!E$4:E$3003,뱅샐입력!F$4:F$3003,뱅샐입력!G$4:G$3003,뱅샐입력!I$4:I$3003,뱅샐입력!J$4:J$3003),(MONTH(뱅샐입력!A$4:A$3003)=1)*(YEAR(뱅샐입력!A$4:A$3003)=설정!C3)*(뱅샐입력!C$4:C$3003<>"이체")),"데이터 없음")

Sheet 02월
A1: =TEXT(DATE(설정!C3,2,1),"YYYY년 MM월 가계부")
A2: 이번달 수입 | B2: =SUMPRODUCT((MONTH(뱅샐입력!A$4:A$3003)=2)*(YEAR(뱅샐입력!A$4:A$3003)=설정!C3)*(뱅샐입력!C$4:C$3003="수입")*뱅샐입력!G$4:G$3003) | C2: 이번달 지출 | D2: =SUMPRODUCT((MONTH(뱅샐입력!A$4:A$3003)=2)*(YEAR(뱅샐입력!A$4:A$3003)=설정!C3)*(뱅샐입력!C$4:C$3003="지출")*ABS(뱅샐입력!G$4:G$3003)) | E2: 잔액 | F2: =B2-D2
A4: 대분류 | B4: 중분류 | C4: 예산기본 | D4: 예산추가 | E4: 예산합계 | F4: 실제지출 | G4: 차액 | H4: 달성율 | I4: 전월지출 | J4: 전월대비
A5: 고정비 | B5: 교통비 | C5: =IFERROR(SUMIFS(수입&예산!H$15:H$50,수입&예산!B$15:B$50,A5,수입&예산!C$15:C$50,B5)*10000,0) | D5: 0 | E5: =C5+D5 | F5: =SUMPRODUCT((MONTH(뱅샐입력!A$4:A$3003)=2)*(YEAR(뱅샐입력!A$4:A$3003)=설정!C3)*(뱅샐입력!C$4:C$3003="지출")*(뱅샐입력!D$4:D$3003=A5)*ABS(뱅샐입력!G$4:G$3003)) | G5: =E5-F5 | H5: =IFERROR(F5/E5,0) | I5: =IFERROR('01월'!F5,0) | J5: =F5-I5
A6: 고정비 | B6: 휴대폰/인터넷 | C6: =IFERROR(SUMIFS(수입&예산!H$15:H$50,수입&예산!B$15:B$50,A6,수입&예산!C$15:C$50,B6)*10000,0) | D6: 0 | E6: =C6+D6 | F6: =SUMPRODUCT((MONTH(뱅샐입력!A$4:A$3003)=2)*(YEAR(뱅샐입력!A$4:A$3003)=설정!C3)*(뱅샐입력!C$4:C$3003="지출")*(뱅샐입력!D$4:D$3003=A6)*ABS(뱅샐입력!G$4:G$3003)) | G6: =E6-F6 | H6: =IFERROR(F6/E6,0) | I6: =IFERROR('01월'!F6,0) | J6: =F6-I6
A7: 고정비 | B7: 보험/연금 | C7: =IFERROR(SUMIFS(수입&예산!H$15:H$50,수입&예산!B$15:B$50,A7,수입&예산!C$15:C$50,B7)*10000,0) | D7: 0 | E7: =C7+D7 | F7: =SUMPRODUCT((MONTH(뱅샐입력!A$4:A$3003)=2)*(YEAR(뱅샐입력!A$4:A$3003)=설정!C3)*(뱅샐입력!C$4:C$3003="지출")*(뱅샐입력!D$4:D$3003=A7)*ABS(뱅샐입력!G$4:G$3003)) | G7: =E7-F7 | H7: =IFERROR(F7/E7,0) | I7: =IFERROR('01월'!F7,0) | J7: =F7-I7
A8: 고정비 | B8: 부모님 | C8: =IFERROR(SUMIFS(수입&예산!H$15:H$50,수입&예산!B$15:B$50,A8,수입&예산!C$15:C$50,B8)*10000,0) | D8: 0 | E8: =C8+D8 | F8: =SUMPRODUCT((MONTH(뱅샐입력!A$4:A$3003)=2)*(YEAR(뱅샐입력!A$4:A$3003)=설정!C3)*(뱅샐입력!C$4:C$3003="지출")*(뱅샐입력!D$4:D$3003=A8)*ABS(뱅샐입력!G$4:G$3003)) | G8: =E8-F8 | H8: =IFERROR(F8/E8,0) | I8: =IFERROR('01월'!F8,0) | J8: =F8-I8
A9: 고정비 | B9: 기흥모임 | C9: =IFERROR(SUMIFS(수입&예산!H$15:H$50,수입&예산!B$15:B$50,A9,수입&예산!C$15:C$50,B9)*10000,0) | D9: 0 | E9: =C9+D9 | F9: =SUMPRODUCT((MONTH(뱅샐입력!A$4:A$3003)=2)*(YEAR(뱅샐입력!A$4:A$3003)=설정!C3)*(뱅샐입력!C$4:C$3003="지출")*(뱅샐입력!D$4:D$3003=A9)*ABS(뱅샐입력!G$4:G$3003)) | G9: =E9-F9 | H9: =IFERROR(F9/E9,0) | I9: =IFERROR('01월'!F9,0) | J9: =F9-I9
A10: 고정비 | B10: 구독형서비스 | C10: =IFERROR(SUMIFS(수입&예산!H$15:H$50,수입&예산!B$15:B$50,A10,수입&예산!C$15:C$50,B10)*10000,0) | D10: 0 | E10: =C10+D10 | F10: =SUMPRODUCT((MONTH(뱅샐입력!A$4:A$3003)=2)*(YEAR(뱅샐입력!A$4:A$3003)=설정!C3)*(뱅샐입력!C$4:C$3003="지출")*(뱅샐입력!D$4:D$3003=A10)*ABS(뱅샐입력!G$4:G$3003)) | G10: =E10-F10 | H10: =IFERROR(F10/E10,0) | I10: =IFERROR('01월'!F10,0) | J10: =F10-I10
A11: 고정비 | B11: 용돈 | C11: =IFERROR(SUMIFS(수입&예산!H$15:H$50,수입&예산!B$15:B$50,A11,수입&예산!C$15:C$50,B11)*10000,0) | D11: 0 | E11: =C11+D11 | F11: =SUMPRODUCT((MONTH(뱅샐입력!A$4:A$3003)=2)*(YEAR(뱅샐입력!A$4:A$3003)=설정!C3)*(뱅샐입력!C$4:C$3003="지출")*(뱅샐입력!D$4:D$3003=A11)*ABS(뱅샐입력!G$4:G$3003)) | G11: =E11-F11 | H11: =IFERROR(F11/E11,0) | I11: =IFERROR('01월'!F11,0) | J11: =F11-I11
A12: 고정비 | B12: 아파트관리비 | C12: =IFERROR(SUMIFS(수입&예산!H$15:H$50,수입&예산!B$15:B$50,A12,수입&예산!C$15:C$50,B12)*10000,0) | D12: 0 | E12: =C12+D12 | F12: =SUMPRODUCT((MONTH(뱅샐입력!A$4:A$3003)=2)*(YEAR(뱅샐입력!A$4:A$3003)=설정!C3)*(뱅샐입력!C$4:C$3003="지출")*(뱅샐입력!D$4:D$3003=A12)*ABS(뱅샐입력!G$4:G$3003)) | G12: =E12-F12 | H12: =IFERROR(F12/E12,0) | I12: =IFERROR('01월'!F12,0) | J12: =F12-I12
A13: 생활비 | B13: 생활비 | C13: =IFERROR(SUMIFS(수입&예산!H$15:H$50,수입&예산!B$15:B$50,A13,수입&예산!C$15:C$50,B13)*10000,0) | D13: 0 | E13: =C13+D13 | F13: =SUMPRODUCT((MONTH(뱅샐입력!A$4:A$3003)=2)*(YEAR(뱅샐입력!A$4:A$3003)=설정!C3)*(뱅샐입력!C$4:C$3003="지출")*(뱅샐입력!D$4:D$3003=A13)*ABS(뱅샐입력!G$4:G$3003)) | G13: =E13-F13 | H13: =IFERROR(F13/E13,0) | I13: =IFERROR('01월'!F13,0) | J13: =F13-I13
A14: 의료/건강 | B14: 의료/건강 | C14: =IFERROR(SUMIFS(수입&예산!H$15:H$50,수입&예산!B$15:B$50,A14,수입&예산!C$15:C$50,B14)*10000,0) | D14: 0 | E14: =C14+D14 | F14: =SUMPRODUCT((MONTH(뱅샐입력!A$4:A$3003)=2)*(YEAR(뱅샐입력!A$4:A$3003)=설정!C3)*(뱅샐입력!C$4:C$3003="지출")*(뱅샐입력!D$4:D$3003=A14)*ABS(뱅샐입력!G$4:G$3003)) | G14: =E14-F14 | H14: =IFERROR(F14/E14,0) | I14: =IFERROR('01월'!F14,0) | J14: =F14-I14
A15: 모임 | B15: 모임 | C15: =IFERROR(SUMIFS(수입&예산!H$15:H$50,수입&예산!B$15:B$50,A15,수입&예산!C$15:C$50,B15)*10000,0) | D15: 0 | E15: =C15+D15 | F15: =SUMPRODUCT((MONTH(뱅샐입력!A$4:A$3003)=2)*(YEAR(뱅샐입력!A$4:A$3003)=설정!C3)*(뱅샐입력!C$4:C$3003="지출")*(뱅샐입력!D$4:D$3003=A15)*ABS(뱅샐입력!G$4:G$3003)) | G15: =E15-F15 | H15: =IFERROR(F15/E15,0) | I15: =IFERROR('01월'!F15,0) | J15: =F15-I15
A16: Tiss | B16: 개인 | C16: =IFERROR(SUMIFS(수입&예산!H$15:H$50,수입&예산!B$15:B$50,A16,수입&예산!C$15:C$50,B16)*10000,0) | D16: 0 | E16: =C16+D16 | F16: =SUMPRODUCT((MONTH(뱅샐입력!A$4:A$3003)=2)*(YEAR(뱅샐입력!A$4:A$3003)=설정!C3)*(뱅샐입력!C$4:C$3003="지출")*(뱅샐입력!D$4:D$3003=A16)*ABS(뱅샐입력!G$4:G$3003)) | G16: =E16-F16 | H16: =IFERROR(F16/E16,0) | I16: =IFERROR('01월'!F16,0) | J16: =F16-I16
A17: JM | B17: 개인 | C17: =IFERROR(SUMIFS(수입&예산!H$15:H$50,수입&예산!B$15:B$50,A17,수입&예산!C$15:C$50,B17)*10000,0) | D17: 0 | E17: =C17+D17 | F17: =SUMPRODUCT((MONTH(뱅샐입력!A$4:A$3003)=2)*(YEAR(뱅샐입력!A$4:A$3003)=설정!C3)*(뱅샐입력!C$4:C$3003="지출")*(뱅샐입력!D$4:D$3003=A17)*ABS(뱅샐입력!G$4:G$3003)) | G17: =E17-F17 | H17: =IFERROR(F17/E17,0) | I17: =IFERROR('01월'!F17,0) | J17: =F17-I17
A18: 세금 | B18: 재산세(주택) | C18: =IFERROR(SUMIFS(수입&예산!H$15:H$50,수입&예산!B$15:B$50,A18,수입&예산!C$15:C$50,B18)*10000,0) | D18: 0 | E18: =C18+D18 | F18: =SUMPRODUCT((MONTH(뱅샐입력!A$4:A$3003)=2)*(YEAR(뱅샐입력!A$4:A$3003)=설정!C3)*(뱅샐입력!C$4:C$3003="지출")*(뱅샐입력!D$4:D$3003=A18)*ABS(뱅샐입력!G$4:G$3003)) | G18: =E18-F18 | H18: =IFERROR(F18/E18,0) | I18: =IFERROR('01월'!F18,0) | J18: =F18-I18
A19: 세금 | B19: 종합소득세 | C19: =IFERROR(SUMIFS(수입&예산!H$15:H$50,수입&예산!B$15:B$50,A19,수입&예산!C$15:C$50,B19)*10000,0) | D19: 0 | E19: =C19+D19 | F19: =SUMPRODUCT((MONTH(뱅샐입력!A$4:A$3003)=2)*(YEAR(뱅샐입력!A$4:A$3003)=설정!C3)*(뱅샐입력!C$4:C$3003="지출")*(뱅샐입력!D$4:D$3003=A19)*ABS(뱅샐입력!G$4:G$3003)) | G19: =E19-F19 | H19: =IFERROR(F19/E19,0) | I19: =IFERROR('01월'!F19,0) | J19: =F19-I19
A20: 대출상환 | B20: 디딤돌대출 | C20: =IFERROR(SUMIFS(수입&예산!H$15:H$50,수입&예산!B$15:B$50,A20,수입&예산!C$15:C$50,B20)*10000,0) | D20: 0 | E20: =C20+D20 | F20: =SUMPRODUCT((MONTH(뱅샐입력!A$4:A$3003)=2)*(YEAR(뱅샐입력!A$4:A$3003)=설정!C3)*(뱅샐입력!C$4:C$3003="지출")*(뱅샐입력!D$4:D$3003=A20)*ABS(뱅샐입력!G$4:G$3003)) | G20: =E20-F20 | H20: =IFERROR(F20/E20,0) | I20: =IFERROR('01월'!F20,0) | J20: =F20-I20
A21: 부동산 | B21: 부동산 | C21: =IFERROR(SUMIFS(수입&예산!H$15:H$50,수입&예산!B$15:B$50,A21,수입&예산!C$15:C$50,B21)*10000,0) | D21: 0 | E21: =C21+D21 | F21: =SUMPRODUCT((MONTH(뱅샐입력!A$4:A$3003)=2)*(YEAR(뱅샐입력!A$4:A$3003)=설정!C3)*(뱅샐입력!C$4:C$3003="지출")*(뱅샐입력!D$4:D$3003=A21)*ABS(뱅샐입력!G$4:G$3003)) | G21: =E21-F21 | H21: =IFERROR(F21/E21,0) | I21: =IFERROR('01월'!F21,0) | J21: =F21-I21
A22: 기타 | B22: 기타 | C22: =IFERROR(SUMIFS(수입&예산!H$15:H$50,수입&예산!B$15:B$50,A22,수입&예산!C$15:C$50,B22)*10000,0) | D22: 0 | E22: =C22+D22 | F22: =SUMPRODUCT((MONTH(뱅샐입력!A$4:A$3003)=2)*(YEAR(뱅샐입력!A$4:A$3003)=설정!C3)*(뱅샐입력!C$4:C$3003="지출")*(뱅샐입력!D$4:D$3003=A22)*ABS(뱅샐입력!G$4:G$3003)) | G22: =E22-F22 | H22: =IFERROR(F22/E22,0) | I22: =IFERROR('01월'!F22,0) | J22: =F22-I22
A23: 합계 | C23: =SUM(C5:C22) | D23: =SUM(D5:D22) | E23: =SUM(E5:E22) | F23: =SUM(F5:F22) | G23: =SUM(G5:G22) | H23: =IFERROR(F23/E23,0) | I23: =SUM(I5:I22) | J23: =F23-I23
A25: 날짜 | B25: 타입 | C25: 대분류 | D25: 소분류 | E25: 내용 | F25: 금액 | G25: 결제수단 | H25: 메모
A26: =IFERROR(FILTER(CHOOSE({1,2,3,4,5,6,7,8},뱅샐입력!A$4:A$3003,뱅샐입력!C$4:C$3003,뱅샐입력!D$4:D$3003,뱅샐입력!E$4:E$3003,뱅샐입력!F$4:F$3003,뱅샐입력!G$4:G$3003,뱅샐입력!I$4:I$3003,뱅샐입력!J$4:J$3003),(MONTH(뱅샐입력!A$4:A$3003)=2)*(YEAR(뱅샐입력!A$4:A$3003)=설정!C3)*(뱅샐입력!C$4:C$3003<>"이체")),"데이터 없음")

Sheet 03월
A1: =TEXT(DATE(설정!C3,3,1),"YYYY년 MM월 가계부")
A2: 이번달 수입 | B2: =SUMPRODUCT((MONTH(뱅샐입력!A$4:A$3003)=3)*(YEAR(뱅샐입력!A$4:A$3003)=설정!C3)*(뱅샐입력!C$4:C$3003="수입")*뱅샐입력!G$4:G$3003) | C2: 이번달 지출 | D2: =SUMPRODUCT((MONTH(뱅샐입력!A$4:A$3003)=3)*(YEAR(뱅샐입력!A$4:A$3003)=설정!C3)*(뱅샐입력!C$4:C$3003="지출")*ABS(뱅샐입력!G$4:G$3003)) | E2: 잔액 | F2: =B2-D2
A4: 대분류 | B4: 중분류 | C4: 예산기본 | D4: 예산추가 | E4: 예산합계 | F4: 실제지출 | G4: 차액 | H4: 달성율 | I4: 전월지출 | J4: 전월대비
A5: 고정비 | B5: 교통비 | C5: =IFERROR(SUMIFS(수입&예산!H$15:H$50,수입&예산!B$15:B$50,A5,수입&예산!C$15:C$50,B5)*10000,0) | D5: 0 | E5: =C5+D5 | F5: =SUMPRODUCT((MONTH(뱅샐입력!A$4:A$3003)=3)*(YEAR(뱅샐입력!A$4:A$3003)=설정!C3)*(뱅샐입력!C$4:C$3003="지출")*(뱅샐입력!D$4:D$3003=A5)*ABS(뱅샐입력!G$4:G$3003)) | G5: =E5-F5 | H5: =IFERROR(F5/E5,0) | I5: =IFERROR('02월'!F5,0) | J5: =F5-I5
A6: 고정비 | B6: 휴대폰/인터넷 | C6: =IFERROR(SUMIFS(수입&예산!H$15:H$50,수입&예산!B$15:B$50,A6,수입&예산!C$15:C$50,B6)*10000,0) | D6: 0 | E6: =C6+D6 | F6: =SUMPRODUCT((MONTH(뱅샐입력!A$4:A$3003)=3)*(YEAR(뱅샐입력!A$4:A$3003)=설정!C3)*(뱅샐입력!C$4:C$3003="지출")*(뱅샐입력!D$4:D$3003=A6)*ABS(뱅샐입력!G$4:G$3003)) | G6: =E6-F6 | H6: =IFERROR(F6/E6,0) | I6: =IFERROR('02월'!F6,0) | J6: =F6-I6
A7: 고정비 | B7: 보험/연금 | C7: =IFERROR(SUMIFS(수입&예산!H$15:H$50,수입&예산!B$15:B$50,A7,수입&예산!C$15:C$50,B7)*10000,0) | D7: 0 | E7: =C7+D7 | F7: =SUMPRODUCT((MONTH(뱅샐입력!A$4:A$3003)=3)*(YEAR(뱅샐입력!A$4:A$3003)=설정!C3)*(뱅샐입력!C$4:C$3003="지출")*(뱅샐입력!D$4:D$3003=A7)*ABS(뱅샐입력!G$4:G$3003)) | G7: =E7-F7 | H7: =IFERROR(F7/E7,0) | I7: =IFERROR('02월'!F7,0) | J7: =F7-I7
A8: 고정비 | B8: 부모님 | C8: =IFERROR(SUMIFS(수입&예산!H$15:H$50,수입&예산!B$15:B$50,A8,수입&예산!C$15:C$50,B8)*10000,0) | D8: 0 | E8: =C8+D8 | F8: =SUMPRODUCT((MONTH(뱅샐입력!A$4:A$3003)=3)*(YEAR(뱅샐입력!A$4:A$3003)=설정!C3)*(뱅샐입력!C$4:C$3003="지출")*(뱅샐입력!D$4:D$3003=A8)*ABS(뱅샐입력!G$4:G$3003)) | G8: =E8-F8 | H8: =IFERROR(F8/E8,0) | I8: =IFERROR('02월'!F8,0) | J8: =F8-I8
A9: 고정비 | B9: 기흥모임 | C9: =IFERROR(SUMIFS(수입&예산!H$15:H$50,수입&예산!B$15:B$50,A9,수입&예산!C$15:C$50,B9)*10000,0) | D9: 0 | E9: =C9+D9 | F9: =SUMPRODUCT((MONTH(뱅샐입력!A$4:A$3003)=3)*(YEAR(뱅샐입력!A$4:A$3003)=설정!C3)*(뱅샐입력!C$4:C$3003="지출")*(뱅샐입력!D$4:D$3003=A9)*ABS(뱅샐입력!G$4:G$3003)) | G9: =E9-F9 | H9: =IFERROR(F9/E9,0) | I9: =IFERROR('02월'!F9,0) | J9: =F9-I9
A10: 고정비 | B10: 구독형서비스 | C10: =IFERROR(SUMIFS(수입&예산!H$15:H$50,수입&예산!B$15:B$50,A10,수입&예산!C$15:C$50,B10)*10000,0) | D10: 0 | E10: =C10+D10 | F10: =SUMPRODUCT((MONTH(뱅샐입력!A$4:A$3003)=3)*(YEAR(뱅샐입력!A$4:A$3003)=설정!C3)*(뱅샐입력!C$4:C$3003="지출")*(뱅샐입력!D$4:D$3003=A10)*ABS(뱅샐입력!G$4:G$3003)) | G10: =E10-F10 | H10: =IFERROR(F10/E10,0) | I10: =IFERROR('02월'!F10,0) | J10: =F10-I10
A11: 고정비 | B11: 용돈 | C11: =IFERROR(SUMIFS(수입&예산!H$15:H$50,수입&예산!B$15:B$50,A11,수입&예산!C$15:C$50,B11)*10000,0) | D11: 0 | E11: =C11+D11 | F11: =SUMPRODUCT((MONTH(뱅샐입력!A$4:A$3003)=3)*(YEAR(뱅샐입력!A$4:A$3003)=설정!C3)*(뱅샐입력!C$4:C$3003="지출")*(뱅샐입력!D$4:D$3003=A11)*ABS(뱅샐입력!G$4:G$3003)) | G11: =E11-F11 | H11: =IFERROR(F11/E11,0) | I11: =IFERROR('02월'!F11,0) | J11: =F11-I11
A12: 고정비 | B12: 아파트관리비 | C12: =IFERROR(SUMIFS(수입&예산!H$15:H$50,수입&예산!B$15:B$50,A12,수입&예산!C$15:C$50,B12)*10000,0) | D12: 0 | E12: =C12+D12 | F12: =SUMPRODUCT((MONTH(뱅샐입력!A$4:A$3003)=3)*(YEAR(뱅샐입력!A$4:A$3003)=설정!C3)*(뱅샐입력!C$4:C$3003="지출")*(뱅샐입력!D$4:D$3003=A12)*ABS(뱅샐입력!G$4:G$3003)) | G12: =E12-F12 | H12: =IFERROR(F12/E12,0) | I12: =IFERROR('02월'!F12,0) | J12: =F12-I12
A13: 생활비 | B13: 생활비 | C13: =IFERROR(SUMIFS(수입&예산!H$15:H$50,수입&예산!B$15:B$50,A13,수입&예산!C$15:C$50,B13)*10000,0) | D13: 0 | E13: =C13+D13 | F13: =SUMPRODUCT((MONTH(뱅샐입력!A$4:A$3003)=3)*(YEAR(뱅샐입력!A$4:A$3003)=설정!C3)*(뱅샐입력!C$4:C$3003="지출")*(뱅샐입력!D$4:D$3003=A13)*ABS(뱅샐입력!G$4:G$3003)) | G13: =E13-F13 | H13: =IFERROR(F13/E13,0) | I13: =IFERROR('02월'!F13,0) | J13: =F13-I13
A14: 의료/건강 | B14: 의료/건강 | C14: =IFERROR(SUMIFS(수입&예산!H$15:H$50,수입&예산!B$15:B$50,A14,수입&예산!C$15:C$50,B14)*10000,0) | D14: 0 | E14: =C14+D14 | F14: =SUMPRODUCT((MONTH(뱅샐입력!A$4:A$3003)=3)*(YEAR(뱅샐입력!A$4:A$3003)=설정!C3)*(뱅샐입력!C$4:C$3003="지출")*(뱅샐입력!D$4:D$3003=A14)*ABS(뱅샐입력!G$4:G$3003)) | G14: =E14-F14 | H14: =IFERROR(F14/E14,0) | I14: =IFERROR('02월'!F14,0) | J14: =F14-I14
A15: 모임 | B15: 모임 | C15: =IFERROR(SUMIFS(수입&예산!H$15:H$50,수입&예산!B$15:B$50,A15,수입&예산!C$15:C$50,B15)*10000,0) | D15: 0 | E15: =C15+D15 | F15: =SUMPRODUCT((MONTH(뱅샐입력!A$4:A$3003)=3)*(YEAR(뱅샐입력!A$4:A$3003)=설정!C3)*(뱅샐입력!C$4:C$3003="지출")*(뱅샐입력!D$4:D$3003=A15)*ABS(뱅샐입력!G$4:G$3003)) | G15: =E15-F15 | H15: =IFERROR(F15/E15,0) | I15: =IFERROR('02월'!F15,0) | J15: =F15-I15
A16: Tiss | B16: 개인 | C16: =IFERROR(SUMIFS(수입&예산!H$15:H$50,수입&예산!B$15:B$50,A16,수입&예산!C$15:C$50,B16)*10000,0) | D16: 0 | E16: =C16+D16 | F16: =SUMPRODUCT((MONTH(뱅샐입력!A$4:A$3003)=3)*(YEAR(뱅샐입력!A$4:A$3003)=설정!C3)*(뱅샐입력!C$4:C$3003="지출")*(뱅샐입력!D$4:D$3003=A16)*ABS(뱅샐입력!G$4:G$3003)) | G16: =E16-F16 | H16: =IFERROR(F16/E16,0) | I16: =IFERROR('02월'!F16,0) | J16: =F16-I16
A17: JM | B17: 개인 | C17: =IFERROR(SUMIFS(수입&예산!H$15:H$50,수입&예산!B$15:B$50,A17,수입&예산!C$15:C$50,B17)*10000,0) | D17: 0 | E17: =C17+D17 | F17: =SUMPRODUCT((MONTH(뱅샐입력!A$4:A$3003)=3)*(YEAR(뱅샐입력!A$4:A$3003)=설정!C3)*(뱅샐입력!C$4:C$3003="지출")*(뱅샐입력!D$4:D$3003=A17)*ABS(뱅샐입력!G$4:G$3003)) | G17: =E17-F17 | H17: =IFERROR(F17/E17,0) | I17: =IFERROR('02월'!F17,0) | J17: =F17-I17
A18: 세금 | B18: 재산세(주택) | C18: =IFERROR(SUMIFS(수입&예산!H$15:H$50,수입&예산!B$15:B$50,A18,수입&예산!C$15:C$50,B18)*10000,0) | D18: 0 | E18: =C18+D18 | F18: =SUMPRODUCT((MONTH(뱅샐입력!A$4:A$3003)=3)*(YEAR(뱅샐입력!A$4:A$3003)=설정!C3)*(뱅샐입력!C$4:C$3003="지출")*(뱅샐입력!D$4:D$3003=A18)*ABS(뱅샐입력!G$4:G$3003)) | G18: =E18-F18 | H18: =IFERROR(F18/E18,0) | I18: =IFERROR('02월'!F18,0) | J18: =F18-I18
A19: 세금 | B19: 종합소득세 | C19: =IFERROR(SUMIFS(수입&예산!H$15:H$50,수입&예산!B$15:B$50,A19,수입&예산!C$15:C$50,B19)*10000,0) | D19: 0 | E19: =C19+D19 | F19: =SUMPRODUCT((MONTH(뱅샐입력!A$4:A$3003)=3)*(YEAR(뱅샐입력!A$4:A$3003)=설정!C3)*(뱅샐입력!C$4:C$3003="지출")*(뱅샐입력!D$4:D$3003=A19)*ABS(뱅샐입력!G$4:G$3003)) | G19: =E19-F19 | H19: =IFERROR(F19/E19,0) | I19: =IFERROR('02월'!F19,0) | J19: =F19-I19
A20: 대출상환 | B20: 디딤돌대출 | C20: =IFERROR(SUMIFS(수입&예산!H$15:H$50,수입&예산!B$15:B$50,A20,수입&예산!C$15:C$50,B20)*10000,0) | D20: 0 | E20: =C20+D20 | F20: =SUMPRODUCT((MONTH(뱅샐입력!A$4:A$3003)=3)*(YEAR(뱅샐입력!A$4:A$3003)=설정!C3)*(뱅샐입력!C$4:C$3003="지출")*(뱅샐입력!D$4:D$3003=A20)*ABS(뱅샐입력!G$4:G$3003)) | G20: =E20-F20 | H20: =IFERROR(F20/E20,0) | I20: =IFERROR('02월'!F20,0) | J20: =F20-I20
A21: 부동산 | B21: 부동산 | C21: =IFERROR(SUMIFS(수입&예산!H$15:H$50,수입&예산!B$15:B$50,A21,수입&예산!C$15:C$50,B21)*10000,0) | D21: 0 | E21: =C21+D21 | F21: =SUMPRODUCT((MONTH(뱅샐입력!A$4:A$3003)=3)*(YEAR(뱅샐입력!A$4:A$3003)=설정!C3)*(뱅샐입력!C$4:C$3003="지출")*(뱅샐입력!D$4:D$3003=A21)*ABS(뱅샐입력!G$4:G$3003)) | G21: =E21-F21 | H21: =IFERROR(F21/E21,0) | I21: =IFERROR('02월'!F21,0) | J21: =F21-I21
A22: 기타 | B22: 기타 | C22: =IFERROR(SUMIFS(수입&예산!H$15:H$50,수입&예산!B$15:B$50,A22,수입&예산!C$15:C$50,B22)*10000,0) | D22: 0 | E22: =C22+D22 | F22: =SUMPRODUCT((MONTH(뱅샐입력!A$4:A$3003)=3)*(YEAR(뱅샐입력!A$4:A$3003)=설정!C3)*(뱅샐입력!C$4:C$3003="지출")*(뱅샐입력!D$4:D$3003=A22)*ABS(뱅샐입력!G$4:G$3003)) | G22: =E22-F22 | H22: =IFERROR(F22/E22,0) | I22: =IFERROR('02월'!F22,0) | J22: =F22-I22
A23: 합계 | C23: =SUM(C5:C22) | D23: =SUM(D5:D22) | E23: =SUM(E5:E22) | F23: =SUM(F5:F22) | G23: =SUM(G5:G22) | H23: =IFERROR(F23/E23,0) | I23: =SUM(I5:I22) | J23: =F23-I23
A25: 날짜 | B25: 타입 | C25: 대분류 | D25: 소분류 | E25: 내용 | F25: 금액 | G25: 결제수단 | H25: 메모
A26: =IFERROR(FILTER(CHOOSE({1,2,3,4,5,6,7,8},뱅샐입력!A$4:A$3003,뱅샐입력!C$4:C$3003,뱅샐입력!D$4:D$3003,뱅샐입력!E$4:E$3003,뱅샐입력!F$4:F$3003,뱅샐입력!G$4:G$3003,뱅샐입력!I$4:I$3003,뱅샐입력!J$4:J$3003),(MONTH(뱅샐입력!A$4:A$3003)=3)*(YEAR(뱅샐입력!A$4:A$3003)=설정!C3)*(뱅샐입력!C$4:C$3003<>"이체")),"데이터 없음")

Sheet 04월
A1: =TEXT(DATE(설정!C3,4,1),"YYYY년 MM월 가계부")
A2: 이번달 수입 | B2: =SUMPRODUCT((MONTH(뱅샐입력!A$4:A$3003)=4)*(YEAR(뱅샐입력!A$4:A$3003)=설정!C3)*(뱅샐입력!C$4:C$3003="수입")*뱅샐입력!G$4:G$3003) | C2: 이번달 지출 | D2: =SUMPRODUCT((MONTH(뱅샐입력!A$4:A$3003)=4)*(YEAR(뱅샐입력!A$4:A$3003)=설정!C3)*(뱅샐입력!C$4:C$3003="지출")*ABS(뱅샐입력!G$4:G$3003)) | E2: 잔액 | F2: =B2-D2
A4: 대분류 | B4: 중분류 | C4: 예산기본 | D4: 예산추가 | E4: 예산합계 | F4: 실제지출 | G4: 차액 | H4: 달성율 | I4: 전월지출 | J4: 전월대비
A5: 고정비 | B5: 교통비 | C5: =IFERROR(SUMIFS(수입&예산!H$15:H$50,수입&예산!B$15:B$50,A5,수입&예산!C$15:C$50,B5)*10000,0) | D5: 0 | E5: =C5+D5 | F5: =SUMPRODUCT((MONTH(뱅샐입력!A$4:A$3003)=4)*(YEAR(뱅샐입력!A$4:A$3003)=설정!C3)*(뱅샐입력!C$4:C$3003="지출")*(뱅샐입력!D$4:D$3003=A5)*ABS(뱅샐입력!G$4:G$3003)) | G5: =E5-F5 | H5: =IFERROR(F5/E5,0) | I5: =IFERROR('03월'!F5,0) | J5: =F5-I5
A6: 고정비 | B6: 휴대폰/인터넷 | C6: =IFERROR(SUMIFS(수입&예산!H$15:H$50,수입&예산!B$15:B$50,A6,수입&예산!C$15:C$50,B6)*10000,0) | D6: 0 | E6: =C6+D6 | F6: =SUMPRODUCT((MONTH(뱅샐입력!A$4:A$3003)=4)*(YEAR(뱅샐입력!A$4:A$3003)=설정!C3)*(뱅샐입력!C$4:C$3003="지출")*(뱅샐입력!D$4:D$3003=A6)*ABS(뱅샐입력!G$4:G$3003)) | G6: =E6-F6 | H6: =IFERROR(F6/E6,0) | I6: =IFERROR('03월'!F6,0) | J6: =F6-I6
A7: 고정비 | B7: 보험/연금 | C7: =IFERROR(SUMIFS(수입&예산!H$15:H$50,수입&예산!B$15:B$50,A7,수입&예산!C$15:C$50,B7)*10000,0) | D7: 0 | E7: =C7+D7 | F7: =SUMPRODUCT((MONTH(뱅샐입력!A$4:A$3003)=4)*(YEAR(뱅샐입력!A$4:A$3003)=설정!C3)*(뱅샐입력!C$4:C$3003="지출")*(뱅샐입력!D$4:D$3003=A7)*ABS(뱅샐입력!G$4:G$3003)) | G7: =E7-F7 | H7: =IFERROR(F7/E7,0) | I7: =IFERROR('03월'!F7,0) | J7: =F7-I7
A8: 고정비 | B8: 부모님 | C8: =IFERROR(SUMIFS(수입&예산!H$15:H$50,수입&예산!B$15:B$50,A8,수입&예산!C$15:C$50,B8)*10000,0) | D8: 0 | E8: =C8+D8 | F8: =SUMPRODUCT((MONTH(뱅샐입력!A$4:A$3003)=4)*(YEAR(뱅샐입력!A$4:A$3003)=설정!C3)*(뱅샐입력!C$4:C$3003="지출")*(뱅샐입력!D$4:D$3003=A8)*ABS(뱅샐입력!G$4:G$3003)) | G8: =E8-F8 | H8: =IFERROR(F8/E8,0) | I8: =IFERROR('03월'!F8,0) | J8: =F8-I8
A9: 고정비 | B9: 기흥모임 | C9: =IFERROR(SUMIFS(수입&예산!H$15:H$50,수입&예산!B$15:B$50,A9,수입&예산!C$15:C$50,B9)*10000,0) | D9: 0 | E9: =C9+D9 | F9: =SUMPRODUCT((MONTH(뱅샐입력!A$4:A$3003)=4)*(YEAR(뱅샐입력!A$4:A$3003)=설정!C3)*(뱅샐입력!C$4:C$3003="지출")*(뱅샐입력!D$4:D$3003=A9)*ABS(뱅샐입력!G$4:G$3003)) | G9: =E9-F9 | H9: =IFERROR(F9/E9,0) | I9: =IFERROR('03월'!F9,0) | J9: =F9-I9
A10: 고정비 | B10: 구독형서비스 | C10: =IFERROR(SUMIFS(수입&예산!H$15:H$50,수입&예산!B$15:B$50,A10,수입&예산!C$15:C$50,B10)*10000,0) | D10: 0 | E10: =C10+D10 | F10: =SUMPRODUCT((MONTH(뱅샐입력!A$4:A$3003)=4)*(YEAR(뱅샐입력!A$4:A$3003)=설정!C3)*(뱅샐입력!C$4:C$3003="지출")*(뱅샐입력!D$4:D$3003=A10)*ABS(뱅샐입력!G$4:G$3003)) | G10: =E10-F10 | H10: =IFERROR(F10/E10,0) | I10: =IFERROR('03월'!F10,0) | J10: =F10-I10
A11: 고정비 | B11: 용돈 | C11: =IFERROR(SUMIFS(수입&예산!H$15:H$50,수입&예산!B$15:B$50,A11,수입&예산!C$15:C$50,B11)*10000,0) | D11: 0 | E11: =C11+D11 | F11: =SUMPRODUCT((MONTH(뱅샐입력!A$4:A$3003)=4)*(YEAR(뱅샐입력!A$4:A$3003)=설정!C3)*(뱅샐입력!C$4:C$3003="지출")*(뱅샐입력!D$4:D$3003=A11)*ABS(뱅샐입력!G$4:G$3003)) | G11: =E11-F11 | H11: =IFERROR(F11/E11,0) | I11: =IFERROR('03월'!F11,0) | J11: =F11-I11
A12: 고정비 | B12: 아파트관리비 | C12: =IFERROR(SUMIFS(수입&예산!H$15:H$50,수입&예산!B$15:B$50,A12,수입&예산!C$15:C$50,B12)*10000,0) | D12: 0 | E12: =C12+D12 | F12: =SUMPRODUCT((MONTH(뱅샐입력!A$4:A$3003)=4)*(YEAR(뱅샐입력!A$4:A$3003)=설정!C3)*(뱅샐입력!C$4:C$3003="지출")*(뱅샐입력!D$4:D$3003=A12)*ABS(뱅샐입력!G$4:G$3003)) | G12: =E12-F12 | H12: =IFERROR(F12/E12,0) | I12: =IFERROR('03월'!F12,0) | J12: =F12-I12
A13: 생활비 | B13: 생활비 | C13: =IFERROR(SUMIFS(수입&예산!H$15:H$50,수입&예산!B$15:B$50,A13,수입&예산!C$15:C$50,B13)*10000,0) | D13: 0 | E13: =C13+D13 | F13: =SUMPRODUCT((MONTH(뱅샐입력!A$4:A$3003)=4)*(YEAR(뱅샐입력!A$4:A$3003)=설정!C3)*(뱅샐입력!C$4:C$3003="지출")*(뱅샐입력!D$4:D$3003=A13)*ABS(뱅샐입력!G$4:G$3003)) | G13: =E13-F13 | H13: =IFERROR(F13/E13,0) | I13: =IFERROR('03월'!F13,0) | J13: =F13-I13
A14: 의료/건강 | B14: 의료/건강 | C14: =IFERROR(SUMIFS(수입&예산!H$15:H$50,수입&예산!B$15:B$50,A14,수입&예산!C$15:C$50,B14)*10000,0) | D14: 0 | E14: =C14+D14 | F14: =SUMPRODUCT((MONTH(뱅샐입력!A$4:A$3003)=4)*(YEAR(뱅샐입력!A$4:A$3003)=설정!C3)*(뱅샐입력!C$4:C$3003="지출")*(뱅샐입력!D$4:D$3003=A14)*ABS(뱅샐입력!G$4:G$3003)) | G14: =E14-F14 | H14: =IFERROR(F14/E14,0) | I14: =IFERROR('03월'!F14,0) | J14: =F14-I14
A15: 모임 | B15: 모임 | C15: =IFERROR(SUMIFS(수입&예산!H$15:H$50,수입&예산!B$15:B$50,A15,수입&예산!C$15:C$50,B15)*10000,0) | D15: 0 | E15: =C15+D15 | F15: =SUMPRODUCT((MONTH(뱅샐입력!A$4:A$3003)=4)*(YEAR(뱅샐입력!A$4:A$3003)=설정!C3)*(뱅샐입력!C$4:C$3003="지출")*(뱅샐입력!D$4:D$3003=A15)*ABS(뱅샐입력!G$4:G$3003)) | G15: =E15-F15 | H15: =IFERROR(F15/E15,0) | I15: =IFERROR('03월'!F15,0) | J15: =F15-I15
A16: Tiss | B16: 개인 | C16: =IFERROR(SUMIFS(수입&예산!H$15:H$50,수입&예산!B$15:B$50,A16,수입&예산!C$15:C$50,B16)*10000,0) | D16: 0 | E16: =C16+D16 | F16: =SUMPRODUCT((MONTH(뱅샐입력!A$4:A$3003)=4)*(YEAR(뱅샐입력!A$4:A$3003)=설정!C3)*(뱅샐입력!C$4:C$3003="지출")*(뱅샐입력!D$4:D$3003=A16)*ABS(뱅샐입력!G$4:G$3003)) | G16: =E16-F16 | H16: =IFERROR(F16/E16,0) | I16: =IFERROR('03월'!F16,0) | J16: =F16-I16
A17: JM | B17: 개인 | C17: =IFERROR(SUMIFS(수입&예산!H$15:H$50,수입&예산!B$15:B$50,A17,수입&예산!C$15:C$50,B17)*10000,0) | D17: 0 | E17: =C17+D17 | F17: =SUMPRODUCT((MONTH(뱅샐입력!A$4:A$3003)=4)*(YEAR(뱅샐입력!A$4:A$3003)=설정!C3)*(뱅샐입력!C$4:C$3003="지출")*(뱅샐입력!D$4:D$3003=A17)*ABS(뱅샐입력!G$4:G$3003)) | G17: =E17-F17 | H17: =IFERROR(F17/E17,0) | I17: =IFERROR('03월'!F17,0) | J17: =F17-I17
A18: 세금 | B18: 재산세(주택) | C18: =IFERROR(SUMIFS(수입&예산!H$15:H$50,수입&예산!B$15:B$50,A18,수입&예산!C$15:C$50,B18)*10000,0) | D18: 0 | E18: =C18+D18 | F18: =SUMPRODUCT((MONTH(뱅샐입력!A$4:A$3003)=4)*(YEAR(뱅샐입력!A$4:A$3003)=설정!C3)*(뱅샐입력!C$4:C$3003="지출")*(뱅샐입력!D$4:D$3003=A18)*ABS(뱅샐입력!G$4:G$3003)) | G18: =E18-F18 | H18: =IFERROR(F18/E18,0) | I18: =IFERROR('03월'!F18,0) | J18: =F18-I18
A19: 세금 | B19: 종합소득세 | C19: =IFERROR(SUMIFS(수입&예산!H$15:H$50,수입&예산!B$15:B$50,A19,수입&예산!C$15:C$50,B19)*10000,0) | D19: 0 | E19: =C19+D19 | F19: =SUMPRODUCT((MONTH(뱅샐입력!A$4:A$3003)=4)*(YEAR(뱅샐입력!A$4:A$3003)=설정!C3)*(뱅샐입력!C$4:C$3003="지출")*(뱅샐입력!D$4:D$3003=A19)*ABS(뱅샐입력!G$4:G$3003)) | G19: =E19-F19 | H19: =IFERROR(F19/E19,0) | I19: =IFERROR('03월'!F19,0) | J19: =F19-I19
A20: 대출상환 | B20: 디딤돌대출 | C20: =IFERROR(SUMIFS(수입&예산!H$15:H$50,수입&예산!B$15:B$50,A20,수입&예산!C$15:C$50,B20)*10000,0) | D20: 0 | E20: =C20+D20 | F20: =SUMPRODUCT((MONTH(뱅샐입력!A$4:A$3003)=4)*(YEAR(뱅샐입력!A$4:A$3003)=설정!C3)*(뱅샐입력!C$4:C$3003="지출")*(뱅샐입력!D$4:D$3003=A20)*ABS(뱅샐입력!G$4:G$3003)) | G20: =E20-F20 | H20: =IFERROR(F20/E20,0) | I20: =IFERROR('03월'!F20,0) | J20: =F20-I20
A21: 부동산 | B21: 부동산 | C21: =IFERROR(SUMIFS(수입&예산!H$15:H$50,수입&예산!B$15:B$50,A21,수입&예산!C$15:C$50,B21)*10000,0) | D21: 0 | E21: =C21+D21 | F21: =SUMPRODUCT((MONTH(뱅샐입력!A$4:A$3003)=4)*(YEAR(뱅샐입력!A$4:A$3003)=설정!C3)*(뱅샐입력!C$4:C$3003="지출")*(뱅샐입력!D$4:D$3003=A21)*ABS(뱅샐입력!G$4:G$3003)) | G21: =E21-F21 | H21: =IFERROR(F21/E21,0) | I21: =IFERROR('03월'!F21,0) | J21: =F21-I21
A22: 기타 | B22: 기타 | C22: =IFERROR(SUMIFS(수입&예산!H$15:H$50,수입&예산!B$15:B$50,A22,수입&예산!C$15:C$50,B22)*10000,0) | D22: 0 | E22: =C22+D22 | F22: =SUMPRODUCT((MONTH(뱅샐입력!A$4:A$3003)=4)*(YEAR(뱅샐입력!A$4:A$3003)=설정!C3)*(뱅샐입력!C$4:C$3003="지출")*(뱅샐입력!D$4:D$3003=A22)*ABS(뱅샐입력!G$4:G$3003)) | G22: =E22-F22 | H22: =IFERROR(F22/E22,0) | I22: =IFERROR('03월'!F22,0) | J22: =F22-I22
A23: 합계 | C23: =SUM(C5:C22) | D23: =SUM(D5:D22) | E23: =SUM(E5:E22) | F23: =SUM(F5:F22) | G23: =SUM(G5:G22) | H23: =IFERROR(F23/E23,0) | I23: =SUM(I5:I22) | J23: =F23-I23
A25: 날짜 | B25: 타입 | C25: 대분류 | D25: 소분류 | E25: 내용 | F25: 금액 | G25: 결제수단 | H25: 메모
A26: =IFERROR(FILTER(CHOOSE({1,2,3,4,5,6,7,8},뱅샐입력!A$4:A$3003,뱅샐입력!C$4:C$3003,뱅샐입력!D$4:D$3003,뱅샐입력!E$4:E$3003,뱅샐입력!F$4:F$3003,뱅샐입력!G$4:G$3003,뱅샐입력!I$4:I$3003,뱅샐입력!J$4:J$3003),(MONTH(뱅샐입력!A$4:A$3003)=4)*(YEAR(뱅샐입력!A$4:A$3003)=설정!C3)*(뱅샐입력!C$4:C$3003<>"이체")),"데이터 없음")

Sheet 05월
A1: =TEXT(DATE(설정!C3,5,1),"YYYY년 MM월 가계부")
A2: 이번달 수입 | B2: =SUMPRODUCT((MONTH(뱅샐입력!A$4:A$3003)=5)*(YEAR(뱅샐입력!A$4:A$3003)=설정!C3)*(뱅샐입력!C$4:C$3003="수입")*뱅샐입력!G$4:G$3003) | C2: 이번달 지출 | D2: =SUMPRODUCT((MONTH(뱅샐입력!A$4:A$3003)=5)*(YEAR(뱅샐입력!A$4:A$3003)=설정!C3)*(뱅샐입력!C$4:C$3003="지출")*ABS(뱅샐입력!G$4:G$3003)) | E2: 잔액 | F2: =B2-D2
A4: 대분류 | B4: 중분류 | C4: 예산기본 | D4: 예산추가 | E4: 예산합계 | F4: 실제지출 | G4: 차액 | H4: 달성율 | I4: 전월지출 | J4: 전월대비
A5: 고정비 | B5: 교통비 | C5: =IFERROR(SUMIFS(수입&예산!H$15:H$50,수입&예산!B$15:B$50,A5,수입&예산!C$15:C$50,B5)*10000,0) | D5: 0 | E5: =C5+D5 | F5: =SUMPRODUCT((MONTH(뱅샐입력!A$4:A$3003)=5)*(YEAR(뱅샐입력!A$4:A$3003)=설정!C3)*(뱅샐입력!C$4:C$3003="지출")*(뱅샐입력!D$4:D$3003=A5)*ABS(뱅샐입력!G$4:G$3003)) | G5: =E5-F5 | H5: =IFERROR(F5/E5,0) | I5: =IFERROR('04월'!F5,0) | J5: =F5-I5
A6: 고정비 | B6: 휴대폰/인터넷 | C6: =IFERROR(SUMIFS(수입&예산!H$15:H$50,수입&예산!B$15:B$50,A6,수입&예산!C$15:C$50,B6)*10000,0) | D6: 0 | E6: =C6+D6 | F6: =SUMPRODUCT((MONTH(뱅샐입력!A$4:A$3003)=5)*(YEAR(뱅샐입력!A$4:A$3003)=설정!C3)*(뱅샐입력!C$4:C$3003="지출")*(뱅샐입력!D$4:D$3003=A6)*ABS(뱅샐입력!G$4:G$3003)) | G6: =E6-F6 | H6: =IFERROR(F6/E6,0) | I6: =IFERROR('04월'!F6,0) | J6: =F6-I6
A7: 고정비 | B7: 보험/연금 | C7: =IFERROR(SUMIFS(수입&예산!H$15:H$50,수입&예산!B$15:B$50,A7,수입&예산!C$15:C$50,B7)*10000,0) | D7: 0 | E7: =C7+D7 | F7: =SUMPRODUCT((MONTH(뱅샐입력!A$4:A$3003)=5)*(YEAR(뱅샐입력!A$4:A$3003)=설정!C3)*(뱅샐입력!C$4:C$3003="지출")*(뱅샐입력!D$4:D$3003=A7)*ABS(뱅샐입력!G$4:G$3003)) | G7: =E7-F7 | H7: =IFERROR(F7/E7,0) | I7: =IFERROR('04월'!F7,0) | J7: =F7-I7
A8: 고정비 | B8: 부모님 | C8: =IFERROR(SUMIFS(수입&예산!H$15:H$50,수입&예산!B$15:B$50,A8,수입&예산!C$15:C$50,B8)*10000,0) | D8: 0 | E8: =C8+D8 | F8: =SUMPRODUCT((MONTH(뱅샐입력!A$4:A$3003)=5)*(YEAR(뱅샐입력!A$4:A$3003)=설정!C3)*(뱅샐입력!C$4:C$3003="지출")*(뱅샐입력!D$4:D$3003=A8)*ABS(뱅샐입력!G$4:G$3003)) | G8: =E8-F8 | H8: =IFERROR(F8/E8,0) | I8: =IFERROR('04월'!F8,0) | J8: =F8-I8
A9: 고정비 | B9: 기흥모임 | C9: =IFERROR(SUMIFS(수입&예산!H$15:H$50,수입&예산!B$15:B$50,A9,수입&예산!C$15:C$50,B9)*10000,0) | D9: 0 | E9: =C9+D9 | F9: =SUMPRODUCT((MONTH(뱅샐입력!A$4:A$3003)=5)*(YEAR(뱅샐입력!A$4:A$3003)=설정!C3)*(뱅샐입력!C$4:C$3003="지출")*(뱅샐입력!D$4:D$3003=A9)*ABS(뱅샐입력!G$4:G$3003)) | G9: =E9-F9 | H9: =IFERROR(F9/E9,0) | I9: =IFERROR('04월'!F9,0) | J9: =F9-I9
A10: 고정비 | B10: 구독형서비스 | C10: =IFERROR(SUMIFS(수입&예산!H$15:H$50,수입&예산!B$15:B$50,A10,수입&예산!C$15:C$50,B10)*10000,0) | D10: 0 | E10: =C10+D10 | F10: =SUMPRODUCT((MONTH(뱅샐입력!A$4:A$3003)=5)*(YEAR(뱅샐입력!A$4:A$3003)=설정!C3)*(뱅샐입력!C$4:C$3003="지출")*(뱅샐입력!D$4:D$3003=A10)*ABS(뱅샐입력!G$4:G$3003)) | G10: =E10-F10 | H10: =IFERROR(F10/E10,0) | I10: =IFERROR('04월'!F10,0) | J10: =F10-I10
A11: 고정비 | B11: 용돈 | C11: =IFERROR(SUMIFS(수입&예산!H$15:H$50,수입&예산!B$15:B$50,A11,수입&예산!C$15:C$50,B11)*10000,0) | D11: 0 | E11: =C11+D11 | F11: =SUMPRODUCT((MONTH(뱅샐입력!A$4:A$3003)=5)*(YEAR(뱅샐입력!A$4:A$3003)=설정!C3)*(뱅샐입력!C$4:C$3003="지출")*(뱅샐입력!D$4:D$3003=A11)*ABS(뱅샐입력!G$4:G$3003)) | G11: =E11-F11 | H11: =IFERROR(F11/E11,0) | I11: =IFERROR('04월'!F11,0) | J11: =F11-I11
A12: 고정비 | B12: 아파트관리비 | C12: =IFERROR(SUMIFS(수입&예산!H$15:H$50,수입&예산!B$15:B$50,A12,수입&예산!C$15:C$50,B12)*10000,0) | D12: 0 | E12: =C12+D12 | F12: =SUMPRODUCT((MONTH(뱅샐입력!A$4:A$3003)=5)*(YEAR(뱅샐입력!A$4:A$3003)=설정!C3)*(뱅샐입력!C$4:C$3003="지출")*(뱅샐입력!D$4:D$3003=A12)*ABS(뱅샐입력!G$4:G$3003)) | G12: =E12-F12 | H12: =IFERROR(F12/E12,0) | I12: =IFERROR('04월'!F12,0) | J12: =F12-I12
A13: 생활비 | B13: 생활비 | C13: =IFERROR(SUMIFS(수입&예산!H$15:H$50,수입&예산!B$15:B$50,A13,수입&예산!C$15:C$50,B13)*10000,0) | D13: 0 | E13: =C13+D13 | F13: =SUMPRODUCT((MONTH(뱅샐입력!A$4:A$3003)=5)*(YEAR(뱅샐입력!A$4:A$3003)=설정!C3)*(뱅샐입력!C$4:C$3003="지출")*(뱅샐입력!D$4:D$3003=A13)*ABS(뱅샐입력!G$4:G$3003)) | G13: =E13-F13 | H13: =IFERROR(F13/E13,0) | I13: =IFERROR('04월'!F13,0) | J13: =F13-I13
A14: 의료/건강 | B14: 의료/건강 | C14: =IFERROR(SUMIFS(수입&예산!H$15:H$50,수입&예산!B$15:B$50,A14,수입&예산!C$15:C$50,B14)*10000,0) | D14: 0 | E14: =C14+D14 | F14: =SUMPRODUCT((MONTH(뱅샐입력!A$4:A$3003)=5)*(YEAR(뱅샐입력!A$4:A$3003)=설정!C3)*(뱅샐입력!C$4:C$3003="지출")*(뱅샐입력!D$4:D$3003=A14)*ABS(뱅샐입력!G$4:G$3003)) | G14: =E14-F14 | H14: =IFERROR(F14/E14,0) | I14: =IFERROR('04월'!F14,0) | J14: =F14-I14
A15: 모임 | B15: 모임 | C15: =IFERROR(SUMIFS(수입&예산!H$15:H$50,수입&예산!B$15:B$50,A15,수입&예산!C$15:C$50,B15)*10000,0) | D15: 0 | E15: =C15+D15 | F15: =SUMPRODUCT((MONTH(뱅샐입력!A$4:A$3003)=5)*(YEAR(뱅샐입력!A$4:A$3003)=설정!C3)*(뱅샐입력!C$4:C$3003="지출")*(뱅샐입력!D$4:D$3003=A15)*ABS(뱅샐입력!G$4:G$3003)) | G15: =E15-F15 | H15: =IFERROR(F15/E15,0) | I15: =IFERROR('04월'!F15,0) | J15: =F15-I15
A16: Tiss | B16: 개인 | C16: =IFERROR(SUMIFS(수입&예산!H$15:H$50,수입&예산!B$15:B$50,A16,수입&예산!C$15:C$50,B16)*10000,0) | D16: 0 | E16: =C16+D16 | F16: =SUMPRODUCT((MONTH(뱅샐입력!A$4:A$3003)=5)*(YEAR(뱅샐입력!A$4:A$3003)=설정!C3)*(뱅샐입력!C$4:C$3003="지출")*(뱅샐입력!D$4:D$3003=A16)*ABS(뱅샐입력!G$4:G$3003)) | G16: =E16-F16 | H16: =IFERROR(F16/E16,0) | I16: =IFERROR('04월'!F16,0) | J16: =F16-I16
A17: JM | B17: 개인 | C17: =IFERROR(SUMIFS(수입&예산!H$15:H$50,수입&예산!B$15:B$50,A17,수입&예산!C$15:C$50,B17)*10000,0) | D17: 0 | E17: =C17+D17 | F17: =SUMPRODUCT((MONTH(뱅샐입력!A$4:A$3003)=5)*(YEAR(뱅샐입력!A$4:A$3003)=설정!C3)*(뱅샐입력!C$4:C$3003="지출")*(뱅샐입력!D$4:D$3003=A17)*ABS(뱅샐입력!G$4:G$3003)) | G17: =E17-F17 | H17: =IFERROR(F17/E17,0) | I17: =IFERROR('04월'!F17,0) | J17: =F17-I17
A18: 세금 | B18: 재산세(주택) | C18: =IFERROR(SUMIFS(수입&예산!H$15:H$50,수입&예산!B$15:B$50,A18,수입&예산!C$15:C$50,B18)*10000,0) | D18: 0 | E18: =C18+D18 | F18: =SUMPRODUCT((MONTH(뱅샐입력!A$4:A$3003)=5)*(YEAR(뱅샐입력!A$4:A$3003)=설정!C3)*(뱅샐입력!C$4:C$3003="지출")*(뱅샐입력!D$4:D$3003=A18)*ABS(뱅샐입력!G$4:G$3003)) | G18: =E18-F18 | H18: =IFERROR(F18/E18,0) | I18: =IFERROR('04월'!F18,0) | J18: =F18-I18
A19: 세금 | B19: 종합소득세 | C19: =IFERROR(SUMIFS(수입&예산!H$15:H$50,수입&예산!B$15:B$50,A19,수입&예산!C$15:C$50,B19)*10000,0) | D19: 0 | E19: =C19+D19 | F19: =SUMPRODUCT((MONTH(뱅샐입력!A$4:A$3003)=5)*(YEAR(뱅샐입력!A$4:A$3003)=설정!C3)*(뱅샐입력!C$4:C$3003="지출")*(뱅샐입력!D$4:D$3003=A19)*ABS(뱅샐입력!G$4:G$3003)) | G19: =E19-F19 | H19: =IFERROR(F19/E19,0) | I19: =IFERROR('04월'!F19,0) | J19: =F19-I19
A20: 대출상환 | B20: 디딤돌대출 | C20: =IFERROR(SUMIFS(수입&예산!H$15:H$50,수입&예산!B$15:B$50,A20,수입&예산!C$15:C$50,B20)*10000,0) | D20: 0 | E20: =C20+D20 | F20: =SUMPRODUCT((MONTH(뱅샐입력!A$4:A$3003)=5)*(YEAR(뱅샐입력!A$4:A$3003)=설정!C3)*(뱅샐입력!C$4:C$3003="지출")*(뱅샐입력!D$4:D$3003=A20)*ABS(뱅샐입력!G$4:G$3003)) | G20: =E20-F20 | H20: =IFERROR(F20/E20,0) | I20: =IFERROR('04월'!F20,0) | J20: =F20-I20
A21: 부동산 | B21: 부동산 | C21: =IFERROR(SUMIFS(수입&예산!H$15:H$50,수입&예산!B$15:B$50,A21,수입&예산!C$15:C$50,B21)*10000,0) | D21: 0 | E21: =C21+D21 | F21: =SUMPRODUCT((MONTH(뱅샐입력!A$4:A$3003)=5)*(YEAR(뱅샐입력!A$4:A$3003)=설정!C3)*(뱅샐입력!C$4:C$3003="지출")*(뱅샐입력!D$4:D$3003=A21)*ABS(뱅샐입력!G$4:G$3003)) | G21: =E21-F21 | H21: =IFERROR(F21/E21,0) | I21: =IFERROR('04월'!F21,0) | J21: =F21-I21
A22: 기타 | B22: 기타 | C22: =IFERROR(SUMIFS(수입&예산!H$15:H$50,수입&예산!B$15:B$50,A22,수입&예산!C$15:C$50,B22)*10000,0) | D22: 0 | E22: =C22+D22 | F22: =SUMPRODUCT((MONTH(뱅샐입력!A$4:A$3003)=5)*(YEAR(뱅샐입력!A$4:A$3003)=설정!C3)*(뱅샐입력!C$4:C$3003="지출")*(뱅샐입력!D$4:D$3003=A22)*ABS(뱅샐입력!G$4:G$3003)) | G22: =E22-F22 | H22: =IFERROR(F22/E22,0) | I22: =IFERROR('04월'!F22,0) | J22: =F22-I22
A23: 합계 | C23: =SUM(C5:C22) | D23: =SUM(D5:D22) | E23: =SUM(E5:E22) | F23: =SUM(F5:F22) | G23: =SUM(G5:G22) | H23: =IFERROR(F23/E23,0) | I23: =SUM(I5:I22) | J23: =F23-I23
A25: 날짜 | B25: 타입 | C25: 대분류 | D25: 소분류 | E25: 내용 | F25: 금액 | G25: 결제수단 | H25: 메모
A26: =IFERROR(FILTER(CHOOSE({1,2,3,4,5,6,7,8},뱅샐입력!A$4:A$3003,뱅샐입력!C$4:C$3003,뱅샐입력!D$4:D$3003,뱅샐입력!E$4:E$3003,뱅샐입력!F$4:F$3003,뱅샐입력!G$4:G$3003,뱅샐입력!I$4:I$3003,뱅샐입력!J$4:J$3003),(MONTH(뱅샐입력!A$4:A$3003)=5)*(YEAR(뱅샐입력!A$4:A$3003)=설정!C3)*(뱅샐입력!C$4:C$3003<>"이체")),"데이터 없음")

Sheet 06월
A1: =TEXT(DATE(설정!C3,6,1),"YYYY년 MM월 가계부")
A2: 이번달 수입 | B2: =SUMPRODUCT((MONTH(뱅샐입력!A$4:A$3003)=6)*(YEAR(뱅샐입력!A$4:A$3003)=설정!C3)*(뱅샐입력!C$4:C$3003="수입")*뱅샐입력!G$4:G$3003) | C2: 이번달 지출 | D2: =SUMPRODUCT((MONTH(뱅샐입력!A$4:A$3003)=6)*(YEAR(뱅샐입력!A$4:A$3003)=설정!C3)*(뱅샐입력!C$4:C$3003="지출")*ABS(뱅샐입력!G$4:G$3003)) | E2: 잔액 | F2: =B2-D2
A4: 대분류 | B4: 중분류 | C4: 예산기본 | D4: 예산추가 | E4: 예산합계 | F4: 실제지출 | G4: 차액 | H4: 달성율 | I4: 전월지출 | J4: 전월대비
A5: 고정비 | B5: 교통비 | C5: =IFERROR(SUMIFS(수입&예산!H$15:H$50,수입&예산!B$15:B$50,A5,수입&예산!C$15:C$50,B5)*10000,0) | D5: 0 | E5: =C5+D5 | F5: =SUMPRODUCT((MONTH(뱅샐입력!A$4:A$3003)=6)*(YEAR(뱅샐입력!A$4:A$3003)=설정!C3)*(뱅샐입력!C$4:C$3003="지출")*(뱅샐입력!D$4:D$3003=A5)*ABS(뱅샐입력!G$4:G$3003)) | G5: =E5-F5 | H5: =IFERROR(F5/E5,0) | I5: =IFERROR('05월'!F5,0) | J5: =F5-I5
A6: 고정비 | B6: 휴대폰/인터넷 | C6: =IFERROR(SUMIFS(수입&예산!H$15:H$50,수입&예산!B$15:B$50,A6,수입&예산!C$15:C$50,B6)*10000,0) | D6: 0 | E6: =C6+D6 | F6: =SUMPRODUCT((MONTH(뱅샐입력!A$4:A$3003)=6)*(YEAR(뱅샐입력!A$4:A$3003)=설정!C3)*(뱅샐입력!C$4:C$3003="지출")*(뱅샐입력!D$4:D$3003=A6)*ABS(뱅샐입력!G$4:G$3003)) | G6: =E6-F6 | H6: =IFERROR(F6/E6,0) | I6: =IFERROR('05월'!F6,0) | J6: =F6-I6
A7: 고정비 | B7: 보험/연금 | C7: =IFERROR(SUMIFS(수입&예산!H$15:H$50,수입&예산!B$15:B$50,A7,수입&예산!C$15:C$50,B7)*10000,0) | D7: 0 | E7: =C7+D7 | F7: =SUMPRODUCT((MONTH(뱅샐입력!A$4:A$3003)=6)*(YEAR(뱅샐입력!A$4:A$3003)=설정!C3)*(뱅샐입력!C$4:C$3003="지출")*(뱅샐입력!D$4:D$3003=A7)*ABS(뱅샐입력!G$4:G$3003)) | G7: =E7-F7 | H7: =IFERROR(F7/E7,0) | I7: =IFERROR('05월'!F7,0) | J7: =F7-I7
A8: 고정비 | B8: 부모님 | C8: =IFERROR(SUMIFS(수입&예산!H$15:H$50,수입&예산!B$15:B$50,A8,수입&예산!C$15:C$50,B8)*10000,0) | D8: 0 | E8: =C8+D8 | F8: =SUMPRODUCT((MONTH(뱅샐입력!A$4:A$3003)=6)*(YEAR(뱅샐입력!A$4:A$3003)=설정!C3)*(뱅샐입력!C$4:C$3003="지출")*(뱅샐입력!D$4:D$3003=A8)*ABS(뱅샐입력!G$4:G$3003)) | G8: =E8-F8 | H8: =IFERROR(F8/E8,0) | I8: =IFERROR('05월'!F8,0) | J8: =F8-I8
A9: 고정비 | B9: 기흥모임 | C9: =IFERROR(SUMIFS(수입&예산!H$15:H$50,수입&예산!B$15:B$50,A9,수입&예산!C$15:C$50,B9)*10000,0) | D9: 0 | E9: =C9+D9 | F9: =SUMPRODUCT((MONTH(뱅샐입력!A$4:A$3003)=6)*(YEAR(뱅샐입력!A$4:A$3003)=설정!C3)*(뱅샐입력!C$4:C$3003="지출")*(뱅샐입력!D$4:D$3003=A9)*ABS(뱅샐입력!G$4:G$3003)) | G9: =E9-F9 | H9: =IFERROR(F9/E9,0) | I9: =IFERROR('05월'!F9,0) | J9: =F9-I9
A10: 고정비 | B10: 구독형서비스 | C10: =IFERROR(SUMIFS(수입&예산!H$15:H$50,수입&예산!B$15:B$50,A10,수입&예산!C$15:C$50,B10)*10000,0) | D10: 0 | E10: =C10+D10 | F10: =SUMPRODUCT((MONTH(뱅샐입력!A$4:A$3003)=6)*(YEAR(뱅샐입력!A$4:A$3003)=설정!C3)*(뱅샐입력!C$4:C$3003="지출")*(뱅샐입력!D$4:D$3003=A10)*ABS(뱅샐입력!G$4:G$3003)) | G10: =E10-F10 | H10: =IFERROR(F10/E10,0) | I10: =IFERROR('05월'!F10,0) | J10: =F10-I10
A11: 고정비 | B11: 용돈 | C11: =IFERROR(SUMIFS(수입&예산!H$15:H$50,수입&예산!B$15:B$50,A11,수입&예산!C$15:C$50,B11)*10000,0) | D11: 0 | E11: =C11+D11 | F11: =SUMPRODUCT((MONTH(뱅샐입력!A$4:A$3003)=6)*(YEAR(뱅샐입력!A$4:A$3003)=설정!C3)*(뱅샐입력!C$4:C$3003="지출")*(뱅샐입력!D$4:D$3003=A11)*ABS(뱅샐입력!G$4:G$3003)) | G11: =E11-F11 | H11: =IFERROR(F11/E11,0) | I11: =IFERROR('05월'!F11,0) | J11: =F11-I11
A12: 고정비 | B12: 아파트관리비 | C12: =IFERROR(SUMIFS(수입&예산!H$15:H$50,수입&예산!B$15:B$50,A12,수입&예산!C$15:C$50,B12)*10000,0) | D12: 0 | E12: =C12+D12 | F12: =SUMPRODUCT((MONTH(뱅샐입력!A$4:A$3003)=6)*(YEAR(뱅샐입력!A$4:A$3003)=설정!C3)*(뱅샐입력!C$4:C$3003="지출")*(뱅샐입력!D$4:D$3003=A12)*ABS(뱅샐입력!G$4:G$3003)) | G12: =E12-F12 | H12: =IFERROR(F12/E12,0) | I12: =IFERROR('05월'!F12,0) | J12: =F12-I12
A13: 생활비 | B13: 생활비 | C13: =IFERROR(SUMIFS(수입&예산!H$15:H$50,수입&예산!B$15:B$50,A13,수입&예산!C$15:C$50,B13)*10000,0) | D13: 0 | E13: =C13+D13 | F13: =SUMPRODUCT((MONTH(뱅샐입력!A$4:A$3003)=6)*(YEAR(뱅샐입력!A$4:A$3003)=설정!C3)*(뱅샐입력!C$4:C$3003="지출")*(뱅샐입력!D$4:D$3003=A13)*ABS(뱅샐입력!G$4:G$3003)) | G13: =E13-F13 | H13: =IFERROR(F13/E13,0) | I13: =IFERROR('05월'!F13,0) | J13: =F13-I13
A14: 의료/건강 | B14: 의료/건강 | C14: =IFERROR(SUMIFS(수입&예산!H$15:H$50,수입&예산!B$15:B$50,A14,수입&예산!C$15:C$50,B14)*10000,0) | D14: 0 | E14: =C14+D14 | F14: =SUMPRODUCT((MONTH(뱅샐입력!A$4:A$3003)=6)*(YEAR(뱅샐입력!A$4:A$3003)=설정!C3)*(뱅샐입력!C$4:C$3003="지출")*(뱅샐입력!D$4:D$3003=A14)*ABS(뱅샐입력!G$4:G$3003)) | G14: =E14-F14 | H14: =IFERROR(F14/E14,0) | I14: =IFERROR('05월'!F14,0) | J14: =F14-I14
A15: 모임 | B15: 모임 | C15: =IFERROR(SUMIFS(수입&예산!H$15:H$50,수입&예산!B$15:B$50,A15,수입&예산!C$15:C$50,B15)*10000,0) | D15: 0 | E15: =C15+D15 | F15: =SUMPRODUCT((MONTH(뱅샐입력!A$4:A$3003)=6)*(YEAR(뱅샐입력!A$4:A$3003)=설정!C3)*(뱅샐입력!C$4:C$3003="지출")*(뱅샐입력!D$4:D$3003=A15)*ABS(뱅샐입력!G$4:G$3003)) | G15: =E15-F15 | H15: =IFERROR(F15/E15,0) | I15: =IFERROR('05월'!F15,0) | J15: =F15-I15
A16: Tiss | B16: 개인 | C16: =IFERROR(SUMIFS(수입&예산!H$15:H$50,수입&예산!B$15:B$50,A16,수입&예산!C$15:C$50,B16)*10000,0) | D16: 0 | E16: =C16+D16 | F16: =SUMPRODUCT((MONTH(뱅샐입력!A$4:A$3003)=6)*(YEAR(뱅샐입력!A$4:A$3003)=설정!C3)*(뱅샐입력!C$4:C$3003="지출")*(뱅샐입력!D$4:D$3003=A16)*ABS(뱅샐입력!G$4:G$3003)) | G16: =E16-F16 | H16: =IFERROR(F16/E16,0) | I16: =IFERROR('05월'!F16,0) | J16: =F16-I16
A17: JM | B17: 개인 | C17: =IFERROR(SUMIFS(수입&예산!H$15:H$50,수입&예산!B$15:B$50,A17,수입&예산!C$15:C$50,B17)*10000,0) | D17: 0 | E17: =C17+D17 | F17: =SUMPRODUCT((MONTH(뱅샐입력!A$4:A$3003)=6)*(YEAR(뱅샐입력!A$4:A$3003)=설정!C3)*(뱅샐입력!C$4:C$3003="지출")*(뱅샐입력!D$4:D$3003=A17)*ABS(뱅샐입력!G$4:G$3003)) | G17: =E17-F17 | H17: =IFERROR(F17/E17,0) | I17: =IFERROR('05월'!F17,0) | J17: =F17-I17
A18: 세금 | B18: 재산세(주택) | C18: =IFERROR(SUMIFS(수입&예산!H$15:H$50,수입&예산!B$15:B$50,A18,수입&예산!C$15:C$50,B18)*10000,0) | D18: 0 | E18: =C18+D18 | F18: =SUMPRODUCT((MONTH(뱅샐입력!A$4:A$3003)=6)*(YEAR(뱅샐입력!A$4:A$3003)=설정!C3)*(뱅샐입력!C$4:C$3003="지출")*(뱅샐입력!D$4:D$3003=A18)*ABS(뱅샐입력!G$4:G$3003)) | G18: =E18-F18 | H18: =IFERROR(F18/E18,0) | I18: =IFERROR('05월'!F18,0) | J18: =F18-I18
A19: 세금 | B19: 종합소득세 | C19: =IFERROR(SUMIFS(수입&예산!H$15:H$50,수입&예산!B$15:B$50,A19,수입&예산!C$15:C$50,B19)*10000,0) | D19: 0 | E19: =C19+D19 | F19: =SUMPRODUCT((MONTH(뱅샐입력!A$4:A$3003)=6)*(YEAR(뱅샐입력!A$4:A$3003)=설정!C3)*(뱅샐입력!C$4:C$3003="지출")*(뱅샐입력!D$4:D$3003=A19)*ABS(뱅샐입력!G$4:G$3003)) | G19: =E19-F19 | H19: =IFERROR(F19/E19,0) | I19: =IFERROR('05월'!F19,0) | J19: =F19-I19
A20: 대출상환 | B20: 디딤돌대출 | C20: =IFERROR(SUMIFS(수입&예산!H$15:H$50,수입&예산!B$15:B$50,A20,수입&예산!C$15:C$50,B20)*10000,0) | D20: 0 | E20: =C20+D20 | F20: =SUMPRODUCT((MONTH(뱅샐입력!A$4:A$3003)=6)*(YEAR(뱅샐입력!A$4:A$3003)=설정!C3)*(뱅샐입력!C$4:C$3003="지출")*(뱅샐입력!D$4:D$3003=A20)*ABS(뱅샐입력!G$4:G$3003)) | G20: =E20-F20 | H20: =IFERROR(F20/E20,0) | I20: =IFERROR('05월'!F20,0) | J20: =F20-I20
A21: 부동산 | B21: 부동산 | C21: =IFERROR(SUMIFS(수입&예산!H$15:H$50,수입&예산!B$15:B$50,A21,수입&예산!C$15:C$50,B21)*10000,0) | D21: 0 | E21: =C21+D21 | F21: =SUMPRODUCT((MONTH(뱅샐입력!A$4:A$3003)=6)*(YEAR(뱅샐입력!A$4:A$3003)=설정!C3)*(뱅샐입력!C$4:C$3003="지출")*(뱅샐입력!D$4:D$3003=A21)*ABS(뱅샐입력!G$4:G$3003)) | G21: =E21-F21 | H21: =IFERROR(F21/E21,0) | I21: =IFERROR('05월'!F21,0) | J21: =F21-I21
A22: 기타 | B22: 기타 | C22: =IFERROR(SUMIFS(수입&예산!H$15:H$50,수입&예산!B$15:B$50,A22,수입&예산!C$15:C$50,B22)*10000,0) | D22: 0 | E22: =C22+D22 | F22: =SUMPRODUCT((MONTH(뱅샐입력!A$4:A$3003)=6)*(YEAR(뱅샐입력!A$4:A$3003)=설정!C3)*(뱅샐입력!C$4:C$3003="지출")*(뱅샐입력!D$4:D$3003=A22)*ABS(뱅샐입력!G$4:G$3003)) | G22: =E22-F22 | H22: =IFERROR(F22/E22,0) | I22: =IFERROR('05월'!F22,0) | J22: =F22-I22
A23: 합계 | C23: =SUM(C5:C22) | D23: =SUM(D5:D22) | E23: =SUM(E5:E22) | F23: =SUM(F5:F22) | G23: =SUM(G5:G22) | H23: =IFERROR(F23/E23,0) | I23: =SUM(I5:I22) | J23: =F23-I23
A25: 날짜 | B25: 타입 | C25: 대분류 | D25: 소분류 | E25: 내용 | F25: 금액 | G25: 결제수단 | H25: 메모
A26: =IFERROR(FILTER(CHOOSE({1,2,3,4,5,6,7,8},뱅샐입력!A$4:A$3003,뱅샐입력!C$4:C$3003,뱅샐입력!D$4:D$3003,뱅샐입력!E$4:E$3003,뱅샐입력!F$4:F$3003,뱅샐입력!G$4:G$3003,뱅샐입력!I$4:I$3003,뱅샐입력!J$4:J$3003),(MONTH(뱅샐입력!A$4:A$3003)=6)*(YEAR(뱅샐입력!A$4:A$3003)=설정!C3)*(뱅샐입력!C$4:C$3003<>"이체")),"데이터 없음")

Sheet 07월
A1: =TEXT(DATE(설정!C3,7,1),"YYYY년 MM월 가계부")
A2: 이번달 수입 | B2: =SUMPRODUCT((MONTH(뱅샐입력!A$4:A$3003)=7)*(YEAR(뱅샐입력!A$4:A$3003)=설정!C3)*(뱅샐입력!C$4:C$3003="수입")*뱅샐입력!G$4:G$3003) | C2: 이번달 지출 | D2: =SUMPRODUCT((MONTH(뱅샐입력!A$4:A$3003)=7)*(YEAR(뱅샐입력!A$4:A$3003)=설정!C3)*(뱅샐입력!C$4:C$3003="지출")*ABS(뱅샐입력!G$4:G$3003)) | E2: 잔액 | F2: =B2-D2
A4: 대분류 | B4: 중분류 | C4: 예산기본 | D4: 예산추가 | E4: 예산합계 | F4: 실제지출 | G4: 차액 | H4: 달성율 | I4: 전월지출 | J4: 전월대비
A5: 고정비 | B5: 교통비 | C5: =IFERROR(SUMIFS(수입&예산!H$15:H$50,수입&예산!B$15:B$50,A5,수입&예산!C$15:C$50,B5)*10000,0) | D5: 0 | E5: =C5+D5 | F5: =SUMPRODUCT((MONTH(뱅샐입력!A$4:A$3003)=7)*(YEAR(뱅샐입력!A$4:A$3003)=설정!C3)*(뱅샐입력!C$4:C$3003="지출")*(뱅샐입력!D$4:D$3003=A5)*ABS(뱅샐입력!G$4:G$3003)) | G5: =E5-F5 | H5: =IFERROR(F5/E5,0) | I5: =IFERROR('06월'!F5,0) | J5: =F5-I5
A6: 고정비 | B6: 휴대폰/인터넷 | C6: =IFERROR(SUMIFS(수입&예산!H$15:H$50,수입&예산!B$15:B$50,A6,수입&예산!C$15:C$50,B6)*10000,0) | D6: 0 | E6: =C6+D6 | F6: =SUMPRODUCT((MONTH(뱅샐입력!A$4:A$3003)=7)*(YEAR(뱅샐입력!A$4:A$3003)=설정!C3)*(뱅샐입력!C$4:C$3003="지출")*(뱅샐입력!D$4:D$3003=A6)*ABS(뱅샐입력!G$4:G$3003)) | G6: =E6-F6 | H6: =IFERROR(F6/E6,0) | I6: =IFERROR('06월'!F6,0) | J6: =F6-I6
